Workbook

Sheet 1 Affaire
B1: DEVIS 2027 | F1: EXEMPLE · tarifs fictifs
B2: Remplir les onglets 1, 2 et 3 : le devis (4) se complète tout seul. Cases bleues = à saisir.
B5: L'AFFAIRE | E5: L'OFFRE
B6: N° d'offre | C6: 26-OFF-0123 | E6: Établi par | F6: Paul HYNDERICK
B7: Date | C7: 46323 | E7: E-mail | F7: =IFERROR(VLOOKUP(F6,Listes!$A$2:$B$12,2,FALSE),"")
B8: Client | C8: Geopetrol | E8: Téléphone | F8: +33 (0)5 59 04 50 45
B9: À l'attention de | C9: M. Dupont | E9: Validité de l'offre | F9: 15 jours / 15 days
B10: Puits / Chantier | C10: Puits Lacq-12 · CLU108 | E10: Incoterm | F10: EXW Lons
E11: Conditions de règlement | F11: 30 jours date de facture / 30 days invoice date
E12: Facturation WE et jours fériés | F12: Non
B16: ➜ Étape suivante : onglet « 2 Matériel »

Sheet 2 Matériel
B1: MATÉRIEL DU DEVIS
B2: Une ligne par référence (quantité 2 = 2 lignes sur la tool list). Pour un titre de groupe (ex. BHA #1), mettre « Oui » dans Bannière et écrire le titre en Description.
A5: # | B5: Bannière ? | C5: Description (ou titre de bannière) | D5: Qté | E5: Stand-by (S) € / jour | F5: Opérations (O) € / jour | G5: UC € / item | H5: LIH / DBR € / item | I5: Inspection € / item | J5: Restocking € | K5: Inclus au forfait ? | L5: Lignes tool list | M5: Cumul | N5: Forfait € (calc.)
A6: =IF(AND(L6>0,B6<>"Oui"),COUNTIFS(L$6:L6,">0",B$6:B6,"<>Oui"),"") | B6: Oui | C6: BHA #1 | L6: =IF($C6="",0,IF($B6="Oui",1,IF(N($D6)>0,INT($D6),1))) | M6: =SUM(L$6:L6) | N6: =IF(AND(L6>0,B6<>"Oui",K6="Oui"),L6*(N(E6)*N('3 Options'!$C$15)+N(F6)*N('3 Options'!$C$16)+N(G6)),0)
A7: =IF(AND(L7>0,B7<>"Oui"),COUNTIFS(L$6:L7,">0",B$6:B7,"<>Oui"),"") | C7: Stab 5-7/8 OD, 2-1/4" ID - 3-1/2" IF Pin x Box | D7: 1 | E7: 85 | F7: 120 | G7: 40 | H7: 4200 | I7: 150 | J7: 600 | K7: Oui | L7: =IF($C7="",0,IF($B7="Oui",1,IF(N($D7)>0,INT($D7),1))) | M7: =SUM(L$6:L7) | N7: =IF(AND(L7>0,B7<>"Oui",K7="Oui"),L7*(N(E7)*N('3 Options'!$C$15)+N(F7)*N('3 Options'!$C$16)+N(G7)),0)
A8: =IF(AND(L8>0,B8<>"Oui"),COUNTIFS(L$6:L8,">0",B$6:B8,"<>Oui"),"") | C8: XO 3-1/2" IF Pin x 2-7/8" EU Box | D8: 2 | E8: 20 | F8: 30 | G8: 10 | H8: 900 | I8: 60 | J8: 150 | K8: Oui | L8: =IF($C8="",0,IF($B8="Oui",1,IF(N($D8)>0,INT($D8),1))) | M8: =SUM(L$6:L8) | N8: =IF(AND(L8>0,B8<>"Oui",K8="Oui"),L8*(N(E8)*N('3 Options'!$C$15)+N(F8)*N('3 Options'!$C$16)+N(G8)),0)
A9: =IF(AND(L9>0,B9<>"Oui"),COUNTIFS(L$6:L9,">0",B$6:B9,"<>Oui"),"") | B9: Oui | C9: BHA #2 | L9: =IF($C9="",0,IF($B9="Oui",1,IF(N($D9)>0,INT($D9),1))) | M9: =SUM(L$6:L9) | N9: =IF(AND(L9>0,B9<>"Oui",K9="Oui"),L9*(N(E9)*N('3 Options'!$C$15)+N(F9)*N('3 Options'!$C$16)+N(G9)),0)
A10: =IF(AND(L10>0,B10<>"Oui"),COUNTIFS(L$6:L10,">0",B$6:B10,"<>Oui"),"") | C10: XO 3-1/2" IF Box x 2-7/8" EU Pin | D10: 1 | E10: 20 | F10: 30 | G10: 10 | H10: 900 | I10: 60 | J10: 150 | K10: Non | L10: =IF($C10="",0,IF($B10="Oui",1,IF(N($D10)>0,INT($D10),1))) | M10: =SUM(L$6:L10) | N10: =IF(AND(L10>0,B10<>"Oui",K10="Oui"),L10*(N(E10)*N('3 Options'!$C$15)+N(F10)*N('3 Options'!$C$16)+N(G10)),0)
A11: =IF(AND(L11>0,B11<>"Oui"),COUNTIFS(L$6:L11,">0",B$6:B11,"<>Oui"),"") | L11: =IF($C11="",0,IF($B11="Oui",1,IF(N($D11)>0,INT($D11),1))) | M11: =SUM(L$6:L11) | N11: =IF(AND(L11>0,B11<>"Oui",K11="Oui"),L11*(N(E11)*N('3 Options'!$C$15)+N(F11)*N('3 Options'!$C$16)+N(G11)),0)
A12: =IF(AND(L12>0,B12<>"Oui"),COUNTIFS(L$6:L12,">0",B$6:B12,"<>Oui"),"") | L12: =IF($C12="",0,IF($B12="Oui",1,IF(N($D12)>0,INT($D12),1))) | M12: =SUM(L$6:L12) | N12: =IF(AND(L12>0,B12<>"Oui",K12="Oui"),L12*(N(E12)*N('3 Options'!$C$15)+N(F12)*N('3 Options'!$C$16)+N(G12)),0)
A13: =IF(AND(L13>0,B13<>"Oui"),COUNTIFS(L$6:L13,">0",B$6:B13,"<>Oui"),"") | L13: =IF($C13="",0,IF($B13="Oui",1,IF(N($D13)>0,INT($D13),1))) | M13: =SUM(L$6:L13) | N13: =IF(AND(L13>0,B13<>"Oui",K13="Oui"),L13*(N(E13)*N('3 Options'!$C$15)+N(F13)*N('3 Options'!$C$16)+N(G13)),0)
A14: =IF(AND(L14>0,B14<>"Oui"),COUNTIFS(L$6:L14,">0",B$6:B14,"<>Oui"),"") | L14: =IF($C14="",0,IF($B14="Oui",1,IF(N($D14)>0,INT($D14),1))) | M14: =SUM(L$6:L14) | N14: =IF(AND(L14>0,B14<>"Oui",K14="Oui"),L14*(N(E14)*N('3 Options'!$C$15)+N(F14)*N('3 Options'!$C$16)+N(G14)),0)
A15: =IF(AND(L15>0,B15<>"Oui"),COUNTIFS(L$6:L15,">0",B$6:B15,"<>Oui"),"") | L15: =IF($C15="",0,IF($B15="Oui",1,IF(N($D15)>0,INT($D15),1))) | M15: =SUM(L$6:L15) | N15: =IF(AND(L15>0,B15<>"Oui",K15="Oui"),L15*(N(E15)*N('3 Options'!$C$15)+N(F15)*N('3 Options'!$C$16)+N(G15)),0)
A16: =IF(AND(L16>0,B16<>"Oui"),COUNTIFS(L$6:L16,">0",B$6:B16,"<>Oui"),"") | L16: =IF($C16="",0,IF($B16="Oui",1,IF(N($D16)>0,INT($D16),1))) | M16: =SUM(L$6:L16) | N16: =IF(AND(L16>0,B16<>"Oui",K16="Oui"),L16*(N(E16)*N('3 Options'!$C$15)+N(F16)*N('3 Options'!$C$16)+N(G16)),0)
A17: =IF(AND(L17>0,B17<>"Oui"),COUNTIFS(L$6:L17,">0",B$6:B17,"<>Oui"),"") | L17: =IF($C17="",0,IF($B17="Oui",1,IF(N($D17)>0,INT($D17),1))) | M17: =SUM(L$6:L17) | N17: =IF(AND(L17>0,B17<>"Oui",K17="Oui"),L17*(N(E17)*N('3 Options'!$C$15)+N(F17)*N('3 Options'!$C$16)+N(G17)),0)
A18: =IF(AND(L18>0,B18<>"Oui"),COUNTIFS(L$6:L18,">0",B$6:B18,"<>Oui"),"") | L18: =IF($C18="",0,IF($B18="Oui",1,IF(N($D18)>0,INT($D18),1))) | M18: =SUM(L$6:L18) | N18: =IF(AND(L18>0,B18<>"Oui",K18="Oui"),L18*(N(E18)*N('3 Options'!$C$15)+N(F18)*N('3 Options'!$C$16)+N(G18)),0)
A19: =IF(AND(L19>0,B19<>"Oui"),COUNTIFS(L$6:L19,">0",B$6:B19,"<>Oui"),"") | L19: =IF($C19="",0,IF($B19="Oui",1,IF(N($D19)>0,INT($D19),1))) | M19: =SUM(L$6:L19) | N19: =IF(AND(L19>0,B19<>"Oui",K19="Oui"),L19*(N(E19)*N('3 Options'!$C$15)+N(F19)*N('3 Options'!$C$16)+N(G19)),0)
A20: =IF(AND(L20>0,B20<>"Oui"),COUNTIFS(L$6:L20,">0",B$6:B20,"<>Oui"),"") | L20: =IF($C20="",0,IF($B20="Oui",1,IF(N($D20)>0,INT($D20),1))) | M20: =SUM(L$6:L20) | N20: =IF(AND(L20>0,B20<>"Oui",K20="Oui"),L20*(N(E20)*N('3 Options'!$C$15)+N(F20)*N('3 Options'!$C$16)+N(G20)),0)
A21: =IF(AND(L21>0,B21<>"Oui"),COUNTIFS(L$6:L21,">0",B$6:B21,"<>Oui"),"") | L21: =IF($C21="",0,IF($B21="Oui",1,IF(N($D21)>0,INT($D21),1))) | M21: =SUM(L$6:L21) | N21: =IF(AND(L21>0,B21<>"Oui",K21="Oui"),L21*(N(E21)*N('3 Options'!$C$15)+N(F21)*N('3 Options'!$C$16)+N(G21)),0)
A22: =IF(AND(L22>0,B22<>"Oui"),COUNTIFS(L$6:L22,">0",B$6:B22,"<>Oui"),"") | L22: =IF($C22="",0,IF($B22="Oui",1,IF(N($D22)>0,INT($D22),1))) | M22: =SUM(L$6:L22) | N22: =IF(AND(L22>0,B22<>"Oui",K22="Oui"),L22*(N(E22)*N('3 Options'!$C$15)+N(F22)*N('3 Options'!$C$16)+N(G22)),0)
... A29: =IF(AND(L29>0,B29<>"Oui"),COUNTIFS(L$6:L29,">0",B$6:B29,"<>Oui"),"") | L29: =IF($C29="",0,IF($B29="Oui",1,IF(N($D29)>0,INT($D29),1))) | M29: =SUM(L$6:L29) | N29: =IF(AND(L29>0,B29<>"Oui",K29="Oui"),L29*(N(E29)*N('3 Options'!$C$15)+N(F29)*N('3 Options'!$C$16)+N(G29)),0)
C31: =SUM(L6:L29)&" ligne(s) sur la tool list · "&COUNTIFS(L6:L29,">0",B6:B29,"<>Oui")&" outil(s) au devis"
C32: Pour la liste de matériel : copier les colonnes B à D (Bannière, Description, Qté) et les coller dans le classeur « Tool List » (sans les prix).
C33: Le devis affiche les 14 premières lignes (les suivantes sont repliées dans l’onglet 4, avec une alerte). Colonnes grises (L à N) : calculs, ne pas modifier.

Sheet 3 Options
B1: OPTIONS ET FORFAIT
B2: Une option sur « Non » disparaît du devis. Serrage, transport et opérateurs s'affichent chacun dans leur bloc ; le forfait dans un bandeau final.
B5: Option | C5: Inclure ? | D5: Intitulé affiché (facultatif) | E5: Qté | F5: Prix € | G5: Unité / mode | H5: Total €
B6: 👷 Opérateur · tarif journalier | C6: Oui | E6: 1 | F6: 750 | G6: €/jour/pers | H6: =IF(C6="Oui",IF(AND(G6="Coût réel +15 %",F6=""),0,N(E6)*N(F6)),0)
B7: 👷 Opérateur · Mob / Demob | C7: Oui | E7: 1 | F7: 300 | G7: €/pers | H7: =IF(C7="Oui",IF(AND(G7="Coût réel +15 %",F7=""),0,N(E7)*N(F7)),0)
B8: 🔧 Serrage · prix par serrage (Qté = nombre de serrages) | C8: Oui | E8: 4 | F8: 180 | G8: €/serrage | H8: =IF(C8="Oui",IF(AND(G8="Coût réel +15 %",F8=""),0,N(E8)*N(F8)),0)
B9: 🚚 Transport MOB | C9: Oui | E9: 1 | G9: Coût réel +15 % | H9: =IF(C9="Oui",IF(AND(G9="Coût réel +15 %",F9=""),0,N(E9)*N(F9)),0)
B10: 🚚 Transport DEMOB | C10: Oui | E10: 1 | G10: Coût réel +15 % | H10: =IF(C10="Oui",IF(AND(G10="Coût réel +15 %",F10=""),0,N(E10)*N(F10)),0)
B12: 📦 FORFAIT · bandeau final du devis, avec son coût
B13: Forfait | C13: Oui | E13: 1 | G13: Forfait calculé (S + O + UC) | H13: =IF(C13="Oui",IF(G13="Forfait calculé (S + O + UC)",IF(F13<>"",F13,C17+IF(AND(C19="Oui",C8="Oui"),H8,0)+IF(C20="Oui",IF(C9="Oui",H9,0)+IF(C10="Oui",H10,0),0)),N(E13)*N(F13)),0)
B14: Périmètre affiché sous le forfait | D14: Location du stabilisateur et des 3 XO
B15: Forfait calculé · jours de stand-by (S) | C15: 3 | D15: Forfait habituel : 3 jours de stand-by + 2 jours d’opérations + toutes les utilisations de charge (UC), sur les lignes « Inclus au forfait » de l’onglet 2. Laisser « Prix € » vide pour utiliser ce calcul (plus serrage et transport si cochés), ou saisir un prix pour le remplacer. Qté sert pour le mode « par jour » (nombre de jours).
B16: Forfait calculé · jours d’opérations (O) | C16: 2
B17: Montant calculé des lignes « Inclus au forfait » | C17: =SUM('2 Matériel'!$N$6:$N$29)
B18: Afficher les prix des lignes du forfait sur le devis | C18: Non | D18: Oui : chaque ligne garde ses tarifs ; Non : « incl. ». Dans les deux cas le prix final du forfait apparaît dans le bandeau.
B19: Inclure le serrage dans le forfait | C19: Oui | D19: Le prix du serrage s’ajoute au montant calculé du forfait.
B20: Inclure le transport dans le forfait | C20: Oui | D20: Le transport MOB et DEMOB (s’ils ont un prix forfaitaire) s’ajoute au montant calculé.
B22: Rappels
B23: Transport « Coût réel +15 % » : aucun montant affiché. Choisir « Forfait » pour imposer un prix.
B24: Lignes couvertes par le forfait : mettre « Oui » dans « Inclus au forfait » (onglet 2). Elles s’affichent « incl. » sur le devis.

Sheet 4 Devis
D1: =INDEX(Textes!$B$2:$C$60,MATCH("title",Textes!$A$2:$A$60,0),Listes!$H$1)
D2: ="N° "&'1 Affaire'!$C$6&" · "&IF('1 Affaire'!$C$7="","",TEXT('1 Affaire'!$C$7,"dd/mm/yyyy"))
B5: =UPPER(INDEX(Textes!$B$2:$C$60,MATCH("client",Textes!$A$2:$A$60,0),Listes!$H$1)) | D5: =UPPER(INDEX(Textes!$B$2:$C$60,MATCH("offer",Textes!$A$2:$A$60,0),Listes!$H$1)) | H5: =UPPER(INDEX(Textes!$B$2:$C$60,MATCH("date",Textes!$A$2:$A$60,0),Listes!$H$1))
B6: =""&'1 Affaire'!$C$8 | D6: =""&'1 Affaire'!$C$6 | H6: =IF('1 Affaire'!$C$7="","",TEXT('1 Affaire'!$C$7,"dd/mm/yyyy"))
B7: =UPPER(INDEX(Textes!$B$2:$C$60,MATCH("attn",Textes!$A$2:$A$60,0),Listes!$H$1)) | D7: =UPPER(INDEX(Textes!$B$2:$C$60,MATCH("well",Textes!$A$2:$A$60,0),Listes!$H$1)) | H7: =UPPER(INDEX(Textes!$B$2:$C$60,MATCH("by",Textes!$A$2:$A$60,0),Listes!$H$1))
B8: =""&'1 Affaire'!$C$9 | D8: =""&'1 Affaire'!$C$10 | H8: =""&'1 Affaire'!$F$6
B9: =UPPER(INDEX(Textes!$B$2:$C$60,MATCH("inco",Textes!$A$2:$A$60,0),Listes!$H$1)) | D9: =UPPER(INDEX(Textes!$B$2:$C$60,MATCH("valid",Textes!$A$2:$A$60,0),Listes!$H$1)) | H9: =UPPER(INDEX(Textes!$B$2:$C$60,MATCH("mail",Textes!$A$2:$A$60,0),Listes!$H$1))
B10: =""&'1 Affaire'!$F$10 | D10: =""&'1 Affaire'!$F$9 | H10: =""&'1 Affaire'!$F$7
B11: =UPPER(INDEX(Textes!$B$2:$C$60,MATCH("pay",Textes!$A$2:$A$60,0),Listes!$H$1)) | D11: =UPPER(INDEX(Textes!$B$2:$C$60,MATCH("we",Textes!$A$2:$A$60,0),Listes!$H$1)) | H11: =UPPER(INDEX(Textes!$B$2:$C$60,MATCH("tel",Textes!$A$2:$A$60,0),Listes!$H$1))
B12: =""&'1 Affaire'!$F$11 | D12: =""&'1 Affaire'!$F$12 | H12: =""&'1 Affaire'!$F$8
B13: =IF(SUBTOTAL(103,B16:B55)<>SUM(N16:N55),"⚠ Appuyer sur Ctrl + Alt + L pour mettre à jour les lignes du devis (matériel ou options modifiés).","")
B14: =INDEX(Textes!$B$2:$C$60,MATCH("sec_eq",Textes!$A$2:$A$60,0),Listes!$H$1)
B15: =INDEX(Textes!$B$2:$C$60,MATCH("h_n",Textes!$A$2:$A$60,0),Listes!$H$1) | C15: =INDEX(Textes!$B$2:$C$60,MATCH("h_desc",Textes!$A$2:$A$60,0),Listes!$H$1) | D15: =INDEX(Textes!$B$2:$C$60,MATCH("h_qty",Textes!$A$2:$A$60,0),Listes!$H$1) | E15: =INDEX(Textes!$B$2:$C$60,MATCH("h_s",Textes!$A$2:$A$60,0),Listes!$H$1) | F15: =INDEX(Textes!$B$2:$C$60,MATCH("h_o",Textes!$A$2:$A$60,0),Listes!$H$1) | G15: =INDEX(Textes!$B$2:$C$60,MATCH("h_uc",Textes!$A$2:$A$60,0),Listes!$H$1) | H15: =INDEX(Textes!$B$2:$C$60,MATCH("h_lih",Textes!$A$2:$A$60,0),Listes!$H$1) | I15: =INDEX(Textes!$B$2:$C$60,MATCH("h_insp",Textes!$A$2:$A$60,0),Listes!$H$1) | J15: =INDEX(Textes!$B$2:$C$60,MATCH("h_rest",Textes!$A$2:$A$60,0),Listes!$H$1) | L15: pos | M15: type | N15: actif
B16: =IF($L16=0,"",INDEX(Flux!$D$2:$D$35,$L16)) | C16: =IF($L16=0,"",INDEX(Flux!$E$2:$E$35,$L16)) | D16: =IF($L16=0,"",INDEX(Flux!$F$2:$F$35,$L16)) | E16: =IF($L16=0,"",INDEX(Flux!$G$2:$G$35,$L16)) | F16: =IF($L16=0,"",INDEX(Flux!$H$2:$H$35,$L16)) | G16: =IF($L16=0,"",INDEX(Flux!$I$2:$I$35,$L16)) | H16: =IF($L16=0,"",INDEX(Flux!$J$2:$J$35,$L16)) | I16: =IF($L16=0,"",INDEX(Flux!$K$2:$K$35,$L16)) | J16: =IF($L16=0,"",INDEX(Flux!$L$2:$L$35,$L16)) | L16: =IFERROR(MATCH(1,Flux!$B$2:$B$35,0),0) | M16: =IF(L16=0,"",INDEX(Flux!$C$2:$C$35,L16)) | N16: =IF(L16>0,1,0)
B17: =IF($L17=0,"",INDEX(Flux!$D$2:$D$35,$L17)) | C17: =IF($L17=0,"",INDEX(Flux!$E$2:$E$35,$L17)) | D17: =IF($L17=0,"",INDEX(Flux!$F$2:$F$35,$L17)) | E17: =IF($L17=0,"",INDEX(Flux!$G$2:$G$35,$L17)) | F17: =IF($L17=0,"",INDEX(Flux!$H$2:$H$35,$L17)) | G17: =IF($L17=0,"",INDEX(Flux!$I$2:$I$35,$L17)) | H17: =IF($L17=0,"",INDEX(Flux!$J$2:$J$35,$L17)) | I17: =IF($L17=0,"",INDEX(Flux!$K$2:$K$35,$L17)) | J17: =IF($L17=0,"",INDEX(Flux!$L$2:$L$35,$L17)) | L17: =IFERROR(MATCH(2,Flux!$B$2:$B$35,0),0) | M17: =IF(L17=0,"",INDEX(Flux!$C$2:$C$35,L17)) | N17: =IF(L17>0,1,0)
B18: =IF($L18=0,"",INDEX(Flux!$D$2:$D$35,$L18)) | C18: =IF($L18=0,"",INDEX(Flux!$E$2:$E$35,$L18)) | D18: =IF($L18=0,"",INDEX(Flux!$F$2:$F$35,$L18)) | E18: =IF($L18=0,"",INDEX(Flux!$G$2:$G$35,$L18)) | F18: =IF($L18=0,"",INDEX(Flux!$H$2:$H$35,$L18)) | G18: =IF($L18=0,"",INDEX(Flux!$I$2:$I$35,$L18)) | H18: =IF($L18=0,"",INDEX(Flux!$J$2:$J$35,$L18)) | I18: =IF($L18=0,"",INDEX(Flux!$K$2:$K$35,$L18)) | J18: =IF($L18=0,"",INDEX(Flux!$L$2:$L$35,$L18)) | L18: =IFERROR(MATCH(3,Flux!$B$2:$B$35,0),0) | M18: =IF(L18=0,"",INDEX(Flux!$C$2:$C$35,L18)) | N18: =IF(L18>0,1,0)
B19: =IF($L19=0,"",INDEX(Flux!$D$2:$D$35,$L19)) | C19: =IF($L19=0,"",INDEX(Flux!$E$2:$E$35,$L19)) | D19: =IF($L19=0,"",INDEX(Flux!$F$2:$F$35,$L19)) | E19: =IF($L19=0,"",INDEX(Flux!$G$2:$G$35,$L19)) | F19: =IF($L19=0,"",INDEX(Flux!$H$2:$H$35,$L19)) | G19: =IF($L19=0,"",INDEX(Flux!$I$2:$I$35,$L19)) | H19: =IF($L19=0,"",INDEX(Flux!$J$2:$J$35,$L19)) | I19: =IF($L19=0,"",INDEX(Flux!$K$2:$K$35,$L19)) | J19: =IF($L19=0,"",INDEX(Flux!$L$2:$L$35,$L19)) | L19: =IFERROR(MATCH(4,Flux!$B$2:$B$35,0),0) | M19: =IF(L19=0,"",INDEX(Flux!$C$2:$C$35,L19)) | N19: =IF(L19>0,1,0)
B20: =IF($L20=0,"",INDEX(Flux!$D$2:$D$35,$L20)) | C20: =IF($L20=0,"",INDEX(Flux!$E$2:$E$35,$L20)) | D20: =IF($L20=0,"",INDEX(Flux!$F$2:$F$35,$L20)) | E20: =IF($L20=0,"",INDEX(Flux!$G$2:$G$35,$L20)) | F20: =IF($L20=0,"",INDEX(Flux!$H$2:$H$35,$L20)) | G20: =IF($L20=0,"",INDEX(Flux!$I$2:$I$35,$L20)) | H20: =IF($L20=0,"",INDEX(Flux!$J$2:$J$35,$L20)) | I20: =IF($L20=0,"",INDEX(Flux!$K$2:$K$35,$L20)) | J20: =IF($L20=0,"",INDEX(Flux!$L$2:$L$35,$L20)) | L20: =IFERROR(MATCH(5,Flux!$B$2:$B$35,0),0) | M20: =IF(L20=0,"",INDEX(Flux!$C$2:$C$35,L20)) | N20: =IF(L20>0,1,0)
B21: =IF($L21=0,"",INDEX(Flux!$D$2:$D$35,$L21)) | C21: =IF($L21=0,"",INDEX(Flux!$E$2:$E$35,$L21)) | D21: =IF($L21=0,"",INDEX(Flux!$F$2:$F$35,$L21)) | E21: =IF($L21=0,"",INDEX(Flux!$G$2:$G$35,$L21)) | F21: =IF($L21=0,"",INDEX(Flux!$H$2:$H$35,$L21)) | G21: =IF($L21=0,"",INDEX(Flux!$I$2:$I$35,$L21)) | H21: =IF($L21=0,"",INDEX(Flux!$J$2:$J$35,$L21)) | I21: =IF($L21=0,"",INDEX(Flux!$K$2:$K$35,$L21)) | J21: =IF($L21=0,"",INDEX(Flux!$L$2:$L$35,$L21)) | L21: =IFERROR(MATCH(6,Flux!$B$2:$B$35,0),0) | M21: =IF(L21=0,"",INDEX(Flux!$C$2:$C$35,L21)) | N21: =IF(L21>0,1,0)
B22: =IF($L22=0,"",INDEX(Flux!$D$2:$D$35,$L22)) | C22: =IF($L22=0,"",INDEX(Flux!$E$2:$E$35,$L22)) | D22: =IF($L22=0,"",INDEX(Flux!$F$2:$F$35,$L22)) | E22: =IF($L22=0,"",INDEX(Flux!$G$2:$G$35,$L22)) | F22: =IF($L22=0,"",INDEX(Flux!$H$2:$H$35,$L22)) | G22: =IF($L22=0,"",INDEX(Flux!$I$2:$I$35,$L22)) | H22: =IF($L22=0,"",INDEX(Flux!$J$2:$J$35,$L22)) | I22: =IF($L22=0,"",INDEX(Flux!$K$2:$K$35,$L22)) | J22: =IF($L22=0,"",INDEX(Flux!$L$2:$L$35,$L22)) | L22: =IFERROR(MATCH(7,Flux!$B$2:$B$35,0),0) | M22: =IF(L22=0,"",INDEX(Flux!$C$2:$C$35,L22)) | N22: =IF(L22>0,1,0)
B23: =IF($L23=0,"",INDEX(Flux!$D$2:$D$35,$L23)) | C23: =IF($L23=0,"",INDEX(Flux!$E$2:$E$35,$L23)) | D23: =IF($L23=0,"",INDEX(Flux!$F$2:$F$35,$L23)) | E23: =IF($L23=0,"",INDEX(Flux!$G$2:$G$35,$L23)) | F23: =IF($L23=0,"",INDEX(Flux!$H$2:$H$35,$L23)) | G23: =IF($L23=0,"",INDEX(Flux!$I$2:$I$35,$L23)) | H23: =IF($L23=0,"",INDEX(Flux!$J$2:$J$35,$L23)) | I23: =IF($L23=0,"",INDEX(Flux!$K$2:$K$35,$L23)) | J23: =IF($L23=0,"",INDEX(Flux!$L$2:$L$35,$L23)) | L23: =IFERROR(MATCH(8,Flux!$B$2:$B$35,0),0) | M23: =IF(L23=0,"",INDEX(Flux!$C$2:$C$35,L23)) | N23: =IF(L23>0,1,0)
B24: =IF($L24=0,"",INDEX(Flux!$D$2:$D$35,$L24)) | C24: =IF($L24=0,"",INDEX(Flux!$E$2:$E$35,$L24)) | D24: =IF($L24=0,"",INDEX(Flux!$F$2:$F$35,$L24)) | E24: =IF($L24=0,"",INDEX(Flux!$G$2:$G$35,$L24)) | F24: =IF($L24=0,"",INDEX(Flux!$H$2:$H$35,$L24)) | G24: =IF($L24=0,"",INDEX(Flux!$I$2:$I$35,$L24)) | H24: =IF($L24=0,"",INDEX(Flux!$J$2:$J$35,$L24)) | I24: =IF($L24=0,"",INDEX(Flux!$K$2:$K$35,$L24)) | J24: =IF($L24=0,"",INDEX(Flux!$L$2:$L$35,$L24)) | L24: =IFERROR(MATCH(9,Flux!$B$2:$B$35,0),0) | M24: =IF(L24=0,"",INDEX(Flux!$C$2:$C$35,L24)) | N24: =IF(L24>0,1,0)
B25: =IF($L25=0,"",INDEX(Flux!$D$2:$D$35,$L25)) | C25: =IF($L25=0,"",INDEX(Flux!$E$2:$E$35,$L25)) | D25: =IF($L25=0,"",INDEX(Flux!$F$2:$F$35,$L25)) | E25: =IF($L25=0,"",INDEX(Flux!$G$2:$G$35,$L25)) | F25: =IF($L25=0,"",INDEX(Flux!$H$2:$H$35,$L25)) | G25: =IF($L25=0,"",INDEX(Flux!$I$2:$I$35,$L25)) | H25: =IF($L25=0,"",INDEX(Flux!$J$2:$J$35,$L25)) | I25: =IF($L25=0,"",INDEX(Flux!$K$2:$K$35,$L25)) | J25: =IF($L25=0,"",INDEX(Flux!$L$2:$L$35,$L25)) | L25: =IFERROR(MATCH(10,Flux!$B$2:$B$35,0),0) | M25: =IF(L25=0,"",INDEX(Flux!$C$2:$C$35,L25)) | N25: =IF(L25>0,1,0)
B26: =IF($L26=0,"",INDEX(Flux!$D$2:$D$35,$L26)) | C26: =IF($L26=0,"",INDEX(Flux!$E$2:$E$35,$L26)) | D26: =IF($L26=0,"",INDEX(Flux!$F$2:$F$35,$L26)) | E26: =IF($L26=0,"",INDEX(Flux!$G$2:$G$35,$L26)) | F26: =IF($L26=0,"",INDEX(Flux!$H$2:$H$35,$L26)) | G26: =IF($L26=0,"",INDEX(Flux!$I$2:$I$35,$L26)) | H26: =IF($L26=0,"",INDEX(Flux!$J$2:$J$35,$L26)) | I26: =IF($L26=0,"",INDEX(Flux!$K$2:$K$35,$L26)) | J26: =IF($L26=0,"",INDEX(Flux!$L$2:$L$35,$L26)) | L26: =IFERROR(MATCH(11,Flux!$B$2:$B$35,0),0) | M26: =IF(L26=0,"",INDEX(Flux!$C$2:$C$35,L26)) | N26: =IF(L26>0,1,0)
B27: =IF($L27=0,"",INDEX(Flux!$D$2:$D$35,$L27)) | C27: =IF($L27=0,"",INDEX(Flux!$E$2:$E$35,$L27)) | D27: =IF($L27=0,"",INDEX(Flux!$F$2:$F$35,$L27)) | E27: =IF($L27=0,"",INDEX(Flux!$G$2:$G$35,$L27)) | F27: =IF($L27=0,"",INDEX(Flux!$H$2:$H$35,$L27)) | G27: =IF($L27=0,"",INDEX(Flux!$I$2:$I$35,$L27)) | H27: =IF($L27=0,"",INDEX(Flux!$J$2:$J$35,$L27)) | I27: =IF($L27=0,"",INDEX(Flux!$K$2:$K$35,$L27)) | J27: =IF($L27=0,"",INDEX(Flux!$L$2:$L$35,$L27)) | L27: =IFERROR(MATCH(12,Flux!$B$2:$B$35,0),0) | M27: =IF(L27=0,"",INDEX(Flux!$C$2:$C$35,L27)) | N27: =IF(L27>0,1,0)
B28: =IF($L28=0,"",INDEX(Flux!$D$2:$D$35,$L28)) | C28: =IF($L28=0,"",INDEX(Flux!$E$2:$E$35,$L28)) | D28: =IF($L28=0,"",INDEX(Flux!$F$2:$F$35,$L28)) | E28: =IF($L28=0,"",INDEX(Flux!$G$2:$G$35,$L28)) | F28: =IF($L28=0,"",INDEX(Flux!$H$2:$H$35,$L28)) | G28: =IF($L28=0,"",INDEX(Flux!$I$2:$I$35,$L28)) | H28: =IF($L28=0,"",INDEX(Flux!$J$2:$J$35,$L28)) | I28: =IF($L28=0,"",INDEX(Flux!$K$2:$K$35,$L28)) | J28: =IF($L28=0,"",INDEX(Flux!$L$2:$L$35,$L28)) | L28: =IFERROR(MATCH(13,Flux!$B$2:$B$35,0),0) | M28: =IF(L28=0,"",INDEX(Flux!$C$2:$C$35,L28)) | N28: =IF(L28>0,1,0)
B29: =IF($L29=0,"",INDEX(Flux!$D$2:$D$35,$L29)) | C29: =IF($L29=0,"",INDEX(Flux!$E$2:$E$35,$L29)) | D29: =IF($L29=0,"",INDEX(Flux!$F$2:$F$35,$L29)) | E29: =IF($L29=0,"",INDEX(Flux!$G$2:$G$35,$L29)) | F29: =IF($L29=0,"",INDEX(Flux!$H$2:$H$35,$L29)) | G29: =IF($L29=0,"",INDEX(Flux!$I$2:$I$35,$L29)) | H29: =IF($L29=0,"",INDEX(Flux!$J$2:$J$35,$L29)) | I29: =IF($L29=0,"",INDEX(Flux!$K$2:$K$35,$L29)) | J29: =IF($L29=0,"",INDEX(Flux!$L$2:$L$35,$L29)) | L29: =IFERROR(MATCH(14,Flux!$B$2:$B$35,0),0) | M29: =IF(L29=0,"",INDEX(Flux!$C$2:$C$35,L29)) | N29: =IF(L29>0,1,0)
B30: =IF($L30=0,"",INDEX(Flux!$D$2:$D$35,$L30)) | C30: =IF($L30=0,"",INDEX(Flux!$E$2:$E$35,$L30)) | D30: =IF($L30=0,"",INDEX(Flux!$F$2:$F$35,$L30)) | E30: =IF($L30=0,"",INDEX(Flux!$G$2:$G$35,$L30)) | F30: =IF($L30=0,"",INDEX(Flux!$H$2:$H$35,$L30)) | G30: =IF($L30=0,"",INDEX(Flux!$I$2:$I$35,$L30)) | H30: =IF($L30=0,"",INDEX(Flux!$J$2:$J$35,$L30)) | I30: =IF($L30=0,"",INDEX(Flux!$K$2:$K$35,$L30)) | J30: =IF($L30=0,"",INDEX(Flux!$L$2:$L$35,$L30)) | L30: =IFERROR(MATCH(15,Flux!$B$2:$B$35,0),0) | M30: =IF(L30=0,"",INDEX(Flux!$C$2:$C$35,L30)) | N30: =IF(L30>0,1,0)
B31: =IF($L31=0,"",INDEX(Flux!$D$2:$D$35,$L31)) | C31: =IF($L31=0,"",INDEX(Flux!$E$2:$E$35,$L31)) | D31: =IF($L31=0,"",INDEX(Flux!$F$2:$F$35,$L31)) | E31: =IF($L31=0,"",INDEX(Flux!$G$2:$G$35,$L31)) | F31: =IF($L31=0,"",INDEX(Flux!$H$2:$H$35,$L31)) | G31: =IF($L31=0,"",INDEX(Flux!$I$2:$I$35,$L31)) | H31: =IF($L31=0,"",INDEX(Flux!$J$2:$J$35,$L31)) | I31: =IF($L31=0,"",INDEX(Flux!$K$2:$K$35,$L31)) | J31: =IF($L31=0,"",INDEX(Flux!$L$2:$L$35,$L31)) | L31: =IFERROR(MATCH(16,Flux!$B$2:$B$35,0),0) | M31: =IF(L31=0,"",INDEX(Flux!$C$2:$C$35,L31)) | N31: =IF(L31>0,1,0)
B32: =IF($L32=0,"",INDEX(Flux!$D$2:$D$35,$L32)) | C32: =IF($L32=0,"",INDEX(Flux!$E$2:$E$35,$L32)) | D32: =IF($L32=0,"",INDEX(Flux!$F$2:$F$35,$L32)) | E32: =IF($L32=0,"",INDEX(Flux!$G$2:$G$35,$L32)) | F32: =IF($L32=0,"",INDEX(Flux!$H$2:$H$35,$L32)) | G32: =IF($L32=0,"",INDEX(Flux!$I$2:$I$35,$L32)) | H32: =IF($L32=0,"",INDEX(Flux!$J$2:$J$35,$L32)) | I32: =IF($L32=0,"",INDEX(Flux!$K$2:$K$35,$L32)) | J32: =IF($L32=0,"",INDEX(Flux!$L$2:$L$35,$L32)) | L32: =IFERROR(MATCH(17,Flux!$B$2:$B$35,0),0) | M32: =IF(L32=0,"",INDEX(Flux!$C$2:$C$35,L32)) | N32: =IF(L32>0,1,0)
B33: =IF($L33=0,"",INDEX(Flux!$D$2:$D$35,$L33)) | C33: =IF($L33=0,"",INDEX(Flux!$E$2:$E$35,$L33)) | D33: =IF($L33=0,"",INDEX(Flux!$F$2:$F$35,$L33)) | E33: =IF($L33=0,"",INDEX(Flux!$G$2:$G$35,$L33)) | F33: =IF($L33=0,"",INDEX(Flux!$H$2:$H$35,$L33)) | G33: =IF($L33=0,"",INDEX(Flux!$I$2:$I$35,$L33)) | H33: =IF($L33=0,"",INDEX(Flux!$J$2:$J$35,$L33)) | I33: =IF($L33=0,"",INDEX(Flux!$K$2:$K$35,$L33)) | J33: =IF($L33=0,"",INDEX(Flux!$L$2:$L$35,$L33)) | L33: =IFERROR(MATCH(18,Flux!$B$2:$B$35,0),0) | M33: =IF(L33=0,"",INDEX(Flux!$C$2:$C$35,L33)) | N33: =IF(L33>0,1,0)
B34: =IF($L34=0,"",INDEX(Flux!$D$2:$D$35,$L34)) | C34: =IF($L34=0,"",INDEX(Flux!$E$2:$E$35,$L34)) | D34: =IF($L34=0,"",INDEX(Flux!$F$2:$F$35,$L34)) | E34: =IF($L34=0,"",INDEX(Flux!$G$2:$G$35,$L34)) | F34: =IF($L34=0,"",INDEX(Flux!$H$2:$H$35,$L34)) | G34: =IF($L34=0,"",INDEX(Flux!$I$2:$I$35,$L34)) | H34: =IF($L34=0,"",INDEX(Flux!$J$2:$J$35,$L34)) | I34: =IF($L34=0,"",INDEX(Flux!$K$2:$K$35,$L34)) | J34: =IF($L34=0,"",INDEX(Flux!$L$2:$L$35,$L34)) | L34: =IFERROR(MATCH(19,Flux!$B$2:$B$35,0),0) | M34: =IF(L34=0,"",INDEX(Flux!$C$2:$C$35,L34)) | N34: =IF(L34>0,1,0)
B35: =IF($L35=0,"",INDEX(Flux!$D$2:$D$35,$L35)) | C35: =IF($L35=0,"",INDEX(Flux!$E$2:$E$35,$L35)) | D35: =IF($L35=0,"",INDEX(Flux!$F$2:$F$35,$L35)) | E35: =IF($L35=0,"",INDEX(Flux!$G$2:$G$35,$L35)) | F35: =IF($L35=0,"",INDEX(Flux!$H$2:$H$35,$L35)) | G35: =IF($L35=0,"",INDEX(Flux!$I$2:$I$35,$L35)) | H35: =IF($L35=0,"",INDEX(Flux!$J$2:$J$35,$L35)) | I35: =IF($L35=0,"",INDEX(Flux!$K$2:$K$35,$L35)) | J35: =IF($L35=0,"",INDEX(Flux!$L$2:$L$35,$L35)) | L35: =IFERROR(MATCH(20,Flux!$B$2:$B$35,0),0) | M35: =IF(L35=0,"",INDEX(Flux!$C$2:$C$35,L35)) | N35: =IF(L35>0,1,0)
B36: =IF($L36=0,"",INDEX(Flux!$D$2:$D$35,$L36)) | C36: =IF($L36=0,"",INDEX(Flux!$E$2:$E$35,$L36)) | D36: =IF($L36=0,"",INDEX(Flux!$F$2:$F$35,$L36)) | E36: =IF($L36=0,"",INDEX(Flux!$G$2:$G$35,$L36)) | F36: =IF($L36=0,"",INDEX(Flux!$H$2:$H$35,$L36)) | G36: =IF($L36=0,"",INDEX(Flux!$I$2:$I$35,$L36)) | H36: =IF($L36=0,"",INDEX(Flux!$J$2:$J$35,$L36)) | I36: =IF($L36=0,"",INDEX(Flux!$K$2:$K$35,$L36)) | J36: =IF($L36=0,"",INDEX(Flux!$L$2:$L$35,$L36)) | L36: =IFERROR(MATCH(21,Flux!$B$2:$B$35,0),0) | M36: =IF(L36=0,"",INDEX(Flux!$C$2:$C$35,L36)) | N36: =IF(L36>0,1,0)
B37: =IF($L37=0,"",INDEX(Flux!$D$2:$D$35,$L37)) | C37: =IF($L37=0,"",INDEX(Flux!$E$2:$E$35,$L37)) | D37: =IF($L37=0,"",INDEX(Flux!$F$2:$F$35,$L37)) | E37: =IF($L37=0,"",INDEX(Flux!$G$2:$G$35,$L37)) | F37: =IF($L37=0,"",INDEX(Flux!$H$2:$H$35,$L37)) | G37: =IF($L37=0,"",INDEX(Flux!$I$2:$I$35,$L37)) | H37: =IF($L37=0,"",INDEX(Flux!$J$2:$J$35,$L37)) | I37: =IF($L37=0,"",INDEX(Flux!$K$2:$K$35,$L37)) | J37: =IF($L37=0,"",INDEX(Flux!$L$2:$L$35,$L37)) | L37: =IFERROR(MATCH(22,Flux!$B$2:$B$35,0),0) | M37: =IF(L37=0,"",INDEX(Flux!$C$2:$C$35,L37)) | N37: =IF(L37>0,1,0)
B38: =IF($L38=0,"",INDEX(Flux!$D$2:$D$35,$L38)) | C38: =IF($L38=0,"",INDEX(Flux!$E$2:$E$35,$L38)) | D38: =IF($L38=0,"",INDEX(Flux!$F$2:$F$35,$L38)) | E38: =IF($L38=0,"",INDEX(Flux!$G$2:$G$35,$L38)) | F38: =IF($L38=0,"",INDEX(Flux!$H$2:$H$35,$L38)) | G38: =IF($L38=0,"",INDEX(Flux!$I$2:$I$35,$L38)) | H38: =IF($L38=0,"",INDEX(Flux!$J$2:$J$35,$L38)) | I38: =IF($L38=0,"",INDEX(Flux!$K$2:$K$35,$L38)) | J38: =IF($L38=0,"",INDEX(Flux!$L$2:$L$35,$L38)) | L38: =IFERROR(MATCH(23,Flux!$B$2:$B$35,0),0) | M38: =IF(L38=0,"",INDEX(Flux!$C$2:$C$35,L38)) | N38: =IF(L38>0,1,0)
B39: =IF($L39=0,"",INDEX(Flux!$D$2:$D$35,$L39)) | C39: =IF($L39=0,"",INDEX(Flux!$E$2:$E$35,$L39)) | D39: =IF($L39=0,"",INDEX(Flux!$F$2:$F$35,$L39)) | E39: =IF($L39=0,"",INDEX(Flux!$G$2:$G$35,$L39)) | F39: =IF($L39=0,"",INDEX(Flux!$H$2:$H$35,$L39)) | G39: =IF($L39=0,"",INDEX(Flux!$I$2:$I$35,$L39)) | H39: =IF($L39=0,"",INDEX(Flux!$J$2:$J$35,$L39)) | I39: =IF($L39=0,"",INDEX(Flux!$K$2:$K$35,$L39)) | J39: =IF($L39=0,"",INDEX(Flux!$L$2:$L$35,$L39)) | L39: =IFERROR(MATCH(24,Flux!$B$2:$B$35,0),0) | M39: =IF(L39=0,"",INDEX(Flux!$C$2:$C$35,L39)) | N39: =IF(L39>0,1,0)
B40: =IF($L40=0,"",INDEX(Flux!$D$2:$D$35,$L40)) | C40: =IF($L40=0,"",INDEX(Flux!$E$2:$E$35,$L40)) | D40: =IF($L40=0,"",INDEX(Flux!$F$2:$F$35,$L40)) | E40: =IF($L40=0,"",INDEX(Flux!$G$2:$G$35,$L40)) | F40: =IF($L40=0,"",INDEX(Flux!$H$2:$H$35,$L40)) | G40: =IF($L40=0,"",INDEX(Flux!$I$2:$I$35,$L40)) | H40: =IF($L40=0,"",INDEX(Flux!$J$2:$J$35,$L40)) | I40: =IF($L40=0,"",INDEX(Flux!$K$2:$K$35,$L40)) | J40: =IF($L40=0,"",INDEX(Flux!$L$2:$L$35,$L40)) | L40: =IFERROR(MATCH(25,Flux!$B$2:$B$35,0),0) | M40: =IF(L40=0,"",INDEX(Flux!$C$2:$C$35,L40)) | N40: =IF(L40>0,1,0)
B41: =IF($L41=0,"",INDEX(Flux!$D$2:$D$35,$L41)) | C41: =IF($L41=0,"",INDEX(Flux!$E$2:$E$35,$L41)) | D41: =IF($L41=0,"",INDEX(Flux!$F$2:$F$35,$L41)) | E41: =IF($L41=0,"",INDEX(Flux!$G$2:$G$35,$L41)) | F41: =IF($L41=0,"",INDEX(Flux!$H$2:$H$35,$L41)) | G41: =IF($L41=0,"",INDEX(Flux!$I$2:$I$35,$L41)) | H41: =IF($L41=0,"",INDEX(Flux!$J$2:$J$35,$L41)) | I41: =IF($L41=0,"",INDEX(Flux!$K$2:$K$35,$L41)) | J41: =IF($L41=0,"",INDEX(Flux!$L$2:$L$35,$L41)) | L41: =IFERROR(MATCH(26,Flux!$B$2:$B$35,0),0) | M41: =IF(L41=0,"",INDEX(Flux!$C$2:$C$35,L41)) | N41: =IF(L41>0,1,0)
B42: =IF($L42=0,"",INDEX(Flux!$D$2:$D$35,$L42)) | C42: =IF($L42=0,"",INDEX(Flux!$E$2:$E$35,$L42)) | D42: =IF($L42=0,"",INDEX(Flux!$F$2:$F$35,$L42)) | E42: =IF($L42=0,"",INDEX(Flux!$G$2:$G$35,$L42)) | F42: =IF($L42=0,"",INDEX(Flux!$H$2:$H$35,$L42)) | G42: =IF($L42=0,"",INDEX(Flux!$I$2:$I$35,$L42)) | H42: =IF($L42=0,"",INDEX(Flux!$J$2:$J$35,$L42)) | I42: =IF($L42=0,"",INDEX(Flux!$K$2:$K$35,$L42)) | J42: =IF($L42=0,"",INDEX(Flux!$L$2:$L$35,$L42)) | L42: =IFERROR(MATCH(27,Flux!$B$2:$B$35,0),0) | M42: =IF(L42=0,"",INDEX(Flux!$C$2:$C$35,L42)) | N42: =IF(L42>0,1,0)
...

Sheet Listes
A1: Contact Enedril | B1: E-mail | D1: Incoterm | E1: Validité | F1: Règlement | G1: Oui / Non | H1: 2 | J1: Support de colisage | K1: N° de colis | L1: Unité | M1: Mode transport | N1: Mode forfait | P1: Statut | Q1: Test / Taille
A2: Fabien JACQUOT | B2: fjacquot@enedril.fr | D2: EXW Lons | E2: 15 jours / 15 days | F2: 30 jours date de facture / 30 days invoice date | G2: Oui | H2: ← langue du devis : 1 = français, 2 = anglais | J2: Palette | K2: P1 | L2: forfait | M2: Coût réel +15 % | N2: Forfait calculé (S + O + UC) | P2: Oui | Q2: Taille OK
A3: Alexis ESTINES | B3: aestines@enedril.fr | D3: FCA Lons | E3: 30 jours / 30 days | F3: 30 jours fin de mois / 30 days end of month | G3: Non | J3: Fishing basket | K3: P2 | L3: €/jour | M3: Forfait | N3: Forfait global | P3: En cours | Q3: Test OK
A4: Paul HYNDERICK | B4: phynderick@enedril.fr | D4: DAP | E4: 60 jours / 60 days | F4: 45 jours fin de mois / 45 days end of month | J4: Caisse | K4: P3 | L4: €/jour/pers | N4: Forfait par jour | Q4: Taille + test OK
A5: Céline CARDONA | B5: ccardona@enedril.fr | D5: DDP | E5: 90 jours / 90 days | F5: À la commande / Upon order | J5: Vrac | K5: P4 | L5: €/pers | Q5: À contrôler
A6: Koen MONDELAERS | B6: kmondelaers@enedril.fr | D6: FOB | K6: P5 | L6: €/unité
A7: Luigi LIBERATORE | B7: lliberatore@enedril.fr | K7: P6
K8: P7
K9: P8
A10: Pour ajouter un contact, une validité, etc. : écrire à la suite dans la colonne (les listes déroulantes lisent les 12 premières lignes). | K10: P9
K11: P10
K12: Vrac

Sheet Textes
A1: Clé | B1: Français | C1: English
A2: title | B2: OFFRE DE LOCATION | C2: EQUIPMENT RENTAL QUOTATION
A3: client | B3: Client | C3: Company
A4: attn | B4: À l'attention de | C4: Attention
A5: well | B5: Puits / Chantier | C5: Well / Location
A6: rig | B6: Rig | C6: Rig
A7: offer | B7: N° d'offre | C7: Offer N°
A8: date | B8: Date | C8: Date
A9: valid | B9: Validité de l'offre | C9: Validity
A10: inco | B10: Incoterm | C10: Incoterm
A11: lead | B11: Délai de mise à dispo | C11: Lead time
A12: pay | B12: Conditions de règlement | C12: Payment terms
... A60: sec_op | B60: OPÉRATEURS | C60: OPERATORS

Sheet Flux
A1: actif | B1: rang | C1: type | D1: # | E1: libellé | F1: qté | G1: v1 | H1: v2 | I1: v3 | J1: v4 | K1: v5 | L1: v6
A2: =IF('2 Matériel'!$L6>0,1,0) | B2: =IF(A2=1,COUNTIF(A$2:A2,1),"") | C2: =IF(A2=1,IF('2 Matériel'!$B6="Oui","BAN","ITM"),"") | D2: =IF(C2="ITM",'2 Matériel'!$A6,"") | E2: =IF(C2="BAN",UPPER('2 Matériel'!$C6),IF(C2="ITM",'2 Matériel'!$C6&IF(AND('2 Matériel'!$K6="Oui",'3 Options'!$C$13="Oui")," · "&INDEX(Textes!$B$2:$C$60,MATCH("incl_long",Textes!$A$2:$A$60,0),Listes!$H$1),""),"")) | F2: =IF(C2="ITM",'2 Matériel'!$L6,"") | G2: =IF(C2="ITM",IF(AND(AND('2 Matériel'!$K6="Oui",'3 Options'!$C$13="Oui"),'3 Options'!$C$18<>"Oui"),INDEX(Textes!$B$2:$C$60,MATCH("incl",Textes!$A$2:$A$60,0),Listes!$H$1),IF('2 Matériel'!$E6="","",'2 Matériel'!$E6)),"") | H2: =IF(C2="ITM",IF(AND(AND('2 Matériel'!$K6="Oui",'3 Options'!$C$13="Oui"),'3 Options'!$C$18<>"Oui"),INDEX(Textes!$B$2:$C$60,MATCH("incl",Textes!$A$2:$A$60,0),Listes!$H$1),IF('2 Matériel'!$F6="","",'2 Matériel'!$F6)),"") | I2: =IF(C2="ITM",IF(AND(AND('2 Matériel'!$K6="Oui",'3 Options'!$C$13="Oui"),'3 Options'!$C$18<>"Oui"),INDEX(Textes!$B$2:$C$60,MATCH("incl",Textes!$A$2:$A$60,0),Listes!$H$1),IF('2 Matériel'!$G6="","",'2 Matériel'!$G6)),"") | J2: =IF(C2="ITM",IF(AND(AND('2 Matériel'!$K6="Oui",'3 Options'!$C$13="Oui"),'3 Options'!$C$18<>"Oui"),INDEX(Textes!$B$2:$C$60,MATCH("incl",Textes!$A$2:$A$60,0),Listes!$H$1),IF('2 Matériel'!$H6="","",'2 Matériel'!$H6)),"") | K2: =IF(C2="ITM",IF(AND(AND('2 Matériel'!$K6="Oui",'3 Options'!$C$13="Oui"),'3 Options'!$C$18<>"Oui"),INDEX(Textes!$B$2:$C$60,MATCH("incl",Textes!$A$2:$A$60,0),Listes!$H$1),IF('2 Matériel'!$I6="","",'2 Matériel'!$I6)),"") | L2: =IF(C2="ITM",IF(AND(AND('2 Matériel'!$K6="Oui",'3 Options'!$C$13="Oui"),'3 Options'!$C$18<>"Oui"),INDEX(Textes!$B$2:$C$60,MATCH("incl",Textes!$A$2:$A$60,0),Listes!$H$1),IF('2 Matériel'!$J6="","",'2 Matériel'!$J6)),"")
A3: =IF('2 Matériel'!$L7>0,1,0) | B3: =IF(A3=1,COUNTIF(A$2:A3,1),"") | C3: =IF(A3=1,IF('2 Matériel'!$B7="Oui","BAN","ITM"),"") | D3: =IF(C3="ITM",'2 Matériel'!$A7,"") | E3: =IF(C3="BAN",UPPER('2 Matériel'!$C7),IF(C3="ITM",'2 Matériel'!$C7&IF(AND('2 Matériel'!$K7="Oui",'3 Options'!$C$13="Oui")," · "&INDEX(Textes!$B$2:$C$60,MATCH("incl_long",Textes!$A$2:$A$60,0),Listes!$H$1),""),"")) | F3: =IF(C3="ITM",'2 Matériel'!$L7,"") | G3: =IF(C3="ITM",IF(AND(AND('2 Matériel'!$K7="Oui",'3 Options'!$C$13="Oui"),'3 Options'!$C$18<>"Oui"),INDEX(Textes!$B$2:$C$60,MATCH("incl",Textes!$A$2:$A$60,0),Listes!$H$1),IF('2 Matériel'!$E7="","",'2 Matériel'!$E7)),"") | H3: =IF(C3="ITM",IF(AND(AND('2 Matériel'!$K7="Oui",'3 Options'!$C$13="Oui"),'3 Options'!$C$18<>"Oui"),INDEX(Textes!$B$2:$C$60,MATCH("incl",Textes!$A$2:$A$60,0),Listes!$H$1),IF('2 Matériel'!$F7="","",'2 Matériel'!$F7)),"") | I3: =IF(C3="ITM",IF(AND(AND('2 Matériel'!$K7="Oui",'3 Options'!$C$13="Oui"),'3 Options'!$C$18<>"Oui"),INDEX(Textes!$B$2:$C$60,MATCH("incl",Textes!$A$2:$A$60,0),Listes!$H$1),IF('2 Matériel'!$G7="","",'2 Matériel'!$G7)),"") | J3: =IF(C3="ITM",IF(AND(AND('2 Matériel'!$K7="Oui",'3 Options'!$C$13="Oui"),'3 Options'!$C$18<>"Oui"),INDEX(Textes!$B$2:$C$60,MATCH("incl",Textes!$A$2:$A$60,0),Listes!$H$1),IF('2 Matériel'!$H7="","",'2 Matériel'!$H7)),"") | K3: =IF(C3="ITM",IF(AND(AND('2 Matériel'!$K7="Oui",'3 Options'!$C$13="Oui"),'3 Options'!$C$18<>"Oui"),INDEX(Textes!$B$2:$C$60,MATCH("incl",Textes!$A$2:$A$60,0),Listes!$H$1),IF('2 Matériel'!$I7="","",'2 Matériel'!$I7)),"") | L3: =IF(C3="ITM",IF(AND(AND('2 Matériel'!$K7="Oui",'3 Options'!$C$13="Oui"),'3 Options'!$C$18<>"Oui"),INDEX(Textes!$B$2:$C$60,MATCH("incl",Textes!$A$2:$A$60,0),Listes!$H$1),IF('2 Matériel'!$J7="","",'2 Matériel'!$J7)),"")
A4: =IF('2 Matériel'!$L8>0,1,0) | B4: =IF(A4=1,COUNTIF(A$2:A4,1),"") | C4: =IF(A4=1,IF('2 Matériel'!$B8="Oui","BAN","ITM"),"") | D4: =IF(C4="ITM",'2 Matériel'!$A8,"") | E4: =IF(C4="BAN",UPPER('2 Matériel'!$C8),IF(C4="ITM",'2 Matériel'!$C8&IF(AND('2 Matériel'!$K8="Oui",'3 Options'!$C$13="Oui")," · "&INDEX(Textes!$B$2:$C$60,MATCH("incl_long",Textes!$A$2:$A$60,0),Listes!$H$1),""),"")) | F4: =IF(C4="ITM",'2 Matériel'!$L8,"") | G4: =IF(C4="ITM",IF(AND(AND('2 Matériel'!$K8="Oui",'3 Options'!$C$13="Oui"),'3 Options'!$C$18<>"Oui"),INDEX(Textes!$B$2:$C$60,MATCH("incl",Textes!$A$2:$A$60,0),Listes!$H$1),IF('2 Matériel'!$E8="","",'2 Matériel'!$E8)),"") | H4: =IF(C4="ITM",IF(AND(AND('2 Matériel'!$K8="Oui",'3 Options'!$C$13="Oui"),'3 Options'!$C$18<>"Oui"),INDEX(Textes!$B$2:$C$60,MATCH("incl",Textes!$A$2:$A$60,0),Listes!$H$1),IF('2 Matériel'!$F8="","",'2 Matériel'!$F8)),"") | I4: =IF(C4="ITM",IF(AND(AND('2 Matériel'!$K8="Oui",'3 Options'!$C$13="Oui"),'3 Options'!$C$18<>"Oui"),INDEX(Textes!$B$2:$C$60,MATCH("incl",Textes!$A$2:$A$60,0),Listes!$H$1),IF('2 Matériel'!$G8="","",'2 Matériel'!$G8)),"") | J4: =IF(C4="ITM",IF(AND(AND('2 Matériel'!$K8="Oui",'3 Options'!$C$13="Oui"),'3 Options'!$C$18<>"Oui"),INDEX(Textes!$B$2:$C$60,MATCH("incl",Textes!$A$2:$A$60,0),Listes!$H$1),IF('2 Matériel'!$H8="","",'2 Matériel'!$H8)),"") | K4: =IF(C4="ITM",IF(AND(AND('2 Matériel'!$K8="Oui",'3 Options'!$C$13="Oui"),'3 Options'!$C$18<>"Oui"),INDEX(Textes!$B$2:$C$60,MATCH("incl",Textes!$A$2:$A$60,0),Listes!$H$1),IF('2 Matériel'!$I8="","",'2 Matériel'!$I8)),"") | L4: =IF(C4="ITM",IF(AND(AND('2 Matériel'!$K8="Oui",'3 Options'!$C$13="Oui"),'3 Options'!$C$18<>"Oui"),INDEX(Textes!$B$2:$C$60,MATCH("incl",Textes!$A$2:$A$60,0),Listes!$H$1),IF('2 Matériel'!$J8="","",'2 Matériel'!$J8)),"")
A5: =IF('2 Matériel'!$L9>0,1,0) | B5: =IF(A5=1,COUNTIF(A$2:A5,1),"") | C5: =IF(A5=1,IF('2 Matériel'!$B9="Oui","BAN","ITM"),"") | D5: =IF(C5="ITM",'2 Matériel'!$A9,"") | E5: =IF(C5="BAN",UPPER('2 Matériel'!$C9),IF(C5="ITM",'2 Matériel'!$C9&IF(AND('2 Matériel'!$K9="Oui",'3 Options'!$C$13="Oui")," · "&INDEX(Textes!$B$2:$C$60,MATCH("incl_long",Textes!$A$2:$A$60,0),Listes!$H$1),""),"")) | F5: =IF(C5="ITM",'2 Matériel'!$L9,"") | G5: =IF(C5="ITM",IF(AND(AND('2 Matériel'!$K9="Oui",'3 Options'!$C$13="Oui"),'3 Options'!$C$18<>"Oui"),INDEX(Textes!$B$2:$C$60,MATCH("incl",Textes!$A$2:$A$60,0),Listes!$H$1),IF('2 Matériel'!$E9="","",'2 Matériel'!$E9)),"") | H5: =IF(C5="ITM",IF(AND(AND('2 Matériel'!$K9="Oui",'3 Options'!$C$13="Oui"),'3 Options'!$C$18<>"Oui"),INDEX(Textes!$B$2:$C$60,MATCH("incl",Textes!$A$2:$A$60,0),Listes!$H$1),IF('2 Matériel'!$F9="","",'2 Matériel'!$F9)),"") | I5: =IF(C5="ITM",IF(AND(AND('2 Matériel'!$K9="Oui",'3 Options'!$C$13="Oui"),'3 Options'!$C$18<>"Oui"),INDEX(Textes!$B$2:$C$60,MATCH("incl",Textes!$A$2:$A$60,0),Listes!$H$1),IF('2 Matériel'!$G9="","",'2 Matériel'!$G9)),"") | J5: =IF(C5="ITM",IF(AND(AND('2 Matériel'!$K9="Oui",'3 Options'!$C$13="Oui"),'3 Options'!$C$18<>"Oui"),INDEX(Textes!$B$2:$C$60,MATCH("incl",Textes!$A$2:$A$60,0),Listes!$H$1),IF('2 Matériel'!$H9="","",'2 Matériel'!$H9)),"") | K5: =IF(C5="ITM",IF(AND(AND('2 Matériel'!$K9="Oui",'3 Options'!$C$13="Oui"),'3 Options'!$C$18<>"Oui"),INDEX(Textes!$B$2:$C$60,MATCH("incl",Textes!$A$2:$A$60,0),Listes!$H$1),IF('2 Matériel'!$I9="","",'2 Matériel'!$I9)),"") | L5: =IF(C5="ITM",IF(AND(AND('2 Matériel'!$K9="Oui",'3 Options'!$C$13="Oui"),'3 Options'!$C$18<>"Oui"),INDEX(Textes!$B$2:$C$60,MATCH("incl",Textes!$A$2:$A$60,0),Listes!$H$1),IF('2 Matériel'!$J9="","",'2 Matériel'!$J9)),"")
A6: =IF('2 Matériel'!$L10>0,1,0) | B6: =IF(A6=1,COUNTIF(A$2:A6,1),"") | C6: =IF(A6=1,IF('2 Matériel'!$B10="Oui","BAN","ITM"),"") | D6: =IF(C6="ITM",'2 Matériel'!$A10,"") | E6: =IF(C6="BAN",UPPER('2 Matériel'!$C10),IF(C6="ITM",'2 Matériel'!$C10&IF(AND('2 Matériel'!$K10="Oui",'3 Options'!$C$13="Oui")," · "&INDEX(Textes!$B$2:$C$60,MATCH("incl_long",Textes!$A$2:$A$60,0),Listes!$H$1),""),"")) | F6: =IF(C6="ITM",'2 Matériel'!$L10,"") | G6: =IF(C6="ITM",IF(AND(AND('2 Matériel'!$K10="Oui",'3 Options'!$C$13="Oui"),'3 Options'!$C$18<>"Oui"),INDEX(Textes!$B$2:$C$60,MATCH("incl",Textes!$A$2:$A$60,0),Listes!$H$1),IF('2 Matériel'!$E10="","",'2 Matériel'!$E10)),"") | H6: =IF(C6="ITM",IF(AND(AND('2 Matériel'!$K10="Oui",'3 Options'!$C$13="Oui"),'3 Options'!$C$18<>"Oui"),INDEX(Textes!$B$2:$C$60,MATCH("incl",Textes!$A$2:$A$60,0),Listes!$H$1),IF('2 Matériel'!$F10="","",'2 Matériel'!$F10)),"") | I6: =IF(C6="ITM",IF(AND(AND('2 Matériel'!$K10="Oui",'3 Options'!$C$13="Oui"),'3 Options'!$C$18<>"Oui"),INDEX(Textes!$B$2:$C$60,MATCH("incl",Textes!$A$2:$A$60,0),Listes!$H$1),IF('2 Matériel'!$G10="","",'2 Matériel'!$G10)),"") | J6: =IF(C6="ITM",IF(AND(AND('2 Matériel'!$K10="Oui",'3 Options'!$C$13="Oui"),'3 Options'!$C$18<>"Oui"),INDEX(Textes!$B$2:$C$60,MATCH("incl",Textes!$A$2:$A$60,0),Listes!$H$1),IF('2 Matériel'!$H10="","",'2 Matériel'!$H10)),"") | K6: =IF(C6="ITM",IF(AND(AND('2 Matériel'!$K10="Oui",'3 Options'!$C$13="Oui"),'3 Options'!$C$18<>"Oui"),INDEX(Textes!$B$2:$C$60,MATCH("incl",Textes!$A$2:$A$60,0),Listes!$H$1),IF('2 Matériel'!$I10="","",'2 Matériel'!$I10)),"") | L6: =IF(C6="ITM",IF(AND(AND('2 Matériel'!$K10="Oui",'3 Options'!$C$13="Oui"),'3 Options'!$C$18<>"Oui"),INDEX(Textes!$B$2:$C$60,MATCH("incl",Textes!$A$2:$A$60,0),Listes!$H$1),IF('2 Matériel'!$J10="","",'2 Matériel'!$J10)),"")
A7: =IF('2 Matériel'!$L11>0,1,0) | B7: =IF(A7=1,COUNTIF(A$2:A7,1),"") | C7: =IF(A7=1,IF('2 Matériel'!$B11="Oui","BAN","ITM"),"") | D7: =IF(C7="ITM",'2 Matériel'!$A11,"") | E7: =IF(C7="BAN",UPPER('2 Matériel'!$C11),IF(C7="ITM",'2 Matériel'!$C11&IF(AND('2 Matériel'!$K11="Oui",'3 Options'!$C$13="Oui")," · "&INDEX(Textes!$B$2:$C$60,MATCH("incl_long",Textes!$A$2:$A$60,0),Listes!$H$1),""),"")) | F7: =IF(C7="ITM",'2 Matériel'!$L11,"") | G7: =IF(C7="ITM",IF(AND(AND('2 Matériel'!$K11="Oui",'3 Options'!$C$13="Oui"),'3 Options'!$C$18<>"Oui"),INDEX(Textes!$B$2:$C$60,MATCH("incl",Textes!$A$2:$A$60,0),Listes!$H$1),IF('2 Matériel'!$E11="","",'2 Matériel'!$E11)),"") | H7: =IF(C7="ITM",IF(AND(AND('2 Matériel'!$K11="Oui",'3 Options'!$C$13="Oui"),'3 Options'!$C$18<>"Oui"),INDEX(Textes!$B$2:$C$60,MATCH("incl",Textes!$A$2:$A$60,0),Listes!$H$1),IF('2 Matériel'!$F11="","",'2 Matériel'!$F11)),"") | I7: =IF(C7="ITM",IF(AND(AND('2 Matériel'!$K11="Oui",'3 Options'!$C$13="Oui"),'3 Options'!$C$18<>"Oui"),INDEX(Textes!$B$2:$C$60,MATCH("incl",Textes!$A$2:$A$60,0),Listes!$H$1),IF('2 Matériel'!$G11="","",'2 Matériel'!$G11)),"") | J7: =IF(C7="ITM",IF(AND(AND('2 Matériel'!$K11="Oui",'3 Options'!$C$13="Oui"),'3 Options'!$C$18<>"Oui"),INDEX(Textes!$B$2:$C$60,MATCH("incl",Textes!$A$2:$A$60,0),Listes!$H$1),IF('2 Matériel'!$H11="","",'2 Matériel'!$H11)),"") | K7: =IF(C7="ITM",IF(AND(AND('2 Matériel'!$K11="Oui",'3 Options'!$C$13="Oui"),'3 Options'!$C$18<>"Oui"),INDEX(Textes!$B$2:$C$60,MATCH("incl",Textes!$A$2:$A$60,0),Listes!$H$1),IF('2 Matériel'!$I11="","",'2 Matériel'!$I11)),"") | L7: =IF(C7="ITM",IF(AND(AND('2 Matériel'!$K11="Oui",'3 Options'!$C$13="Oui"),'3 Options'!$C$18<>"Oui"),INDEX(Textes!$B$2:$C$60,MATCH("incl",Textes!$A$2:$A$60,0),Listes!$H$1),IF('2 Matériel'!$J11="","",'2 Matériel'!$J11)),"")
A8: =IF('2 Matériel'!$L12>0,1,0) | B8: =IF(A8=1,COUNTIF(A$2:A8,1),"") | C8: =IF(A8=1,IF('2 Matériel'!$B12="Oui","BAN","ITM"),"") | D8: =IF(C8="ITM",'2 Matériel'!$A12,"") | E8: =IF(C8="BAN",UPPER('2 Matériel'!$C12),IF(C8="ITM",'2 Matériel'!$C12&IF(AND('2 Matériel'!$K12="Oui",'3 Options'!$C$13="Oui")," · "&INDEX(Textes!$B$2:$C$60,MATCH("incl_long",Textes!$A$2:$A$60,0),Listes!$H$1),""),"")) | F8: =IF(C8="ITM",'2 Matériel'!$L12,"") | G8: =IF(C8="ITM",IF(AND(AND('2 Matériel'!$K12="Oui",'3 Options'!$C$13="Oui"),'3 Options'!$C$18<>"Oui"),INDEX(Textes!$B$2:$C$60,MATCH("incl",Textes!$A$2:$A$60,0),Listes!$H$1),IF('2 Matériel'!$E12="","",'2 Matériel'!$E12)),"") | H8: =IF(C8="ITM",IF(AND(AND('2 Matériel'!$K12="Oui",'3 Options'!$C$13="Oui"),'3 Options'!$C$18<>"Oui"),INDEX(Textes!$B$2:$C$60,MATCH("incl",Textes!$A$2:$A$60,0),Listes!$H$1),IF('2 Matériel'!$F12="","",'2 Matériel'!$F12)),"") | I8: =IF(C8="ITM",IF(AND(AND('2 Matériel'!$K12="Oui",'3 Options'!$C$13="Oui"),'3 Options'!$C$18<>"Oui"),INDEX(Textes!$B$2:$C$60,MATCH("incl",Textes!$A$2:$A$60,0),Listes!$H$1),IF('2 Matériel'!$G12="","",'2 Matériel'!$G12)),"") | J8: =IF(C8="ITM",IF(AND(AND('2 Matériel'!$K12="Oui",'3 Options'!$C$13="Oui"),'3 Options'!$C$18<>"Oui"),INDEX(Textes!$B$2:$C$60,MATCH("incl",Textes!$A$2:$A$60,0),Listes!$H$1),IF('2 Matériel'!$H12="","",'2 Matériel'!$H12)),"") | K8: =IF(C8="ITM",IF(AND(AND('2 Matériel'!$K12="Oui",'3 Options'!$C$13="Oui"),'3 Options'!$C$18<>"Oui"),INDEX(Textes!$B$2:$C$60,MATCH("incl",Textes!$A$2:$A$60,0),Listes!$H$1),IF('2 Matériel'!$I12="","",'2 Matériel'!$I12)),"") | L8: =IF(C8="ITM",IF(AND(AND('2 Matériel'!$K12="Oui",'3 Options'!$C$13="Oui"),'3 Options'!$C$18<>"Oui"),INDEX(Textes!$B$2:$C$60,MATCH("incl",Textes!$A$2:$A$60,0),Listes!$H$1),IF('2 Matériel'!$J12="","",'2 Matériel'!$J12)),"")
A9: =IF('2 Matériel'!$L13>0,1,0) | B9: =IF(A9=1,COUNTIF(A$2:A9,1),"") | C9: =IF(A9=1,IF('2 Matériel'!$B13="Oui","BAN","ITM"),"") | D9: =IF(C9="ITM",'2 Matériel'!$A13,"") | E9: =IF(C9="BAN",UPPER('2 Matériel'!$C13),IF(C9="ITM",'2 Matériel'!$C13&IF(AND('2 Matériel'!$K13="Oui",'3 Options'!$C$13="Oui")," · "&INDEX(Textes!$B$2:$C$60,MATCH("incl_long",Textes!$A$2:$A$60,0),Listes!$H$1),""),"")) | F9: =IF(C9="ITM",'2 Matériel'!$L13,"") | G9: =IF(C9="ITM",IF(AND(AND('2 Matériel'!$K13="Oui",'3 Options'!$C$13="Oui"),'3 Options'!$C$18<>"Oui"),INDEX(Textes!$B$2:$C$60,MATCH("incl",Textes!$A$2:$A$60,0),Listes!$H$1),IF('2 Matériel'!$E13="","",'2 Matériel'!$E13)),"") | H9: =IF(C9="ITM",IF(AND(AND('2 Matériel'!$K13="Oui",'3 Options'!$C$13="Oui"),'3 Options'!$C$18<>"Oui"),INDEX(Textes!$B$2:$C$60,MATCH("incl",Textes!$A$2:$A$60,0),Listes!$H$1),IF('2 Matériel'!$F13="","",'2 Matériel'!$F13)),"") | I9: =IF(C9="ITM",IF(AND(AND('2 Matériel'!$K13="Oui",'3 Options'!$C$13="Oui"),'3 Options'!$C$18<>"Oui"),INDEX(Textes!$B$2:$C$60,MATCH("incl",Textes!$A$2:$A$60,0),Listes!$H$1),IF('2 Matériel'!$G13="","",'2 Matériel'!$G13)),"") | J9: =IF(C9="ITM",IF(AND(AND('2 Matériel'!$K13="Oui",'3 Options'!$C$13="Oui"),'3 Options'!$C$18<>"Oui"),INDEX(Textes!$B$2:$C$60,MATCH("incl",Textes!$A$2:$A$60,0),Listes!$H$1),IF('2 Matériel'!$H13="","",'2 Matériel'!$H13)),"") | K9: =IF(C9="ITM",IF(AND(AND('2 Matériel'!$K13="Oui",'3 Options'!$C$13="Oui"),'3 Options'!$C$18<>"Oui"),INDEX(Textes!$B$2:$C$60,MATCH("incl",Textes!$A$2:$A$60,0),Listes!$H$1),IF('2 Matériel'!$I13="","",'2 Matériel'!$I13)),"") | L9: =IF(C9="ITM",IF(AND(AND('2 Matériel'!$K13="Oui",'3 Options'!$C$13="Oui"),'3 Options'!$C$18<>"Oui"),INDEX(Textes!$B$2:$C$60,MATCH("incl",Textes!$A$2:$A$60,0),Listes!$H$1),IF('2 Matériel'!$J13="","",'2 Matériel'!$J13)),"")
A10: =IF('2 Matériel'!$L14>0,1,0) | B10: =IF(A10=1,COUNTIF(A$2:A10,1),"") | C10: =IF(A10=1,IF('2 Matériel'!$B14="Oui","BAN","ITM"),"") | D10: =IF(C10="ITM",'2 Matériel'!$A14,"") | E10: =IF(C10="BAN",UPPER('2 Matériel'!$C14),IF(C10="ITM",'2 Matériel'!$C14&IF(AND('2 Matériel'!$K14="Oui",'3 Options'!$C$13="Oui")," · "&INDEX(Textes!$B$2:$C$60,MATCH("incl_long",Textes!$A$2:$A$60,0),Listes!$H$1),""),"")) | F10: =IF(C10="ITM",'2 Matériel'!$L14,"") | G10: =IF(C10="ITM",IF(AND(AND('2 Matériel'!$K14="Oui",'3 Options'!$C$13="Oui"),'3 Options'!$C$18<>"Oui"),INDEX(Textes!$B$2:$C$60,MATCH("incl",Textes!$A$2:$A$60,0),Listes!$H$1),IF('2 Matériel'!$E14="","",'2 Matériel'!$E14)),"") | H10: =IF(C10="ITM",IF(AND(AND('2 Matériel'!$K14="Oui",'3 Options'!$C$13="Oui"),'3 Options'!$C$18<>"Oui"),INDEX(Textes!$B$2:$C$60,MATCH("incl",Textes!$A$2:$A$60,0),Listes!$H$1),IF('2 Matériel'!$F14="","",'2 Matériel'!$F14)),"") | I10: =IF(C10="ITM",IF(AND(AND('2 Matériel'!$K14="Oui",'3 Options'!$C$13="Oui"),'3 Options'!$C$18<>"Oui"),INDEX(Textes!$B$2:$C$60,MATCH("incl",Textes!$A$2:$A$60,0),Listes!$H$1),IF('2 Matériel'!$G14="","",'2 Matériel'!$G14)),"") | J10: =IF(C10="ITM",IF(AND(AND('2 Matériel'!$K14="Oui",'3 Options'!$C$13="Oui"),'3 Options'!$C$18<>"Oui"),INDEX(Textes!$B$2:$C$60,MATCH("incl",Textes!$A$2:$A$60,0),Listes!$H$1),IF('2 Matériel'!$H14="","",'2 Matériel'!$H14)),"") | K10: =IF(C10="ITM",IF(AND(AND('2 Matériel'!$K14="Oui",'3 Options'!$C$13="Oui"),'3 Options'!$C$18<>"Oui"),INDEX(Textes!$B$2:$C$60,MATCH("incl",Textes!$A$2:$A$60,0),Listes!$H$1),IF('2 Matériel'!$I14="","",'2 Matériel'!$I14)),"") | L10: =IF(C10="ITM",IF(AND(AND('2 Matériel'!$K14="Oui",'3 Options'!$C$13="Oui"),'3 Options'!$C$18<>"Oui"),INDEX(Textes!$B$2:$C$60,MATCH("incl",Textes!$A$2:$A$60,0),Listes!$H$1),IF('2 Matériel'!$J14="","",'2 Matériel'!$J14)),"")
A11: =IF('2 Matériel'!$L15>0,1,0) | B11: =IF(A11=1,COUNTIF(A$2:A11,1),"") | C11: =IF(A11=1,IF('2 Matériel'!$B15="Oui","BAN","ITM"),"") | D11: =IF(C11="ITM",'2 Matériel'!$A15,"") | E11: =IF(C11="BAN",UPPER('2 Matériel'!$C15),IF(C11="ITM",'2 Matériel'!$C15&IF(AND('2 Matériel'!$K15="Oui",'3 Options'!$C$13="Oui")," · "&INDEX(Textes!$B$2:$C$60,MATCH("incl_long",Textes!$A$2:$A$60,0),Listes!$H$1),""),"")) | F11: =IF(C11="ITM",'2 Matériel'!$L15,"") | G11: =IF(C11="ITM",IF(AND(AND('2 Matériel'!$K15="Oui",'3 Options'!$C$13="Oui"),'3 Options'!$C$18<>"Oui"),INDEX(Textes!$B$2:$C$60,MATCH("incl",Textes!$A$2:$A$60,0),Listes!$H$1),IF('2 Matériel'!$E15="","",'2 Matériel'!$E15)),"") | H11: =IF(C11="ITM",IF(AND(AND('2 Matériel'!$K15="Oui",'3 Options'!$C$13="Oui"),'3 Options'!$C$18<>"Oui"),INDEX(Textes!$B$2:$C$60,MATCH("incl",Textes!$A$2:$A$60,0),Listes!$H$1),IF('2 Matériel'!$F15="","",'2 Matériel'!$F15)),"") | I11: =IF(C11="ITM",IF(AND(AND('2 Matériel'!$K15="Oui",'3 Options'!$C$13="Oui"),'3 Options'!$C$18<>"Oui"),INDEX(Textes!$B$2:$C$60,MATCH("incl",Textes!$A$2:$A$60,0),Listes!$H$1),IF('2 Matériel'!$G15="","",'2 Matériel'!$G15)),"") | J11: =IF(C11="ITM",IF(AND(AND('2 Matériel'!$K15="Oui",'3 Options'!$C$13="Oui"),'3 Options'!$C$18<>"Oui"),INDEX(Textes!$B$2:$C$60,MATCH("incl",Textes!$A$2:$A$60,0),Listes!$H$1),IF('2 Matériel'!$H15="","",'2 Matériel'!$H15)),"") | K11: =IF(C11="ITM",IF(AND(AND('2 Matériel'!$K15="Oui",'3 Options'!$C$13="Oui"),'3 Options'!$C$18<>"Oui"),INDEX(Textes!$B$2:$C$60,MATCH("incl",Textes!$A$2:$A$60,0),Listes!$H$1),IF('2 Matériel'!$I15="","",'2 Matériel'!$I15)),"") | L11: =IF(C11="ITM",IF(AND(AND('2 Matériel'!$K15="Oui",'3 Options'!$C$13="Oui"),'3 Options'!$C$18<>"Oui"),INDEX(Textes!$B$2:$C$60,MATCH("incl",Textes!$A$2:$A$60,0),Listes!$H$1),IF('2 Matériel'!$J15="","",'2 Matériel'!$J15)),"")
A12: =IF('2 Matériel'!$L16>0,1,0) | B12: =IF(A12=1,COUNTIF(A$2:A12,1),"") | C12: =IF(A12=1,IF('2 Matériel'!$B16="Oui","BAN","ITM"),"") | D12: =IF(C12="ITM",'2 Matériel'!$A16,"") | E12: =IF(C12="BAN",UPPER('2 Matériel'!$C16),IF(C12="ITM",'2 Matériel'!$C16&IF(AND('2 Matériel'!$K16="Oui",'3 Options'!$C$13="Oui")," · "&INDEX(Textes!$B$2:$C$60,MATCH("incl_long",Textes!$A$2:$A$60,0),Listes!$H$1),""),"")) | F12: =IF(C12="ITM",'2 Matériel'!$L16,"") | G12: =IF(C12="ITM",IF(AND(AND('2 Matériel'!$K16="Oui",'3 Options'!$C$13="Oui"),'3 Options'!$C$18<>"Oui"),INDEX(Textes!$B$2:$C$60,MATCH("incl",Textes!$A$2:$A$60,0),Listes!$H$1),IF('2 Matériel'!$E16="","",'2 Matériel'!$E16)),"") | H12: =IF(C12="ITM",IF(AND(AND('2 Matériel'!$K16="Oui",'3 Options'!$C$13="Oui"),'3 Options'!$C$18<>"Oui"),INDEX(Textes!$B$2:$C$60,MATCH("incl",Textes!$A$2:$A$60,0),Listes!$H$1),IF('2 Matériel'!$F16="","",'2 Matériel'!$F16)),"") | I12: =IF(C12="ITM",IF(AND(AND('2 Matériel'!$K16="Oui",'3 Options'!$C$13="Oui"),'3 Options'!$C$18<>"Oui"),INDEX(Textes!$B$2:$C$60,MATCH("incl",Textes!$A$2:$A$60,0),Listes!$H$1),IF('2 Matériel'!$G16="","",'2 Matériel'!$G16)),"") | J12: =IF(C12="ITM",IF(AND(AND('2 Matériel'!$K16="Oui",'3 Options'!$C$13="Oui"),'3 Options'!$C$18<>"Oui"),INDEX(Textes!$B$2:$C$60,MATCH("incl",Textes!$A$2:$A$60,0),Listes!$H$1),IF('2 Matériel'!$H16="","",'2 Matériel'!$H16)),"") | K12: =IF(C12="ITM",IF(AND(AND('2 Matériel'!$K16="Oui",'3 Options'!$C$13="Oui"),'3 Options'!$C$18<>"Oui"),INDEX(Textes!$B$2:$C$60,MATCH("incl",Textes!$A$2:$A$60,0),Listes!$H$1),IF('2 Matériel'!$I16="","",'2 Matériel'!$I16)),"") | L12: =IF(C12="ITM",IF(AND(AND('2 Matériel'!$K16="Oui",'3 Options'!$C$13="Oui"),'3 Options'!$C$18<>"Oui"),INDEX(Textes!$B$2:$C$60,MATCH("incl",Textes!$A$2:$A$60,0),Listes!$H$1),IF('2 Matériel'!$J16="","",'2 Matériel'!$J16)),"")
A13: =IF('2 Matériel'!$L17>0,1,0) | B13: =IF(A13=1,COUNTIF(A$2:A13,1),"") | C13: =IF(A13=1,IF('2 Matériel'!$B17="Oui","BAN","ITM"),"") | D13: =IF(C13="ITM",'2 Matériel'!$A17,"") | E13: =IF(C13="BAN",UPPER('2 Matériel'!$C17),IF(C13="ITM",'2 Matériel'!$C17&IF(AND('2 Matériel'!$K17="Oui",'3 Options'!$C$13="Oui")," · "&INDEX(Textes!$B$2:$C$60,MATCH("incl_long",Textes!$A$2:$A$60,0),Listes!$H$1),""),"")) | F13: =IF(C13="ITM",'2 Matériel'!$L17,"") | G13: =IF(C13="ITM",IF(AND(AND('2 Matériel'!$K17="Oui",'3 Options'!$C$13="Oui"),'3 Options'!$C$18<>"Oui"),INDEX(Textes!$B$2:$C$60,MATCH("incl",Textes!$A$2:$A$60,0),Listes!$H$1),IF('2 Matériel'!$E17="","",'2 Matériel'!$E17)),"") | H13: =IF(C13="ITM",IF(AND(AND('2 Matériel'!$K17="Oui",'3 Options'!$C$13="Oui"),'3 Options'!$C$18<>"Oui"),INDEX(Textes!$B$2:$C$60,MATCH("incl",Textes!$A$2:$A$60,0),Listes!$H$1),IF('2 Matériel'!$F17="","",'2 Matériel'!$F17)),"") | I13: =IF(C13="ITM",IF(AND(AND('2 Matériel'!$K17="Oui",'3 Options'!$C$13="Oui"),'3 Options'!$C$18<>"Oui"),INDEX(Textes!$B$2:$C$60,MATCH("incl",Textes!$A$2:$A$60,0),Listes!$H$1),IF('2 Matériel'!$G17="","",'2 Matériel'!$G17)),"") | J13: =IF(C13="ITM",IF(AND(AND('2 Matériel'!$K17="Oui",'3 Options'!$C$13="Oui"),'3 Options'!$C$18<>"Oui"),INDEX(Textes!$B$2:$C$60,MATCH("incl",Textes!$A$2:$A$60,0),Listes!$H$1),IF('2 Matériel'!$H17="","",'2 Matériel'!$H17)),"") | K13: =IF(C13="ITM",IF(AND(AND('2 Matériel'!$K17="Oui",'3 Options'!$C$13="Oui"),'3 Options'!$C$18<>"Oui"),INDEX(Textes!$B$2:$C$60,MATCH("incl",Textes!$A$2:$A$60,0),Listes!$H$1),IF('2 Matériel'!$I17="","",'2 Matériel'!$I17)),"") | L13: =IF(C13="ITM",IF(AND(AND('2 Matériel'!$K17="Oui",'3 Options'!$C$13="Oui"),'3 Options'!$C$18<>"Oui"),INDEX(Textes!$B$2:$C$60,MATCH("incl",Textes!$A$2:$A$60,0),Listes!$H$1),IF('2 Matériel'!$J17="","",'2 Matériel'!$J17)),"")
... A25: =IF('2 Matériel'!$L29>0,1,0) | B25: =IF(A25=1,COUNTIF(A$2:A25,1),"") | C25: =IF(A25=1,IF('2 Matériel'!$B29="Oui","BAN","ITM"),"") | D25: =IF(C25="ITM",'2 Matériel'!$A29,"") | E25: =IF(C25="BAN",UPPER('2 Matériel'!$C29),IF(C25="ITM",'2 Matériel'!$C29&IF(AND('2 Matériel'!$K29="Oui",'3 Options'!$C$13="Oui")," · "&INDEX(Textes!$B$2:$C$60,MATCH("incl_long",Textes!$A$2:$A$60,0),Listes!$H$1),""),"")) | F25: =IF(C25="ITM",'2 Matériel'!$L29,"") | G25: =IF(C25="ITM",IF(AND(AND('2 Matériel'!$K29="Oui",'3 Options'!$C$13="Oui"),'3 Options'!$C$18<>"Oui"),INDEX(Textes!$B$2:$C$60,MATCH("incl",Textes!$A$2:$A$60,0),Listes!$H$1),IF('2 Matériel'!$E29="","",'2 Matériel'!$E29)),"") | H25: =IF(C25="ITM",IF(AND(AND('2 Matériel'!$K29="Oui",'3 Options'!$C$13="Oui"),'3 Options'!$C$18<>"Oui"),INDEX(Textes!$B$2:$C$60,MATCH("incl",Textes!$A$2:$A$60,0),Listes!$H$1),IF('2 Matériel'!$F29="","",'2 Matériel'!$F29)),"") | I25: =IF(C25="ITM",IF(AND(AND('2 Matériel'!$K29="Oui",'3 Options'!$C$13="Oui"),'3 Options'!$C$18<>"Oui"),INDEX(Textes!$B$2:$C$60,MATCH("incl",Textes!$A$2:$A$60,0),Listes!$H$1),IF('2 Matériel'!$G29="","",'2 Matériel'!$G29)),"") | J25: =IF(C25="ITM",IF(AND(AND('2 Matériel'!$K29="Oui",'3 Options'!$C$13="Oui"),'3 Options'!$C$18<>"Oui"),INDEX(Textes!$B$2:$C$60,MATCH("incl",Textes!$A$2:$A$60,0),Listes!$H$1),IF('2 Matériel'!$H29="","",'2 Matériel'!$H29)),"") | K25: =IF(C25="ITM",IF(AND(AND('2 Matériel'!$K29="Oui",'3 Options'!$C$13="Oui"),'3 Options'!$C$18<>"Oui"),INDEX(Textes!$B$2:$C$60,MATCH("incl",Textes!$A$2:$A$60,0),Listes!$H$1),IF('2 Matériel'!$I29="","",'2 Matériel'!$I29)),"") | L25: =IF(C25="ITM",IF(AND(AND('2 Matériel'!$K29="Oui",'3 Options'!$C$13="Oui"),'3 Options'!$C$18<>"Oui"),INDEX(Textes!$B$2:$C$60,MATCH("incl",Textes!$A$2:$A$60,0),Listes!$H$1),IF('2 Matériel'!$J29="","",'2 Matériel'!$J29)),"")
A26: =IF('3 Options'!$C$8="Oui",1,0) | B26: =IF(A26=1,COUNTIF(A$2:A26,1),"") | C26: =IF(A26=1,"HDR","") | D26: ="" | E26: =INDEX(Textes!$B$2:$C$60,MATCH("sec_tight",Textes!$A$2:$A$60,0),Listes!$H$1) | F26: =INDEX(Textes!$B$2:$C$60,MATCH("h_qty",Textes!$A$2:$A$60,0),Listes!$H$1) | G26: =INDEX(Textes!$B$2:$C$60,MATCH("h_unit",Textes!$A$2:$A$60,0),Listes!$H$1) | H26: =INDEX(Textes!$B$2:$C$60,MATCH("h_pu",Textes!$A$2:$A$60,0),Listes!$H$1) | I26: =INDEX(Textes!$B$2:$C$60,MATCH("h_tot",Textes!$A$2:$A$60,0),Listes!$H$1) | J26: ="" | K26: ="" | L26: =""
A27: =IF('3 Options'!$C$8="Oui",1,0) | B27: =IF(A27=1,COUNTIF(A$2:A27,1),"") | C27: =IF(A27=1,"LIN","") | D27: ="" | E27: =IF('3 Options'!$D$8<>"",'3 Options'!$D$8,INDEX(Textes!$B$2:$C$60,MATCH("tight",Textes!$A$2:$A$60,0),Listes!$H$1))&IF(AND('3 Options'!$C$13="Oui",'3 Options'!$C$19="Oui")," · "&INDEX(Textes!$B$2:$C$60,MATCH("incl_long",Textes!$A$2:$A$60,0),Listes!$H$1),"") | F27: =IF('3 Options'!$G$8="Coût réel +15 %","",'3 Options'!$E$8) | G27: =IF('3 Options'!$G$8="Coût réel +15 %","",IF(Listes!$H$1=2,SUBSTITUTE(SUBSTITUTE(SUBSTITUTE(SUBSTITUTE('3 Options'!$G$8,"jour","day"),"serrage","make-up"),"unité","unit"),"forfait","lump sum"),'3 Options'!$G$8)) | H27: =IF(AND(AND('3 Options'!$C$13="Oui",'3 Options'!$C$19="Oui"),'3 Options'!$C$18<>"Oui"),INDEX(Textes!$B$2:$C$60,MATCH("incl",Textes!$A$2:$A$60,0),Listes!$H$1),IF('3 Options'!$G$8="Coût réel +15 %",INDEX(Textes!$B$2:$C$60,MATCH("at_cost",Textes!$A$2:$A$60,0),Listes!$H$1),IF('3 Options'!$F$8="","",'3 Options'!$F$8))) | I27: =IF(AND(AND('3 Options'!$C$13="Oui",'3 Options'!$C$19="Oui"),'3 Options'!$C$18<>"Oui"),INDEX(Textes!$B$2:$C$60,MATCH("incl",Textes!$A$2:$A$60,0),Listes!$H$1),IF('3 Options'!$G$8="Coût réel +15 %","—",'3 Options'!$H$8)) | J27: ="" | K27: ="" | L27: =""
A28: =IF(OR('3 Options'!$C$9="Oui",'3 Options'!$C$10="Oui"),1,0) | B28: =IF(A28=1,COUNTIF(A$2:A28,1),"") | C28: =IF(A28=1,"HDR","") | D28: ="" | E28: =INDEX(Textes!$B$2:$C$60,MATCH("sec_tr",Textes!$A$2:$A$60,0),Listes!$H$1) | F28: =INDEX(Textes!$B$2:$C$60,MATCH("h_qty",Textes!$A$2:$A$60,0),Listes!$H$1) | G28: =INDEX(Textes!$B$2:$C$60,MATCH("h_unit",Textes!$A$2:$A$60,0),Listes!$H$1) | H28: =INDEX(Textes!$B$2:$C$60,MATCH("h_pu",Textes!$A$2:$A$60,0),Listes!$H$1) | I28: =INDEX(Textes!$B$2:$C$60,MATCH("h_tot",Textes!$A$2:$A$60,0),Listes!$H$1) | J28: ="" | K28: ="" | L28: =""
A29: =IF('3 Options'!$C$9="Oui",1,0) | B29: =IF(A29=1,COUNTIF(A$2:A29,1),"") | C29: =IF(A29=1,"LIN","") | D29: ="" | E29: =IF('3 Options'!$D$9<>"",'3 Options'!$D$9,INDEX(Textes!$B$2:$C$60,MATCH("tr_mob",Textes!$A$2:$A$60,0),Listes!$H$1))&IF(AND('3 Options'!$C$13="Oui",'3 Options'!$C$20="Oui")," · "&INDEX(Textes!$B$2:$C$60,MATCH("incl_long",Textes!$A$2:$A$60,0),Listes!$H$1),"") | F29: =IF('3 Options'!$G$9="Coût réel +15 %","",'3 Options'!$E$9) | G29: =IF('3 Options'!$G$9="Coût réel +15 %","",IF(Listes!$H$1=2,SUBSTITUTE(SUBSTITUTE(SUBSTITUTE(SUBSTITUTE('3 Options'!$G$9,"jour","day"),"serrage","make-up"),"unité","unit"),"forfait","lump sum"),'3 Options'!$G$9)) | H29: =IF(AND(AND('3 Options'!$C$13="Oui",'3 Options'!$C$20="Oui"),'3 Options'!$C$18<>"Oui"),INDEX(Textes!$B$2:$C$60,MATCH("incl",Textes!$A$2:$A$60,0),Listes!$H$1),IF('3 Options'!$G$9="Coût réel +15 %",INDEX(Textes!$B$2:$C$60,MATCH("at_cost",Textes!$A$2:$A$60,0),Listes!$H$1),IF('3 Options'!$F$9="","",'3 Options'!$F$9))) | I29: =IF(AND(AND('3 Options'!$C$13="Oui",'3 Options'!$C$20="Oui"),'3 Options'!$C$18<>"Oui"),INDEX(Textes!$B$2:$C$60,MATCH("incl",Textes!$A$2:$A$60,0),Listes!$H$1),IF('3 Options'!$G$9="Coût réel +15 %","—",'3 Options'!$H$9)) | J29: ="" | K29: ="" | L29: =""
A30: =IF('3 Options'!$C$10="Oui",1,0) | B30: =IF(A30=1,COUNTIF(A$2:A30,1),"") | C30: =IF(A30=1,"LIN","") | D30: ="" | E30: =IF('3 Options'!$D$10<>"",'3 Options'!$D$10,INDEX(Textes!$B$2:$C$60,MATCH("tr_dem",Textes!$A$2:$A$60,0),Listes!$H$1))&IF(AND('3 Options'!$C$13="Oui",'3 Options'!$C$20="Oui")," · "&INDEX(Textes!$B$2:$C$60,MATCH("incl_long",Textes!$A$2:$A$60,0),Listes!$H$1),"") | F30: =IF('3 Options'!$G$10="Coût réel +15 %","",'3 Options'!$E$10) | G30: =IF('3 Options'!$G$10="Coût réel +15 %","",IF(Listes!$H$1=2,SUBSTITUTE(SUBSTITUTE(SUBSTITUTE(SUBSTITUTE('3 Options'!$G$10,"jour","day"),"serrage","make-up"),"unité","unit"),"forfait","lump sum"),'3 Options'!$G$10)) | H30: =IF(AND(AND('3 Options'!$C$13="Oui",'3 Options'!$C$20="Oui"),'3 Options'!$C$18<>"Oui"),INDEX(Textes!$B$2:$C$60,MATCH("incl",Textes!$A$2:$A$60,0),Listes!$H$1),IF('3 Options'!$G$10="Coût réel +15 %",INDEX(Textes!$B$2:$C$60,MATCH("at_cost",Textes!$A$2:$A$60,0),Listes!$H$1),IF('3 Options'!$F$10="","",'3 Options'!$F$10))) | I30: =IF(AND(AND('3 Options'!$C$13="Oui",'3 Options'!$C$20="Oui"),'3 Options'!$C$18<>"Oui"),INDEX(Textes!$B$2:$C$60,MATCH("incl",Textes!$A$2:$A$60,0),Listes!$H$1),IF('3 Options'!$G$10="Coût réel +15 %","—",'3 Options'!$H$10)) | J30: ="" | K30: ="" | L30: =""
A31: =IF(OR('3 Options'!$C$6="Oui",'3 Options'!$C$7="Oui"),1,0) | B31: =IF(A31=1,COUNTIF(A$2:A31,1),"") | C31: =IF(A31=1,"HDR","") | D31: ="" | E31: =INDEX(Textes!$B$2:$C$60,MATCH("sec_op",Textes!$A$2:$A$60,0),Listes!$H$1) | F31: =INDEX(Textes!$B$2:$C$60,MATCH("h_qty",Textes!$A$2:$A$60,0),Listes!$H$1) | G31: =INDEX(Textes!$B$2:$C$60,MATCH("h_unit",Textes!$A$2:$A$60,0),Listes!$H$1) | H31: =INDEX(Textes!$B$2:$C$60,MATCH("h_pu",Textes!$A$2:$A$60,0),Listes!$H$1) | I31: =INDEX(Textes!$B$2:$C$60,MATCH("h_tot",Textes!$A$2:$A$60,0),Listes!$H$1) | J31: ="" | K31: ="" | L31: =""
A32: =IF('3 Options'!$C$6="Oui",1,0) | B32: =IF(A32=1,COUNTIF(A$2:A32,1),"") | C32: =IF(A32=1,"LIN","") | D32: ="" | E32: =IF('3 Options'!$D$6<>"",'3 Options'!$D$6,INDEX(Textes!$B$2:$C$60,MATCH("op_day",Textes!$A$2:$A$60,0),Listes!$H$1))&IF(FALSE," · "&INDEX(Textes!$B$2:$C$60,MATCH("incl_long",Textes!$A$2:$A$60,0),Listes!$H$1),"") | F32: =IF('3 Options'!$G$6="Coût réel +15 %","",'3 Options'!$E$6) | G32: =IF('3 Options'!$G$6="Coût réel +15 %","",IF(Listes!$H$1=2,SUBSTITUTE(SUBSTITUTE(SUBSTITUTE(SUBSTITUTE('3 Options'!$G$6,"jour","day"),"serrage","make-up"),"unité","unit"),"forfait","lump sum"),'3 Options'!$G$6)) | H32: =IF(AND(FALSE,'3 Options'!$C$18<>"Oui"),INDEX(Textes!$B$2:$C$60,MATCH("incl",Textes!$A$2:$A$60,0),Listes!$H$1),IF('3 Options'!$G$6="Coût réel +15 %",INDEX(Textes!$B$2:$C$60,MATCH("at_cost",Textes!$A$2:$A$60,0),Listes!$H$1),IF('3 Options'!$F$6="","",'3 Options'!$F$6))) | I32: =IF(AND(FALSE,'3 Options'!$C$18<>"Oui"),INDEX(Textes!$B$2:$C$60,MATCH("incl",Textes!$A$2:$A$60,0),Listes!$H$1),IF('3 Options'!$G$6="Coût réel +15 %","—",'3 Options'!$H$6)) | J32: ="" | K32: ="" | L32: =""
