Workbook

Sheet 1 Affaire
B1: DEVIS 2027
B2: Remplir les onglets 1, 2 et 3 : le devis (4) se complète tout seul. Cases bleues = à saisir.
B5: L'AFFAIRE | E5: L'OFFRE
B6: N° d'offre | E6: Établi par
B7: Date | E7: E-mail | F7: =IFERROR(VLOOKUP(F6,Listes!$A$2:$B$12,2,FALSE),"")
B8: Client | E8: Téléphone | F8: +33 (0)5 59 04 50 45
B9: À l'attention de | E9: Validité de l'offre | F9: 15 jours / 15 days
B10: Puits / Chantier | E10: Incoterm | F10: EXW Lons
B11: Rig | E11: Délai de mise à dispo
E12: Conditions de règlement | F12: 30 jours date de facture / 30 days invoice date
E13: Facturation WE et jours fériés | F13: Non
B16: ➜ Étape suivante : onglet « 2 Matériel »

Sheet 2 Matériel
B1: MATÉRIEL DU DEVIS
B2: Une ligne par référence (quantité 2 = 2 lignes sur la tool list). Pour un titre de groupe (ex. BHA #1), mettre « Oui » dans Bannière et écrire le titre en Description.
A5: # | B5: Bannière ? | C5: Description (ou titre de bannière) | D5: Qté | E5: Note pour la tool list | F5: Stand-by (S) € / jour | G5: Opérations (O) € / jour | H5: UC € / item | I5: LIH / DBR € / item | J5: Inspection € / item | K5: Restocking € | L5: Inclus au forfait ? | M5: Lignes tool list | N5: Cumul | O5: Forfait € (calc.)
A6: =IF(AND(M6>0,B6<>"Oui"),COUNTIFS(M$6:M6,">0",B$6:B6,"<>Oui"),"") | M6: =IF($C6="",0,IF($B6="Oui",1,IF(N($D6)>0,INT($D6),1))) | N6: =SUM(M$6:M6) | O6: =IF(AND(M6>0,B6<>"Oui",L6="Oui"),M6*(N(F6)*N('3 Options'!$C$18)+N(G6)*N('3 Options'!$C$19)+N(H6)),0)
A7: =IF(AND(M7>0,B7<>"Oui"),COUNTIFS(M$6:M7,">0",B$6:B7,"<>Oui"),"") | M7: =IF($C7="",0,IF($B7="Oui",1,IF(N($D7)>0,INT($D7),1))) | N7: =SUM(M$6:M7) | O7: =IF(AND(M7>0,B7<>"Oui",L7="Oui"),M7*(N(F7)*N('3 Options'!$C$18)+N(G7)*N('3 Options'!$C$19)+N(H7)),0)
A8: =IF(AND(M8>0,B8<>"Oui"),COUNTIFS(M$6:M8,">0",B$6:B8,"<>Oui"),"") | M8: =IF($C8="",0,IF($B8="Oui",1,IF(N($D8)>0,INT($D8),1))) | N8: =SUM(M$6:M8) | O8: =IF(AND(M8>0,B8<>"Oui",L8="Oui"),M8*(N(F8)*N('3 Options'!$C$18)+N(G8)*N('3 Options'!$C$19)+N(H8)),0)
A9: =IF(AND(M9>0,B9<>"Oui"),COUNTIFS(M$6:M9,">0",B$6:B9,"<>Oui"),"") | M9: =IF($C9="",0,IF($B9="Oui",1,IF(N($D9)>0,INT($D9),1))) | N9: =SUM(M$6:M9) | O9: =IF(AND(M9>0,B9<>"Oui",L9="Oui"),M9*(N(F9)*N('3 Options'!$C$18)+N(G9)*N('3 Options'!$C$19)+N(H9)),0)
A10: =IF(AND(M10>0,B10<>"Oui"),COUNTIFS(M$6:M10,">0",B$6:B10,"<>Oui"),"") | M10: =IF($C10="",0,IF($B10="Oui",1,IF(N($D10)>0,INT($D10),1))) | N10: =SUM(M$6:M10) | O10: =IF(AND(M10>0,B10<>"Oui",L10="Oui"),M10*(N(F10)*N('3 Options'!$C$18)+N(G10)*N('3 Options'!$C$19)+N(H10)),0)
A11: =IF(AND(M11>0,B11<>"Oui"),COUNTIFS(M$6:M11,">0",B$6:B11,"<>Oui"),"") | M11: =IF($C11="",0,IF($B11="Oui",1,IF(N($D11)>0,INT($D11),1))) | N11: =SUM(M$6:M11) | O11: =IF(AND(M11>0,B11<>"Oui",L11="Oui"),M11*(N(F11)*N('3 Options'!$C$18)+N(G11)*N('3 Options'!$C$19)+N(H11)),0)
A12: =IF(AND(M12>0,B12<>"Oui"),COUNTIFS(M$6:M12,">0",B$6:B12,"<>Oui"),"") | M12: =IF($C12="",0,IF($B12="Oui",1,IF(N($D12)>0,INT($D12),1))) | N12: =SUM(M$6:M12) | O12: =IF(AND(M12>0,B12<>"Oui",L12="Oui"),M12*(N(F12)*N('3 Options'!$C$18)+N(G12)*N('3 Options'!$C$19)+N(H12)),0)
A13: =IF(AND(M13>0,B13<>"Oui"),COUNTIFS(M$6:M13,">0",B$6:B13,"<>Oui"),"") | M13: =IF($C13="",0,IF($B13="Oui",1,IF(N($D13)>0,INT($D13),1))) | N13: =SUM(M$6:M13) | O13: =IF(AND(M13>0,B13<>"Oui",L13="Oui"),M13*(N(F13)*N('3 Options'!$C$18)+N(G13)*N('3 Options'!$C$19)+N(H13)),0)
A14: =IF(AND(M14>0,B14<>"Oui"),COUNTIFS(M$6:M14,">0",B$6:B14,"<>Oui"),"") | M14: =IF($C14="",0,IF($B14="Oui",1,IF(N($D14)>0,INT($D14),1))) | N14: =SUM(M$6:M14) | O14: =IF(AND(M14>0,B14<>"Oui",L14="Oui"),M14*(N(F14)*N('3 Options'!$C$18)+N(G14)*N('3 Options'!$C$19)+N(H14)),0)
A15: =IF(AND(M15>0,B15<>"Oui"),COUNTIFS(M$6:M15,">0",B$6:B15,"<>Oui"),"") | M15: =IF($C15="",0,IF($B15="Oui",1,IF(N($D15)>0,INT($D15),1))) | N15: =SUM(M$6:M15) | O15: =IF(AND(M15>0,B15<>"Oui",L15="Oui"),M15*(N(F15)*N('3 Options'!$C$18)+N(G15)*N('3 Options'!$C$19)+N(H15)),0)
A16: =IF(AND(M16>0,B16<>"Oui"),COUNTIFS(M$6:M16,">0",B$6:B16,"<>Oui"),"") | M16: =IF($C16="",0,IF($B16="Oui",1,IF(N($D16)>0,INT($D16),1))) | N16: =SUM(M$6:M16) | O16: =IF(AND(M16>0,B16<>"Oui",L16="Oui"),M16*(N(F16)*N('3 Options'!$C$18)+N(G16)*N('3 Options'!$C$19)+N(H16)),0)
A17: =IF(AND(M17>0,B17<>"Oui"),COUNTIFS(M$6:M17,">0",B$6:B17,"<>Oui"),"") | M17: =IF($C17="",0,IF($B17="Oui",1,IF(N($D17)>0,INT($D17),1))) | N17: =SUM(M$6:M17) | O17: =IF(AND(M17>0,B17<>"Oui",L17="Oui"),M17*(N(F17)*N('3 Options'!$C$18)+N(G17)*N('3 Options'!$C$19)+N(H17)),0)
... A29: =IF(AND(M29>0,B29<>"Oui"),COUNTIFS(M$6:M29,">0",B$6:B29,"<>Oui"),"") | M29: =IF($C29="",0,IF($B29="Oui",1,IF(N($D29)>0,INT($D29),1))) | N29: =SUM(M$6:M29) | O29: =IF(AND(M29>0,B29<>"Oui",L29="Oui"),M29*(N(F29)*N('3 Options'!$C$18)+N(G29)*N('3 Options'!$C$19)+N(H29)),0)
C31: =SUM(M6:M29)&" ligne(s) sur la tool list · "&COUNTIFS(M6:M29,">0",B6:B29,"<>Oui")&" outil(s) au devis"
C32: Pour la tool list : copier les colonnes B à E (Bannière, Description, Qté, Note) et les coller dans le classeur « Tool List » (sans les prix).
C33: Le devis affiche les 14 premières lignes (les suivantes sont repliées dans l’onglet 4, avec une alerte). Colonnes grises (M à O) : calculs, ne pas modifier.

Sheet 3 Options
B1: OPTIONS ET FORFAIT
B2: Une option sur « Non » disparaît du devis. Le forfait s'affiche à part, en grand, sous la liste du matériel. Le transport reste activé par défaut.
B5: Option | C5: Inclure ? | D5: Intitulé affiché (facultatif) | E5: Qté | F5: Prix € | G5: Unité / mode | H5: Total € | I5: Rang | J5: Détail affiché sur le devis
B6: 👷 Opérateur · tarif journalier | C6: Non | E6: 1 | G6: €/jour/pers | H6: =IF(C6="Oui",IF(AND(G6="Coût réel +15 %",F6=""),0,N(E6)*N(F6)),0) | I6: =IF(C6="Oui",COUNTIF(C$6:C6,"Oui"),"")
B7: 👷 Opérateur · Mob / Demob | C7: Non | E7: 1 | G7: €/pers | H7: =IF(C7="Oui",IF(AND(G7="Coût réel +15 %",F7=""),0,N(E7)*N(F7)),0) | I7: =IF(C7="Oui",COUNTIF(C$6:C7,"Oui"),"")
B8: 🔧 Serrage · Make-up | C8: Non | E8: 1 | G8: forfait | H8: =IF(C8="Oui",IF(AND(G8="Coût réel +15 %",F8=""),0,N(E8)*N(F8)),0) | I8: =IF(C8="Oui",COUNTIF(C$6:C8,"Oui"),"")
B9: 🚚 Transport MOB | C9: Oui | E9: 1 | G9: Coût réel +15 % | H9: =IF(C9="Oui",IF(AND(G9="Coût réel +15 %",F9=""),0,N(E9)*N(F9)),0) | I9: =IF(C9="Oui",COUNTIF(C$6:C9,"Oui"),"")
B10: 🚚 Transport DEMOB | C10: Oui | E10: 1 | G10: Coût réel +15 % | H10: =IF(C10="Oui",IF(AND(G10="Coût réel +15 %",F10=""),0,N(E10)*N(F10)),0) | I10: =IF(C10="Oui",COUNTIF(C$6:C10,"Oui"),"")
B11: ➕ Option libre 1 | C11: Non | E11: 1 | G11: forfait | H11: =IF(C11="Oui",IF(AND(G11="Coût réel +15 %",F11=""),0,N(E11)*N(F11)),0) | I11: =IF(C11="Oui",COUNTIF(C$6:C11,"Oui"),"")
B12: ➕ Option libre 2 | C12: Non | E12: 1 | G12: forfait | H12: =IF(C12="Oui",IF(AND(G12="Coût réel +15 %",F12=""),0,N(E12)*N(F12)),0) | I12: =IF(C12="Oui",COUNTIF(C$6:C12,"Oui"),"")
B13: ➕ Option libre 3 | C13: Non | E13: 1 | G13: forfait | H13: =IF(C13="Oui",IF(AND(G13="Coût réel +15 %",F13=""),0,N(E13)*N(F13)),0) | I13: =IF(C13="Oui",COUNTIF(C$6:C13,"Oui"),"")
B15: 📦 FORFAIT · bloc détaché, affiché en grand sous la liste du matériel
B16: Forfait | C16: Non | E16: 1 | G16: Forfait calculé (S + O + UC) | H16: =IF(C16="Oui",IF(G16="Forfait calculé (S + O + UC)",IF(F16<>"",F16,C20),N(E16)*N(F16)),0)
B17: Périmètre affiché sous le forfait
B18: Forfait calculé · jours de stand-by (S) | C18: 3 | D18: Forfait habituel : 3 jours de stand-by + 2 jours d’opérations + toutes les utilisations de charge (UC), sur les lignes « Inclus au forfait » de l’onglet 2. Laisser « Prix € » vide pour utiliser ce calcul, ou saisir un prix pour le remplacer. Qté sert pour le mode « par jour » (nombre de jours).
B19: Forfait calculé · jours d’opérations (O) | C19: 2
B20: Montant calculé des lignes « Inclus au forfait » | C20: =SUM('2 Matériel'!$O$6:$O$29)
B22: Rappels
B23: Transport « Coût réel +15 % » : aucun montant affiché. Choisir « Forfait » pour imposer un prix.
B24: Lignes couvertes par le forfait : mettre « Oui » dans « Inclus au forfait » (onglet 2). Elles s’affichent « incl. » sur le devis.
B25: Une option libre : écrire son intitulé, son unité et son prix, puis « Oui ».

Sheet 4 Devis
E1: =INDEX(Textes!$B$2:$C$52,MATCH("title",Textes!$A$2:$A$52,0),Listes!$H$1)
E2: ="N° "&'1 Affaire'!$C$6&" · "&IF('1 Affaire'!$C$7="","",TEXT('1 Affaire'!$C$7,"dd/mm/yyyy"))
B5: =UPPER(INDEX(Textes!$B$2:$C$52,MATCH("client",Textes!$A$2:$A$52,0),Listes!$H$1)) | D5: =UPPER(INDEX(Textes!$B$2:$C$52,MATCH("offer",Textes!$A$2:$A$52,0),Listes!$H$1)) | G5: =UPPER(INDEX(Textes!$B$2:$C$52,MATCH("date",Textes!$A$2:$A$52,0),Listes!$H$1)) | I5: =UPPER(INDEX(Textes!$B$2:$C$52,MATCH("by",Textes!$A$2:$A$52,0),Listes!$H$1))
B6: =""&'1 Affaire'!$C$8 | D6: =""&'1 Affaire'!$C$6 | G6: =IF('1 Affaire'!$C$7="","",TEXT('1 Affaire'!$C$7,"dd/mm/yyyy")) | I6: =""&'1 Affaire'!$F$6
B7: =UPPER(INDEX(Textes!$B$2:$C$52,MATCH("attn",Textes!$A$2:$A$52,0),Listes!$H$1)) | D7: =UPPER(INDEX(Textes!$B$2:$C$52,MATCH("well",Textes!$A$2:$A$52,0),Listes!$H$1)) | G7: =UPPER(INDEX(Textes!$B$2:$C$52,MATCH("rig",Textes!$A$2:$A$52,0),Listes!$H$1)) | I7: =UPPER(INDEX(Textes!$B$2:$C$52,MATCH("mail",Textes!$A$2:$A$52,0),Listes!$H$1))
B8: =""&'1 Affaire'!$C$9 | D8: =""&'1 Affaire'!$C$10 | G8: =""&'1 Affaire'!$C$11 | I8: =""&'1 Affaire'!$F$7
B9: =UPPER(INDEX(Textes!$B$2:$C$52,MATCH("inco",Textes!$A$2:$A$52,0),Listes!$H$1)) | D9: =UPPER(INDEX(Textes!$B$2:$C$52,MATCH("valid",Textes!$A$2:$A$52,0),Listes!$H$1)) | G9: =UPPER(INDEX(Textes!$B$2:$C$52,MATCH("lead",Textes!$A$2:$A$52,0),Listes!$H$1)) | I9: =UPPER(INDEX(Textes!$B$2:$C$52,MATCH("tel",Textes!$A$2:$A$52,0),Listes!$H$1))
B10: =""&'1 Affaire'!$F$10 | D10: =""&'1 Affaire'!$F$9 | G10: =""&'1 Affaire'!$F$11 | I10: =""&'1 Affaire'!$F$8
B11: =UPPER(INDEX(Textes!$B$2:$C$52,MATCH("pay",Textes!$A$2:$A$52,0),Listes!$H$1)) | D11: =UPPER(INDEX(Textes!$B$2:$C$52,MATCH("we",Textes!$A$2:$A$52,0),Listes!$H$1))
B12: =""&'1 Affaire'!$F$12 | D12: =""&'1 Affaire'!$F$13
B14: =INDEX(Textes!$B$2:$C$52,MATCH("sec_eq",Textes!$A$2:$A$52,0),Listes!$H$1)
B15: =INDEX(Textes!$B$2:$C$52,MATCH("h_n",Textes!$A$2:$A$52,0),Listes!$H$1) | C15: =INDEX(Textes!$B$2:$C$52,MATCH("h_desc",Textes!$A$2:$A$52,0),Listes!$H$1) | D15: =INDEX(Textes!$B$2:$C$52,MATCH("h_qty",Textes!$A$2:$A$52,0),Listes!$H$1) | E15: =INDEX(Textes!$B$2:$C$52,MATCH("h_s",Textes!$A$2:$A$52,0),Listes!$H$1) | F15: =INDEX(Textes!$B$2:$C$52,MATCH("h_o",Textes!$A$2:$A$52,0),Listes!$H$1) | G15: =INDEX(Textes!$B$2:$C$52,MATCH("h_uc",Textes!$A$2:$A$52,0),Listes!$H$1) | H15: =INDEX(Textes!$B$2:$C$52,MATCH("h_lih",Textes!$A$2:$A$52,0),Listes!$H$1) | I15: =INDEX(Textes!$B$2:$C$52,MATCH("h_insp",Textes!$A$2:$A$52,0),Listes!$H$1) | J15: =INDEX(Textes!$B$2:$C$52,MATCH("h_rest",Textes!$A$2:$A$52,0),Listes!$H$1) | K15: =INDEX(Textes!$B$2:$C$52,MATCH("h_ref",Textes!$A$2:$A$52,0),Listes!$H$1)
B16: =IF(AND('2 Matériel'!$M6>0,NOT('2 Matériel'!$B6="Oui")),'2 Matériel'!$A6,"") | C16: =IF('2 Matériel'!$M6>0,IF('2 Matériel'!$B6="Oui",UPPER('2 Matériel'!$C6),'2 Matériel'!$C6),"") | D16: =IF(AND('2 Matériel'!$M6>0,NOT('2 Matériel'!$B6="Oui")),'2 Matériel'!$M6,"") | E16: =IF(AND('2 Matériel'!$M6>0,NOT('2 Matériel'!$B6="Oui")),IF(AND('2 Matériel'!$L6="Oui",'3 Options'!$C$16="Oui"),INDEX(Textes!$B$2:$C$52,MATCH("incl",Textes!$A$2:$A$52,0),Listes!$H$1),IF('2 Matériel'!$F6="","",'2 Matériel'!$F6)),"") | F16: =IF(AND('2 Matériel'!$M6>0,NOT('2 Matériel'!$B6="Oui")),IF(AND('2 Matériel'!$L6="Oui",'3 Options'!$C$16="Oui"),INDEX(Textes!$B$2:$C$52,MATCH("incl",Textes!$A$2:$A$52,0),Listes!$H$1),IF('2 Matériel'!$G6="","",'2 Matériel'!$G6)),"") | G16: =IF(AND('2 Matériel'!$M6>0,NOT('2 Matériel'!$B6="Oui")),IF(AND('2 Matériel'!$L6="Oui",'3 Options'!$C$16="Oui"),INDEX(Textes!$B$2:$C$52,MATCH("incl",Textes!$A$2:$A$52,0),Listes!$H$1),IF('2 Matériel'!$H6="","",'2 Matériel'!$H6)),"") | H16: =IF(AND('2 Matériel'!$M6>0,NOT('2 Matériel'!$B6="Oui")),IF(AND('2 Matériel'!$L6="Oui",'3 Options'!$C$16="Oui"),INDEX(Textes!$B$2:$C$52,MATCH("incl",Textes!$A$2:$A$52,0),Listes!$H$1),IF('2 Matériel'!$I6="","",'2 Matériel'!$I6)),"") | I16: =IF(AND('2 Matériel'!$M6>0,NOT('2 Matériel'!$B6="Oui")),IF(AND('2 Matériel'!$L6="Oui",'3 Options'!$C$16="Oui"),INDEX(Textes!$B$2:$C$52,MATCH("incl",Textes!$A$2:$A$52,0),Listes!$H$1),IF('2 Matériel'!$J6="","",'2 Matériel'!$J6)),"") | J16: =IF(AND('2 Matériel'!$M6>0,NOT('2 Matériel'!$B6="Oui")),IF(AND('2 Matériel'!$L6="Oui",'3 Options'!$C$16="Oui"),INDEX(Textes!$B$2:$C$52,MATCH("incl",Textes!$A$2:$A$52,0),Listes!$H$1),IF('2 Matériel'!$K6="","",'2 Matériel'!$K6)),"") | K16: =IF(AND('2 Matériel'!$M6>0,NOT('2 Matériel'!$B6="Oui")),IF(AND('2 Matériel'!$L6="Oui",'3 Options'!$C$16="Oui"),INDEX(Textes!$B$2:$C$52,MATCH("incl_long",Textes!$A$2:$A$52,0),Listes!$H$1),""),"") | M16: =IF(AND('2 Matériel'!$M6>0,'2 Matériel'!$B6="Oui"),1,0)
B17: =IF(AND('2 Matériel'!$M7>0,NOT('2 Matériel'!$B7="Oui")),'2 Matériel'!$A7,"") | C17: =IF('2 Matériel'!$M7>0,IF('2 Matériel'!$B7="Oui",UPPER('2 Matériel'!$C7),'2 Matériel'!$C7),"") | D17: =IF(AND('2 Matériel'!$M7>0,NOT('2 Matériel'!$B7="Oui")),'2 Matériel'!$M7,"") | E17: =IF(AND('2 Matériel'!$M7>0,NOT('2 Matériel'!$B7="Oui")),IF(AND('2 Matériel'!$L7="Oui",'3 Options'!$C$16="Oui"),INDEX(Textes!$B$2:$C$52,MATCH("incl",Textes!$A$2:$A$52,0),Listes!$H$1),IF('2 Matériel'!$F7="","",'2 Matériel'!$F7)),"") | F17: =IF(AND('2 Matériel'!$M7>0,NOT('2 Matériel'!$B7="Oui")),IF(AND('2 Matériel'!$L7="Oui",'3 Options'!$C$16="Oui"),INDEX(Textes!$B$2:$C$52,MATCH("incl",Textes!$A$2:$A$52,0),Listes!$H$1),IF('2 Matériel'!$G7="","",'2 Matériel'!$G7)),"") | G17: =IF(AND('2 Matériel'!$M7>0,NOT('2 Matériel'!$B7="Oui")),IF(AND('2 Matériel'!$L7="Oui",'3 Options'!$C$16="Oui"),INDEX(Textes!$B$2:$C$52,MATCH("incl",Textes!$A$2:$A$52,0),Listes!$H$1),IF('2 Matériel'!$H7="","",'2 Matériel'!$H7)),"") | H17: =IF(AND('2 Matériel'!$M7>0,NOT('2 Matériel'!$B7="Oui")),IF(AND('2 Matériel'!$L7="Oui",'3 Options'!$C$16="Oui"),INDEX(Textes!$B$2:$C$52,MATCH("incl",Textes!$A$2:$A$52,0),Listes!$H$1),IF('2 Matériel'!$I7="","",'2 Matériel'!$I7)),"") | I17: =IF(AND('2 Matériel'!$M7>0,NOT('2 Matériel'!$B7="Oui")),IF(AND('2 Matériel'!$L7="Oui",'3 Options'!$C$16="Oui"),INDEX(Textes!$B$2:$C$52,MATCH("incl",Textes!$A$2:$A$52,0),Listes!$H$1),IF('2 Matériel'!$J7="","",'2 Matériel'!$J7)),"") | J17: =IF(AND('2 Matériel'!$M7>0,NOT('2 Matériel'!$B7="Oui")),IF(AND('2 Matériel'!$L7="Oui",'3 Options'!$C$16="Oui"),INDEX(Textes!$B$2:$C$52,MATCH("incl",Textes!$A$2:$A$52,0),Listes!$H$1),IF('2 Matériel'!$K7="","",'2 Matériel'!$K7)),"") | K17: =IF(AND('2 Matériel'!$M7>0,NOT('2 Matériel'!$B7="Oui")),IF(AND('2 Matériel'!$L7="Oui",'3 Options'!$C$16="Oui"),INDEX(Textes!$B$2:$C$52,MATCH("incl_long",Textes!$A$2:$A$52,0),Listes!$H$1),""),"") | M17: =IF(AND('2 Matériel'!$M7>0,'2 Matériel'!$B7="Oui"),1,0)
B18: =IF(AND('2 Matériel'!$M8>0,NOT('2 Matériel'!$B8="Oui")),'2 Matériel'!$A8,"") | C18: =IF('2 Matériel'!$M8>0,IF('2 Matériel'!$B8="Oui",UPPER('2 Matériel'!$C8),'2 Matériel'!$C8),"") | D18: =IF(AND('2 Matériel'!$M8>0,NOT('2 Matériel'!$B8="Oui")),'2 Matériel'!$M8,"") | E18: =IF(AND('2 Matériel'!$M8>0,NOT('2 Matériel'!$B8="Oui")),IF(AND('2 Matériel'!$L8="Oui",'3 Options'!$C$16="Oui"),INDEX(Textes!$B$2:$C$52,MATCH("incl",Textes!$A$2:$A$52,0),Listes!$H$1),IF('2 Matériel'!$F8="","",'2 Matériel'!$F8)),"") | F18: =IF(AND('2 Matériel'!$M8>0,NOT('2 Matériel'!$B8="Oui")),IF(AND('2 Matériel'!$L8="Oui",'3 Options'!$C$16="Oui"),INDEX(Textes!$B$2:$C$52,MATCH("incl",Textes!$A$2:$A$52,0),Listes!$H$1),IF('2 Matériel'!$G8="","",'2 Matériel'!$G8)),"") | G18: =IF(AND('2 Matériel'!$M8>0,NOT('2 Matériel'!$B8="Oui")),IF(AND('2 Matériel'!$L8="Oui",'3 Options'!$C$16="Oui"),INDEX(Textes!$B$2:$C$52,MATCH("incl",Textes!$A$2:$A$52,0),Listes!$H$1),IF('2 Matériel'!$H8="","",'2 Matériel'!$H8)),"") | H18: =IF(AND('2 Matériel'!$M8>0,NOT('2 Matériel'!$B8="Oui")),IF(AND('2 Matériel'!$L8="Oui",'3 Options'!$C$16="Oui"),INDEX(Textes!$B$2:$C$52,MATCH("incl",Textes!$A$2:$A$52,0),Listes!$H$1),IF('2 Matériel'!$I8="","",'2 Matériel'!$I8)),"") | I18: =IF(AND('2 Matériel'!$M8>0,NOT('2 Matériel'!$B8="Oui")),IF(AND('2 Matériel'!$L8="Oui",'3 Options'!$C$16="Oui"),INDEX(Textes!$B$2:$C$52,MATCH("incl",Textes!$A$2:$A$52,0),Listes!$H$1),IF('2 Matériel'!$J8="","",'2 Matériel'!$J8)),"") | J18: =IF(AND('2 Matériel'!$M8>0,NOT('2 Matériel'!$B8="Oui")),IF(AND('2 Matériel'!$L8="Oui",'3 Options'!$C$16="Oui"),INDEX(Textes!$B$2:$C$52,MATCH("incl",Textes!$A$2:$A$52,0),Listes!$H$1),IF('2 Matériel'!$K8="","",'2 Matériel'!$K8)),"") | K18: =IF(AND('2 Matériel'!$M8>0,NOT('2 Matériel'!$B8="Oui")),IF(AND('2 Matériel'!$L8="Oui",'3 Options'!$C$16="Oui"),INDEX(Textes!$B$2:$C$52,MATCH("incl_long",Textes!$A$2:$A$52,0),Listes!$H$1),""),"") | M18: =IF(AND('2 Matériel'!$M8>0,'2 Matériel'!$B8="Oui"),1,0)
B19: =IF(AND('2 Matériel'!$M9>0,NOT('2 Matériel'!$B9="Oui")),'2 Matériel'!$A9,"") | C19: =IF('2 Matériel'!$M9>0,IF('2 Matériel'!$B9="Oui",UPPER('2 Matériel'!$C9),'2 Matériel'!$C9),"") | D19: =IF(AND('2 Matériel'!$M9>0,NOT('2 Matériel'!$B9="Oui")),'2 Matériel'!$M9,"") | E19: =IF(AND('2 Matériel'!$M9>0,NOT('2 Matériel'!$B9="Oui")),IF(AND('2 Matériel'!$L9="Oui",'3 Options'!$C$16="Oui"),INDEX(Textes!$B$2:$C$52,MATCH("incl",Textes!$A$2:$A$52,0),Listes!$H$1),IF('2 Matériel'!$F9="","",'2 Matériel'!$F9)),"") | F19: =IF(AND('2 Matériel'!$M9>0,NOT('2 Matériel'!$B9="Oui")),IF(AND('2 Matériel'!$L9="Oui",'3 Options'!$C$16="Oui"),INDEX(Textes!$B$2:$C$52,MATCH("incl",Textes!$A$2:$A$52,0),Listes!$H$1),IF('2 Matériel'!$G9="","",'2 Matériel'!$G9)),"") | G19: =IF(AND('2 Matériel'!$M9>0,NOT('2 Matériel'!$B9="Oui")),IF(AND('2 Matériel'!$L9="Oui",'3 Options'!$C$16="Oui"),INDEX(Textes!$B$2:$C$52,MATCH("incl",Textes!$A$2:$A$52,0),Listes!$H$1),IF('2 Matériel'!$H9="","",'2 Matériel'!$H9)),"") | H19: =IF(AND('2 Matériel'!$M9>0,NOT('2 Matériel'!$B9="Oui")),IF(AND('2 Matériel'!$L9="Oui",'3 Options'!$C$16="Oui"),INDEX(Textes!$B$2:$C$52,MATCH("incl",Textes!$A$2:$A$52,0),Listes!$H$1),IF('2 Matériel'!$I9="","",'2 Matériel'!$I9)),"") | I19: =IF(AND('2 Matériel'!$M9>0,NOT('2 Matériel'!$B9="Oui")),IF(AND('2 Matériel'!$L9="Oui",'3 Options'!$C$16="Oui"),INDEX(Textes!$B$2:$C$52,MATCH("incl",Textes!$A$2:$A$52,0),Listes!$H$1),IF('2 Matériel'!$J9="","",'2 Matériel'!$J9)),"") | J19: =IF(AND('2 Matériel'!$M9>0,NOT('2 Matériel'!$B9="Oui")),IF(AND('2 Matériel'!$L9="Oui",'3 Options'!$C$16="Oui"),INDEX(Textes!$B$2:$C$52,MATCH("incl",Textes!$A$2:$A$52,0),Listes!$H$1),IF('2 Matériel'!$K9="","",'2 Matériel'!$K9)),"") | K19: =IF(AND('2 Matériel'!$M9>0,NOT('2 Matériel'!$B9="Oui")),IF(AND('2 Matériel'!$L9="Oui",'3 Options'!$C$16="Oui"),INDEX(Textes!$B$2:$C$52,MATCH("incl_long",Textes!$A$2:$A$52,0),Listes!$H$1),""),"") | M19: =IF(AND('2 Matériel'!$M9>0,'2 Matériel'!$B9="Oui"),1,0)
B20: =IF(AND('2 Matériel'!$M10>0,NOT('2 Matériel'!$B10="Oui")),'2 Matériel'!$A10,"") | C20: =IF('2 Matériel'!$M10>0,IF('2 Matériel'!$B10="Oui",UPPER('2 Matériel'!$C10),'2 Matériel'!$C10),"") | D20: =IF(AND('2 Matériel'!$M10>0,NOT('2 Matériel'!$B10="Oui")),'2 Matériel'!$M10,"") | E20: =IF(AND('2 Matériel'!$M10>0,NOT('2 Matériel'!$B10="Oui")),IF(AND('2 Matériel'!$L10="Oui",'3 Options'!$C$16="Oui"),INDEX(Textes!$B$2:$C$52,MATCH("incl",Textes!$A$2:$A$52,0),Listes!$H$1),IF('2 Matériel'!$F10="","",'2 Matériel'!$F10)),"") | F20: =IF(AND('2 Matériel'!$M10>0,NOT('2 Matériel'!$B10="Oui")),IF(AND('2 Matériel'!$L10="Oui",'3 Options'!$C$16="Oui"),INDEX(Textes!$B$2:$C$52,MATCH("incl",Textes!$A$2:$A$52,0),Listes!$H$1),IF('2 Matériel'!$G10="","",'2 Matériel'!$G10)),"") | G20: =IF(AND('2 Matériel'!$M10>0,NOT('2 Matériel'!$B10="Oui")),IF(AND('2 Matériel'!$L10="Oui",'3 Options'!$C$16="Oui"),INDEX(Textes!$B$2:$C$52,MATCH("incl",Textes!$A$2:$A$52,0),Listes!$H$1),IF('2 Matériel'!$H10="","",'2 Matériel'!$H10)),"") | H20: =IF(AND('2 Matériel'!$M10>0,NOT('2 Matériel'!$B10="Oui")),IF(AND('2 Matériel'!$L10="Oui",'3 Options'!$C$16="Oui"),INDEX(Textes!$B$2:$C$52,MATCH("incl",Textes!$A$2:$A$52,0),Listes!$H$1),IF('2 Matériel'!$I10="","",'2 Matériel'!$I10)),"") | I20: =IF(AND('2 Matériel'!$M10>0,NOT('2 Matériel'!$B10="Oui")),IF(AND('2 Matériel'!$L10="Oui",'3 Options'!$C$16="Oui"),INDEX(Textes!$B$2:$C$52,MATCH("incl",Textes!$A$2:$A$52,0),Listes!$H$1),IF('2 Matériel'!$J10="","",'2 Matériel'!$J10)),"") | J20: =IF(AND('2 Matériel'!$M10>0,NOT('2 Matériel'!$B10="Oui")),IF(AND('2 Matériel'!$L10="Oui",'3 Options'!$C$16="Oui"),INDEX(Textes!$B$2:$C$52,MATCH("incl",Textes!$A$2:$A$52,0),Listes!$H$1),IF('2 Matériel'!$K10="","",'2 Matériel'!$K10)),"") | K20: =IF(AND('2 Matériel'!$M10>0,NOT('2 Matériel'!$B10="Oui")),IF(AND('2 Matériel'!$L10="Oui",'3 Options'!$C$16="Oui"),INDEX(Textes!$B$2:$C$52,MATCH("incl_long",Textes!$A$2:$A$52,0),Listes!$H$1),""),"") | M20: =IF(AND('2 Matériel'!$M10>0,'2 Matériel'!$B10="Oui"),1,0)
B21: =IF(AND('2 Matériel'!$M11>0,NOT('2 Matériel'!$B11="Oui")),'2 Matériel'!$A11,"") | C21: =IF('2 Matériel'!$M11>0,IF('2 Matériel'!$B11="Oui",UPPER('2 Matériel'!$C11),'2 Matériel'!$C11),"") | D21: =IF(AND('2 Matériel'!$M11>0,NOT('2 Matériel'!$B11="Oui")),'2 Matériel'!$M11,"") | E21: =IF(AND('2 Matériel'!$M11>0,NOT('2 Matériel'!$B11="Oui")),IF(AND('2 Matériel'!$L11="Oui",'3 Options'!$C$16="Oui"),INDEX(Textes!$B$2:$C$52,MATCH("incl",Textes!$A$2:$A$52,0),Listes!$H$1),IF('2 Matériel'!$F11="","",'2 Matériel'!$F11)),"") | F21: =IF(AND('2 Matériel'!$M11>0,NOT('2 Matériel'!$B11="Oui")),IF(AND('2 Matériel'!$L11="Oui",'3 Options'!$C$16="Oui"),INDEX(Textes!$B$2:$C$52,MATCH("incl",Textes!$A$2:$A$52,0),Listes!$H$1),IF('2 Matériel'!$G11="","",'2 Matériel'!$G11)),"") | G21: =IF(AND('2 Matériel'!$M11>0,NOT('2 Matériel'!$B11="Oui")),IF(AND('2 Matériel'!$L11="Oui",'3 Options'!$C$16="Oui"),INDEX(Textes!$B$2:$C$52,MATCH("incl",Textes!$A$2:$A$52,0),Listes!$H$1),IF('2 Matériel'!$H11="","",'2 Matériel'!$H11)),"") | H21: =IF(AND('2 Matériel'!$M11>0,NOT('2 Matériel'!$B11="Oui")),IF(AND('2 Matériel'!$L11="Oui",'3 Options'!$C$16="Oui"),INDEX(Textes!$B$2:$C$52,MATCH("incl",Textes!$A$2:$A$52,0),Listes!$H$1),IF('2 Matériel'!$I11="","",'2 Matériel'!$I11)),"") | I21: =IF(AND('2 Matériel'!$M11>0,NOT('2 Matériel'!$B11="Oui")),IF(AND('2 Matériel'!$L11="Oui",'3 Options'!$C$16="Oui"),INDEX(Textes!$B$2:$C$52,MATCH("incl",Textes!$A$2:$A$52,0),Listes!$H$1),IF('2 Matériel'!$J11="","",'2 Matériel'!$J11)),"") | J21: =IF(AND('2 Matériel'!$M11>0,NOT('2 Matériel'!$B11="Oui")),IF(AND('2 Matériel'!$L11="Oui",'3 Options'!$C$16="Oui"),INDEX(Textes!$B$2:$C$52,MATCH("incl",Textes!$A$2:$A$52,0),Listes!$H$1),IF('2 Matériel'!$K11="","",'2 Matériel'!$K11)),"") | K21: =IF(AND('2 Matériel'!$M11>0,NOT('2 Matériel'!$B11="Oui")),IF(AND('2 Matériel'!$L11="Oui",'3 Options'!$C$16="Oui"),INDEX(Textes!$B$2:$C$52,MATCH("incl_long",Textes!$A$2:$A$52,0),Listes!$H$1),""),"") | M21: =IF(AND('2 Matériel'!$M11>0,'2 Matériel'!$B11="Oui"),1,0)
B22: =IF(AND('2 Matériel'!$M12>0,NOT('2 Matériel'!$B12="Oui")),'2 Matériel'!$A12,"") | C22: =IF('2 Matériel'!$M12>0,IF('2 Matériel'!$B12="Oui",UPPER('2 Matériel'!$C12),'2 Matériel'!$C12),"") | D22: =IF(AND('2 Matériel'!$M12>0,NOT('2 Matériel'!$B12="Oui")),'2 Matériel'!$M12,"") | E22: =IF(AND('2 Matériel'!$M12>0,NOT('2 Matériel'!$B12="Oui")),IF(AND('2 Matériel'!$L12="Oui",'3 Options'!$C$16="Oui"),INDEX(Textes!$B$2:$C$52,MATCH("incl",Textes!$A$2:$A$52,0),Listes!$H$1),IF('2 Matériel'!$F12="","",'2 Matériel'!$F12)),"") | F22: =IF(AND('2 Matériel'!$M12>0,NOT('2 Matériel'!$B12="Oui")),IF(AND('2 Matériel'!$L12="Oui",'3 Options'!$C$16="Oui"),INDEX(Textes!$B$2:$C$52,MATCH("incl",Textes!$A$2:$A$52,0),Listes!$H$1),IF('2 Matériel'!$G12="","",'2 Matériel'!$G12)),"") | G22: =IF(AND('2 Matériel'!$M12>0,NOT('2 Matériel'!$B12="Oui")),IF(AND('2 Matériel'!$L12="Oui",'3 Options'!$C$16="Oui"),INDEX(Textes!$B$2:$C$52,MATCH("incl",Textes!$A$2:$A$52,0),Listes!$H$1),IF('2 Matériel'!$H12="","",'2 Matériel'!$H12)),"") | H22: =IF(AND('2 Matériel'!$M12>0,NOT('2 Matériel'!$B12="Oui")),IF(AND('2 Matériel'!$L12="Oui",'3 Options'!$C$16="Oui"),INDEX(Textes!$B$2:$C$52,MATCH("incl",Textes!$A$2:$A$52,0),Listes!$H$1),IF('2 Matériel'!$I12="","",'2 Matériel'!$I12)),"") | I22: =IF(AND('2 Matériel'!$M12>0,NOT('2 Matériel'!$B12="Oui")),IF(AND('2 Matériel'!$L12="Oui",'3 Options'!$C$16="Oui"),INDEX(Textes!$B$2:$C$52,MATCH("incl",Textes!$A$2:$A$52,0),Listes!$H$1),IF('2 Matériel'!$J12="","",'2 Matériel'!$J12)),"") | J22: =IF(AND('2 Matériel'!$M12>0,NOT('2 Matériel'!$B12="Oui")),IF(AND('2 Matériel'!$L12="Oui",'3 Options'!$C$16="Oui"),INDEX(Textes!$B$2:$C$52,MATCH("incl",Textes!$A$2:$A$52,0),Listes!$H$1),IF('2 Matériel'!$K12="","",'2 Matériel'!$K12)),"") | K22: =IF(AND('2 Matériel'!$M12>0,NOT('2 Matériel'!$B12="Oui")),IF(AND('2 Matériel'!$L12="Oui",'3 Options'!$C$16="Oui"),INDEX(Textes!$B$2:$C$52,MATCH("incl_long",Textes!$A$2:$A$52,0),Listes!$H$1),""),"") | M22: =IF(AND('2 Matériel'!$M12>0,'2 Matériel'!$B12="Oui"),1,0)
B23: =IF(AND('2 Matériel'!$M13>0,NOT('2 Matériel'!$B13="Oui")),'2 Matériel'!$A13,"") | C23: =IF('2 Matériel'!$M13>0,IF('2 Matériel'!$B13="Oui",UPPER('2 Matériel'!$C13),'2 Matériel'!$C13),"") | D23: =IF(AND('2 Matériel'!$M13>0,NOT('2 Matériel'!$B13="Oui")),'2 Matériel'!$M13,"") | E23: =IF(AND('2 Matériel'!$M13>0,NOT('2 Matériel'!$B13="Oui")),IF(AND('2 Matériel'!$L13="Oui",'3 Options'!$C$16="Oui"),INDEX(Textes!$B$2:$C$52,MATCH("incl",Textes!$A$2:$A$52,0),Listes!$H$1),IF('2 Matériel'!$F13="","",'2 Matériel'!$F13)),"") | F23: =IF(AND('2 Matériel'!$M13>0,NOT('2 Matériel'!$B13="Oui")),IF(AND('2 Matériel'!$L13="Oui",'3 Options'!$C$16="Oui"),INDEX(Textes!$B$2:$C$52,MATCH("incl",Textes!$A$2:$A$52,0),Listes!$H$1),IF('2 Matériel'!$G13="","",'2 Matériel'!$G13)),"") | G23: =IF(AND('2 Matériel'!$M13>0,NOT('2 Matériel'!$B13="Oui")),IF(AND('2 Matériel'!$L13="Oui",'3 Options'!$C$16="Oui"),INDEX(Textes!$B$2:$C$52,MATCH("incl",Textes!$A$2:$A$52,0),Listes!$H$1),IF('2 Matériel'!$H13="","",'2 Matériel'!$H13)),"") | H23: =IF(AND('2 Matériel'!$M13>0,NOT('2 Matériel'!$B13="Oui")),IF(AND('2 Matériel'!$L13="Oui",'3 Options'!$C$16="Oui"),INDEX(Textes!$B$2:$C$52,MATCH("incl",Textes!$A$2:$A$52,0),Listes!$H$1),IF('2 Matériel'!$I13="","",'2 Matériel'!$I13)),"") | I23: =IF(AND('2 Matériel'!$M13>0,NOT('2 Matériel'!$B13="Oui")),IF(AND('2 Matériel'!$L13="Oui",'3 Options'!$C$16="Oui"),INDEX(Textes!$B$2:$C$52,MATCH("incl",Textes!$A$2:$A$52,0),Listes!$H$1),IF('2 Matériel'!$J13="","",'2 Matériel'!$J13)),"") | J23: =IF(AND('2 Matériel'!$M13>0,NOT('2 Matériel'!$B13="Oui")),IF(AND('2 Matériel'!$L13="Oui",'3 Options'!$C$16="Oui"),INDEX(Textes!$B$2:$C$52,MATCH("incl",Textes!$A$2:$A$52,0),Listes!$H$1),IF('2 Matériel'!$K13="","",'2 Matériel'!$K13)),"") | K23: =IF(AND('2 Matériel'!$M13>0,NOT('2 Matériel'!$B13="Oui")),IF(AND('2 Matériel'!$L13="Oui",'3 Options'!$C$16="Oui"),INDEX(Textes!$B$2:$C$52,MATCH("incl_long",Textes!$A$2:$A$52,0),Listes!$H$1),""),"") | M23: =IF(AND('2 Matériel'!$M13>0,'2 Matériel'!$B13="Oui"),1,0)
B24: =IF(AND('2 Matériel'!$M14>0,NOT('2 Matériel'!$B14="Oui")),'2 Matériel'!$A14,"") | C24: =IF('2 Matériel'!$M14>0,IF('2 Matériel'!$B14="Oui",UPPER('2 Matériel'!$C14),'2 Matériel'!$C14),"") | D24: =IF(AND('2 Matériel'!$M14>0,NOT('2 Matériel'!$B14="Oui")),'2 Matériel'!$M14,"") | E24: =IF(AND('2 Matériel'!$M14>0,NOT('2 Matériel'!$B14="Oui")),IF(AND('2 Matériel'!$L14="Oui",'3 Options'!$C$16="Oui"),INDEX(Textes!$B$2:$C$52,MATCH("incl",Textes!$A$2:$A$52,0),Listes!$H$1),IF('2 Matériel'!$F14="","",'2 Matériel'!$F14)),"") | F24: =IF(AND('2 Matériel'!$M14>0,NOT('2 Matériel'!$B14="Oui")),IF(AND('2 Matériel'!$L14="Oui",'3 Options'!$C$16="Oui"),INDEX(Textes!$B$2:$C$52,MATCH("incl",Textes!$A$2:$A$52,0),Listes!$H$1),IF('2 Matériel'!$G14="","",'2 Matériel'!$G14)),"") | G24: =IF(AND('2 Matériel'!$M14>0,NOT('2 Matériel'!$B14="Oui")),IF(AND('2 Matériel'!$L14="Oui",'3 Options'!$C$16="Oui"),INDEX(Textes!$B$2:$C$52,MATCH("incl",Textes!$A$2:$A$52,0),Listes!$H$1),IF('2 Matériel'!$H14="","",'2 Matériel'!$H14)),"") | H24: =IF(AND('2 Matériel'!$M14>0,NOT('2 Matériel'!$B14="Oui")),IF(AND('2 Matériel'!$L14="Oui",'3 Options'!$C$16="Oui"),INDEX(Textes!$B$2:$C$52,MATCH("incl",Textes!$A$2:$A$52,0),Listes!$H$1),IF('2 Matériel'!$I14="","",'2 Matériel'!$I14)),"") | I24: =IF(AND('2 Matériel'!$M14>0,NOT('2 Matériel'!$B14="Oui")),IF(AND('2 Matériel'!$L14="Oui",'3 Options'!$C$16="Oui"),INDEX(Textes!$B$2:$C$52,MATCH("incl",Textes!$A$2:$A$52,0),Listes!$H$1),IF('2 Matériel'!$J14="","",'2 Matériel'!$J14)),"") | J24: =IF(AND('2 Matériel'!$M14>0,NOT('2 Matériel'!$B14="Oui")),IF(AND('2 Matériel'!$L14="Oui",'3 Options'!$C$16="Oui"),INDEX(Textes!$B$2:$C$52,MATCH("incl",Textes!$A$2:$A$52,0),Listes!$H$1),IF('2 Matériel'!$K14="","",'2 Matériel'!$K14)),"") | K24: =IF(AND('2 Matériel'!$M14>0,NOT('2 Matériel'!$B14="Oui")),IF(AND('2 Matériel'!$L14="Oui",'3 Options'!$C$16="Oui"),INDEX(Textes!$B$2:$C$52,MATCH("incl_long",Textes!$A$2:$A$52,0),Listes!$H$1),""),"") | M24: =IF(AND('2 Matériel'!$M14>0,'2 Matériel'!$B14="Oui"),1,0)
B25: =IF(AND('2 Matériel'!$M15>0,NOT('2 Matériel'!$B15="Oui")),'2 Matériel'!$A15,"") | C25: =IF('2 Matériel'!$M15>0,IF('2 Matériel'!$B15="Oui",UPPER('2 Matériel'!$C15),'2 Matériel'!$C15),"") | D25: =IF(AND('2 Matériel'!$M15>0,NOT('2 Matériel'!$B15="Oui")),'2 Matériel'!$M15,"") | E25: =IF(AND('2 Matériel'!$M15>0,NOT('2 Matériel'!$B15="Oui")),IF(AND('2 Matériel'!$L15="Oui",'3 Options'!$C$16="Oui"),INDEX(Textes!$B$2:$C$52,MATCH("incl",Textes!$A$2:$A$52,0),Listes!$H$1),IF('2 Matériel'!$F15="","",'2 Matériel'!$F15)),"") | F25: =IF(AND('2 Matériel'!$M15>0,NOT('2 Matériel'!$B15="Oui")),IF(AND('2 Matériel'!$L15="Oui",'3 Options'!$C$16="Oui"),INDEX(Textes!$B$2:$C$52,MATCH("incl",Textes!$A$2:$A$52,0),Listes!$H$1),IF('2 Matériel'!$G15="","",'2 Matériel'!$G15)),"") | G25: =IF(AND('2 Matériel'!$M15>0,NOT('2 Matériel'!$B15="Oui")),IF(AND('2 Matériel'!$L15="Oui",'3 Options'!$C$16="Oui"),INDEX(Textes!$B$2:$C$52,MATCH("incl",Textes!$A$2:$A$52,0),Listes!$H$1),IF('2 Matériel'!$H15="","",'2 Matériel'!$H15)),"") | H25: =IF(AND('2 Matériel'!$M15>0,NOT('2 Matériel'!$B15="Oui")),IF(AND('2 Matériel'!$L15="Oui",'3 Options'!$C$16="Oui"),INDEX(Textes!$B$2:$C$52,MATCH("incl",Textes!$A$2:$A$52,0),Listes!$H$1),IF('2 Matériel'!$I15="","",'2 Matériel'!$I15)),"") | I25: =IF(AND('2 Matériel'!$M15>0,NOT('2 Matériel'!$B15="Oui")),IF(AND('2 Matériel'!$L15="Oui",'3 Options'!$C$16="Oui"),INDEX(Textes!$B$2:$C$52,MATCH("incl",Textes!$A$2:$A$52,0),Listes!$H$1),IF('2 Matériel'!$J15="","",'2 Matériel'!$J15)),"") | J25: =IF(AND('2 Matériel'!$M15>0,NOT('2 Matériel'!$B15="Oui")),IF(AND('2 Matériel'!$L15="Oui",'3 Options'!$C$16="Oui"),INDEX(Textes!$B$2:$C$52,MATCH("incl",Textes!$A$2:$A$52,0),Listes!$H$1),IF('2 Matériel'!$K15="","",'2 Matériel'!$K15)),"") | K25: =IF(AND('2 Matériel'!$M15>0,NOT('2 Matériel'!$B15="Oui")),IF(AND('2 Matériel'!$L15="Oui",'3 Options'!$C$16="Oui"),INDEX(Textes!$B$2:$C$52,MATCH("incl_long",Textes!$A$2:$A$52,0),Listes!$H$1),""),"") | M25: =IF(AND('2 Matériel'!$M15>0,'2 Matériel'!$B15="Oui"),1,0)
B26: =IF(AND('2 Matériel'!$M16>0,NOT('2 Matériel'!$B16="Oui")),'2 Matériel'!$A16,"") | C26: =IF('2 Matériel'!$M16>0,IF('2 Matériel'!$B16="Oui",UPPER('2 Matériel'!$C16),'2 Matériel'!$C16),"") | D26: =IF(AND('2 Matériel'!$M16>0,NOT('2 Matériel'!$B16="Oui")),'2 Matériel'!$M16,"") | E26: =IF(AND('2 Matériel'!$M16>0,NOT('2 Matériel'!$B16="Oui")),IF(AND('2 Matériel'!$L16="Oui",'3 Options'!$C$16="Oui"),INDEX(Textes!$B$2:$C$52,MATCH("incl",Textes!$A$2:$A$52,0),Listes!$H$1),IF('2 Matériel'!$F16="","",'2 Matériel'!$F16)),"") | F26: =IF(AND('2 Matériel'!$M16>0,NOT('2 Matériel'!$B16="Oui")),IF(AND('2 Matériel'!$L16="Oui",'3 Options'!$C$16="Oui"),INDEX(Textes!$B$2:$C$52,MATCH("incl",Textes!$A$2:$A$52,0),Listes!$H$1),IF('2 Matériel'!$G16="","",'2 Matériel'!$G16)),"") | G26: =IF(AND('2 Matériel'!$M16>0,NOT('2 Matériel'!$B16="Oui")),IF(AND('2 Matériel'!$L16="Oui",'3 Options'!$C$16="Oui"),INDEX(Textes!$B$2:$C$52,MATCH("incl",Textes!$A$2:$A$52,0),Listes!$H$1),IF('2 Matériel'!$H16="","",'2 Matériel'!$H16)),"") | H26: =IF(AND('2 Matériel'!$M16>0,NOT('2 Matériel'!$B16="Oui")),IF(AND('2 Matériel'!$L16="Oui",'3 Options'!$C$16="Oui"),INDEX(Textes!$B$2:$C$52,MATCH("incl",Textes!$A$2:$A$52,0),Listes!$H$1),IF('2 Matériel'!$I16="","",'2 Matériel'!$I16)),"") | I26: =IF(AND('2 Matériel'!$M16>0,NOT('2 Matériel'!$B16="Oui")),IF(AND('2 Matériel'!$L16="Oui",'3 Options'!$C$16="Oui"),INDEX(Textes!$B$2:$C$52,MATCH("incl",Textes!$A$2:$A$52,0),Listes!$H$1),IF('2 Matériel'!$J16="","",'2 Matériel'!$J16)),"") | J26: =IF(AND('2 Matériel'!$M16>0,NOT('2 Matériel'!$B16="Oui")),IF(AND('2 Matériel'!$L16="Oui",'3 Options'!$C$16="Oui"),INDEX(Textes!$B$2:$C$52,MATCH("incl",Textes!$A$2:$A$52,0),Listes!$H$1),IF('2 Matériel'!$K16="","",'2 Matériel'!$K16)),"") | K26: =IF(AND('2 Matériel'!$M16>0,NOT('2 Matériel'!$B16="Oui")),IF(AND('2 Matériel'!$L16="Oui",'3 Options'!$C$16="Oui"),INDEX(Textes!$B$2:$C$52,MATCH("incl_long",Textes!$A$2:$A$52,0),Listes!$H$1),""),"") | M26: =IF(AND('2 Matériel'!$M16>0,'2 Matériel'!$B16="Oui"),1,0)
B27: =IF(AND('2 Matériel'!$M17>0,NOT('2 Matériel'!$B17="Oui")),'2 Matériel'!$A17,"") | C27: =IF('2 Matériel'!$M17>0,IF('2 Matériel'!$B17="Oui",UPPER('2 Matériel'!$C17),'2 Matériel'!$C17),"") | D27: =IF(AND('2 Matériel'!$M17>0,NOT('2 Matériel'!$B17="Oui")),'2 Matériel'!$M17,"") | E27: =IF(AND('2 Matériel'!$M17>0,NOT('2 Matériel'!$B17="Oui")),IF(AND('2 Matériel'!$L17="Oui",'3 Options'!$C$16="Oui"),INDEX(Textes!$B$2:$C$52,MATCH("incl",Textes!$A$2:$A$52,0),Listes!$H$1),IF('2 Matériel'!$F17="","",'2 Matériel'!$F17)),"") | F27: =IF(AND('2 Matériel'!$M17>0,NOT('2 Matériel'!$B17="Oui")),IF(AND('2 Matériel'!$L17="Oui",'3 Options'!$C$16="Oui"),INDEX(Textes!$B$2:$C$52,MATCH("incl",Textes!$A$2:$A$52,0),Listes!$H$1),IF('2 Matériel'!$G17="","",'2 Matériel'!$G17)),"") | G27: =IF(AND('2 Matériel'!$M17>0,NOT('2 Matériel'!$B17="Oui")),IF(AND('2 Matériel'!$L17="Oui",'3 Options'!$C$16="Oui"),INDEX(Textes!$B$2:$C$52,MATCH("incl",Textes!$A$2:$A$52,0),Listes!$H$1),IF('2 Matériel'!$H17="","",'2 Matériel'!$H17)),"") | H27: =IF(AND('2 Matériel'!$M17>0,NOT('2 Matériel'!$B17="Oui")),IF(AND('2 Matériel'!$L17="Oui",'3 Options'!$C$16="Oui"),INDEX(Textes!$B$2:$C$52,MATCH("incl",Textes!$A$2:$A$52,0),Listes!$H$1),IF('2 Matériel'!$I17="","",'2 Matériel'!$I17)),"") | I27: =IF(AND('2 Matériel'!$M17>0,NOT('2 Matériel'!$B17="Oui")),IF(AND('2 Matériel'!$L17="Oui",'3 Options'!$C$16="Oui"),INDEX(Textes!$B$2:$C$52,MATCH("incl",Textes!$A$2:$A$52,0),Listes!$H$1),IF('2 Matériel'!$J17="","",'2 Matériel'!$J17)),"") | J27: =IF(AND('2 Matériel'!$M17>0,NOT('2 Matériel'!$B17="Oui")),IF(AND('2 Matériel'!$L17="Oui",'3 Options'!$C$16="Oui"),INDEX(Textes!$B$2:$C$52,MATCH("incl",Textes!$A$2:$A$52,0),Listes!$H$1),IF('2 Matériel'!$K17="","",'2 Matériel'!$K17)),"") | K27: =IF(AND('2 Matériel'!$M17>0,NOT('2 Matériel'!$B17="Oui")),IF(AND('2 Matériel'!$L17="Oui",'3 Options'!$C$16="Oui"),INDEX(Textes!$B$2:$C$52,MATCH("incl_long",Textes!$A$2:$A$52,0),Listes!$H$1),""),"") | M27: =IF(AND('2 Matériel'!$M17>0,'2 Matériel'!$B17="Oui"),1,0)
... B39: =IF(AND('2 Matériel'!$M29>0,NOT('2 Matériel'!$B29="Oui")),'2 Matériel'!$A29,"") | C39: =IF('2 Matériel'!$M29>0,IF('2 Matériel'!$B29="Oui",UPPER('2 Matériel'!$C29),'2 Matériel'!$C29),"") | D39: =IF(AND('2 Matériel'!$M29>0,NOT('2 Matériel'!$B29="Oui")),'2 Matériel'!$M29,"") | E39: =IF(AND('2 Matériel'!$M29>0,NOT('2 Matériel'!$B29="Oui")),IF(AND('2 Matériel'!$L29="Oui",'3 Options'!$C$16="Oui"),INDEX(Textes!$B$2:$C$52,MATCH("incl",Textes!$A$2:$A$52,0),Listes!$H$1),IF('2 Matériel'!$F29="","",'2 Matériel'!$F29)),"") | F39: =IF(AND('2 Matériel'!$M29>0,NOT('2 Matériel'!$B29="Oui")),IF(AND('2 Matériel'!$L29="Oui",'3 Options'!$C$16="Oui"),INDEX(Textes!$B$2:$C$52,MATCH("incl",Textes!$A$2:$A$52,0),Listes!$H$1),IF('2 Matériel'!$G29="","",'2 Matériel'!$G29)),"") | G39: =IF(AND('2 Matériel'!$M29>0,NOT('2 Matériel'!$B29="Oui")),IF(AND('2 Matériel'!$L29="Oui",'3 Options'!$C$16="Oui"),INDEX(Textes!$B$2:$C$52,MATCH("incl",Textes!$A$2:$A$52,0),Listes!$H$1),IF('2 Matériel'!$H29="","",'2 Matériel'!$H29)),"") | H39: =IF(AND('2 Matériel'!$M29>0,NOT('2 Matériel'!$B29="Oui")),IF(AND('2 Matériel'!$L29="Oui",'3 Options'!$C$16="Oui"),INDEX(Textes!$B$2:$C$52,MATCH("incl",Textes!$A$2:$A$52,0),Listes!$H$1),IF('2 Matériel'!$I29="","",'2 Matériel'!$I29)),"") | I39: =IF(AND('2 Matériel'!$M29>0,NOT('2 Matériel'!$B29="Oui")),IF(AND('2 Matériel'!$L29="Oui",'3 Options'!$C$16="Oui"),INDEX(Textes!$B$2:$C$52,MATCH("incl",Textes!$A$2:$A$52,0),Listes!$H$1),IF('2 Matériel'!$J29="","",'2 Matériel'!$J29)),"") | J39: =IF(AND('2 Matériel'!$M29>0,NOT('2 Matériel'!$B29="Oui")),IF(AND('2 Matériel'!$L29="Oui",'3 Options'!$C$16="Oui"),INDEX(Textes!$B$2:$C$52,MATCH("incl",Textes!$A$2:$A$52,0),Listes!$H$1),IF('2 Matériel'!$K29="","",'2 Matériel'!$K29)),"") | K39: =IF(AND('2 Matériel'!$M29>0,NOT('2 Matériel'!$B29="Oui")),IF(AND('2 Matériel'!$L29="Oui",'3 Options'!$C$16="Oui"),INDEX(Textes!$B$2:$C$52,MATCH("incl_long",Textes!$A$2:$A$52,0),Listes!$H$1),""),"") | M39: =IF(AND('2 Matériel'!$M29>0,'2 Matériel'!$B29="Oui"),1,0)
B40: =IF(SUM('2 Matériel'!$M$20:$M$29)>0,"⚠ Des lignes de matériel au-delà de la ligne 14 sont masquées : cliquer sur le [+] dans la marge gauche pour les afficher.","")
B42: =IF('3 Options'!$C$16="Oui",UPPER(INDEX(Textes!$B$2:$C$52,MATCH("forfait",Textes!$A$2:$A$52,0),Listes!$H$1)),"") | M42: =IF('3 Options'!$C$16="Oui",1,0)
B43: =IF('3 Options'!$C$16="Oui",IF('3 Options'!$D$16<>"",'3 Options'!$D$16,INDEX(Textes!$B$2:$C$52,MATCH("forfait",Textes!$A$2:$A$52,0),Listes!$H$1)),"") | I43: =IF('3 Options'!$C$16="Oui",'3 Options'!$H$16,"")
B44: =IF('3 Options'!$C$16="Oui",IF('3 Options'!$G$16="Forfait calculé (S + O + UC)",'3 Options'!$C$18&" "&SUBSTITUTE(INDEX(Textes!$B$2:$C$52,MATCH("calc_det",Textes!$A$2:$A$52,0),Listes!$H$1),"%s",'3 Options'!$C$19),IF('3 Options'!$G$16="Forfait par jour",'3 Options'!$E$16&" j × "&TEXT('3 Options'!$F$16,"#,##0.00")&" €/j",""))&IF(AND('3 Options'!$D$17<>"",'3 Options'!$G$16<>"Forfait global")," · ","")&'3 Options'!$D$17,"") | I44: =IF('3 Options'!$C$16="Oui",INDEX(Textes!$B$2:$C$52,MATCH("ht",Textes!$A$2:$A$52,0),Listes!$H$1),"")
B47: =INDEX(Textes!$B$2:$C$52,MATCH("sec_opt",Textes!$A$2:$A$52,0),Listes!$H$1)
C48: =INDEX(Textes!$B$2:$C$52,MATCH("h_label",Textes!$A$2:$A$52,0),Listes!$H$1) | D48: =INDEX(Textes!$B$2:$C$52,MATCH("h_qty",Textes!$A$2:$A$52,0),Listes!$H$1) | E48: =INDEX(Textes!$B$2:$C$52,MATCH("h_unit",Textes!$A$2:$A$52,0),Listes!$H$1) | F48: =INDEX(Textes!$B$2:$C$52,MATCH("h_pu",Textes!$A$2:$A$52,0),Listes!$H$1) | G48: =INDEX(Textes!$B$2:$C$52,MATCH("h_tot",Textes!$A$2:$A$52,0),Listes!$H$1) | H48: =INDEX(Textes!$B$2:$C$52,MATCH("h_det",Textes!$A$2:$A$52,0),Listes!$H$1)
C49: =IF(ISNUMBER(MATCH(1,'3 Options'!$I$6:$I$13,0)),IF(INDEX('3 Options'!$D$6:$D$13,MATCH(1,'3 Options'!$I$6:$I$13,0))<>"",INDEX('3 Options'!$D$6:$D$13,MATCH(1,'3 Options'!$I$6:$I$13,0)),CHOOSE(MATCH(1,'3 Options'!$I$6:$I$13,0),INDEX(Textes!$B$2:$C$52,MATCH("op_day",Textes!$A$2:$A$52,0),Listes!$H$1),INDEX(Textes!$B$2:$C$52,MATCH("op_mob",Textes!$A$2:$A$52,0),Listes!$H$1),INDEX(Textes!$B$2:$C$52,MATCH("tight",Textes!$A$2:$A$52,0),Listes!$H$1),INDEX(Textes!$B$2:$C$52,MATCH("tr_mob",Textes!$A$2:$A$52,0),Listes!$H$1),INDEX(Textes!$B$2:$C$52,MATCH("tr_dem",Textes!$A$2:$A$52,0),Listes!$H$1),INDEX(Textes!$B$2:$C$52,MATCH("free",Textes!$A$2:$A$52,0),Listes!$H$1)&" 1",INDEX(Textes!$B$2:$C$52,MATCH("free",Textes!$A$2:$A$52,0),Listes!$H$1)&" 2",INDEX(Textes!$B$2:$C$52,MATCH("free",Textes!$A$2:$A$52,0),Listes!$H$1)&" 3")),"") | D49: =IF(ISNUMBER(MATCH(1,'3 Options'!$I$6:$I$13,0)),IF(INDEX('3 Options'!$G$6:$G$13,MATCH(1,'3 Options'!$I$6:$I$13,0))="Coût réel +15 %","",INDEX('3 Options'!$E$6:$E$13,MATCH(1,'3 Options'!$I$6:$I$13,0))),"") | E49: =IF(ISNUMBER(MATCH(1,'3 Options'!$I$6:$I$13,0)),IF(INDEX('3 Options'!$G$6:$G$13,MATCH(1,'3 Options'!$I$6:$I$13,0))="Coût réel +15 %","",INDEX('3 Options'!$G$6:$G$13,MATCH(1,'3 Options'!$I$6:$I$13,0))),"") | F49: =IF(ISNUMBER(MATCH(1,'3 Options'!$I$6:$I$13,0)),IF(INDEX('3 Options'!$G$6:$G$13,MATCH(1,'3 Options'!$I$6:$I$13,0))="Coût réel +15 %",INDEX(Textes!$B$2:$C$52,MATCH("at_cost",Textes!$A$2:$A$52,0),Listes!$H$1),IF(INDEX('3 Options'!$F$6:$F$13,MATCH(1,'3 Options'!$I$6:$I$13,0))="","",INDEX('3 Options'!$F$6:$F$13,MATCH(1,'3 Options'!$I$6:$I$13,0)))),"") | G49: =IF(ISNUMBER(MATCH(1,'3 Options'!$I$6:$I$13,0)),IF(INDEX('3 Options'!$G$6:$G$13,MATCH(1,'3 Options'!$I$6:$I$13,0))="Coût réel +15 %","—",INDEX('3 Options'!$H$6:$H$13,MATCH(1,'3 Options'!$I$6:$I$13,0))),"") | H49: =IF(ISNUMBER(MATCH(1,'3 Options'!$I$6:$I$13,0)),IF(OR(MATCH(1,'3 Options'!$I$6:$I$13,0)=4,MATCH(1,'3 Options'!$I$6:$I$13,0)=5),INDEX(Textes!$B$2:$C$52,MATCH("tr_note",Textes!$A$2:$A$52,0),Listes!$H$1),""),"")
C50: =IF(ISNUMBER(MATCH(2,'3 Options'!$I$6:$I$13,0)),IF(INDEX('3 Options'!$D$6:$D$13,MATCH(2,'3 Options'!$I$6:$I$13,0))<>"",INDEX('3 Options'!$D$6:$D$13,MATCH(2,'3 Options'!$I$6:$I$13,0)),CHOOSE(MATCH(2,'3 Options'!$I$6:$I$13,0),INDEX(Textes!$B$2:$C$52,MATCH("op_day",Textes!$A$2:$A$52,0),Listes!$H$1),INDEX(Textes!$B$2:$C$52,MATCH("op_mob",Textes!$A$2:$A$52,0),Listes!$H$1),INDEX(Textes!$B$2:$C$52,MATCH("tight",Textes!$A$2:$A$52,0),Listes!$H$1),INDEX(Textes!$B$2:$C$52,MATCH("tr_mob",Textes!$A$2:$A$52,0),Listes!$H$1),INDEX(Textes!$B$2:$C$52,MATCH("tr_dem",Textes!$A$2:$A$52,0),Listes!$H$1),INDEX(Textes!$B$2:$C$52,MATCH("free",Textes!$A$2:$A$52,0),Listes!$H$1)&" 1",INDEX(Textes!$B$2:$C$52,MATCH("free",Textes!$A$2:$A$52,0),Listes!$H$1)&" 2",INDEX(Textes!$B$2:$C$52,MATCH("free",Textes!$A$2:$A$52,0),Listes!$H$1)&" 3")),"") | D50: =IF(ISNUMBER(MATCH(2,'3 Options'!$I$6:$I$13,0)),IF(INDEX('3 Options'!$G$6:$G$13,MATCH(2,'3 Options'!$I$6:$I$13,0))="Coût réel +15 %","",INDEX('3 Options'!$E$6:$E$13,MATCH(2,'3 Options'!$I$6:$I$13,0))),"") | E50: =IF(ISNUMBER(MATCH(2,'3 Options'!$I$6:$I$13,0)),IF(INDEX('3 Options'!$G$6:$G$13,MATCH(2,'3 Options'!$I$6:$I$13,0))="Coût réel +15 %","",INDEX('3 Options'!$G$6:$G$13,MATCH(2,'3 Options'!$I$6:$I$13,0))),"") | F50: =IF(ISNUMBER(MATCH(2,'3 Options'!$I$6:$I$13,0)),IF(INDEX('3 Options'!$G$6:$G$13,MATCH(2,'3 Options'!$I$6:$I$13,0))="Coût réel +15 %",INDEX(Textes!$B$2:$C$52,MATCH("at_cost",Textes!$A$2:$A$52,0),Listes!$H$1),IF(INDEX('3 Options'!$F$6:$F$13,MATCH(2,'3 Options'!$I$6:$I$13,0))="","",INDEX('3 Options'!$F$6:$F$13,MATCH(2,'3 Options'!$I$6:$I$13,0)))),"") | G50: =IF(ISNUMBER(MATCH(2,'3 Options'!$I$6:$I$13,0)),IF(INDEX('3 Options'!$G$6:$G$13,MATCH(2,'3 Options'!$I$6:$I$13,0))="Coût réel +15 %","—",INDEX('3 Options'!$H$6:$H$13,MATCH(2,'3 Options'!$I$6:$I$13,0))),"") | H50: =IF(ISNUMBER(MATCH(2,'3 Options'!$I$6:$I$13,0)),IF(OR(MATCH(2,'3 Options'!$I$6:$I$13,0)=4,MATCH(2,'3 Options'!$I$6:$I$13,0)=5),INDEX(Textes!$B$2:$C$52,MATCH("tr_note",Textes!$A$2:$A$52,0),Listes!$H$1),""),"")
C51: =IF(ISNUMBER(MATCH(3,'3 Options'!$I$6:$I$13,0)),IF(INDEX('3 Options'!$D$6:$D$13,MATCH(3,'3 Options'!$I$6:$I$13,0))<>"",INDEX('3 Options'!$D$6:$D$13,MATCH(3,'3 Options'!$I$6:$I$13,0)),CHOOSE(MATCH(3,'3 Options'!$I$6:$I$13,0),INDEX(Textes!$B$2:$C$52,MATCH("op_day",Textes!$A$2:$A$52,0),Listes!$H$1),INDEX(Textes!$B$2:$C$52,MATCH("op_mob",Textes!$A$2:$A$52,0),Listes!$H$1),INDEX(Textes!$B$2:$C$52,MATCH("tight",Textes!$A$2:$A$52,0),Listes!$H$1),INDEX(Textes!$B$2:$C$52,MATCH("tr_mob",Textes!$A$2:$A$52,0),Listes!$H$1),INDEX(Textes!$B$2:$C$52,MATCH("tr_dem",Textes!$A$2:$A$52,0),Listes!$H$1),INDEX(Textes!$B$2:$C$52,MATCH("free",Textes!$A$2:$A$52,0),Listes!$H$1)&" 1",INDEX(Textes!$B$2:$C$52,MATCH("free",Textes!$A$2:$A$52,0),Listes!$H$1)&" 2",INDEX(Textes!$B$2:$C$52,MATCH("free",Textes!$A$2:$A$52,0),Listes!$H$1)&" 3")),"") | D51: =IF(ISNUMBER(MATCH(3,'3 Options'!$I$6:$I$13,0)),IF(INDEX('3 Options'!$G$6:$G$13,MATCH(3,'3 Options'!$I$6:$I$13,0))="Coût réel +15 %","",INDEX('3 Options'!$E$6:$E$13,MATCH(3,'3 Options'!$I$6:$I$13,0))),"") | E51: =IF(ISNUMBER(MATCH(3,'3 Options'!$I$6:$I$13,0)),IF(INDEX('3 Options'!$G$6:$G$13,MATCH(3,'3 Options'!$I$6:$I$13,0))="Coût réel +15 %","",INDEX('3 Options'!$G$6:$G$13,MATCH(3,'3 Options'!$I$6:$I$13,0))),"") | F51: =IF(ISNUMBER(MATCH(3,'3 Options'!$I$6:$I$13,0)),IF(INDEX('3 Options'!$G$6:$G$13,MATCH(3,'3 Options'!$I$6:$I$13,0))="Coût réel +15 %",INDEX(Textes!$B$2:$C$52,MATCH("at_cost",Textes!$A$2:$A$52,0),Listes!$H$1),IF(INDEX('3 Options'!$F$6:$F$13,MATCH(3,'3 Options'!$I$6:$I$13,0))="","",INDEX('3 Options'!$F$6:$F$13,MATCH(3,'3 Options'!$I$6:$I$13,0)))),"") | G51: =IF(ISNUMBER(MATCH(3,'3 Options'!$I$6:$I$13,0)),IF(INDEX('3 Options'!$G$6:$G$13,MATCH(3,'3 Options'!$I$6:$I$13,0))="Coût réel +15 %","—",INDEX('3 Options'!$H$6:$H$13,MATCH(3,'3 Options'!$I$6:$I$13,0))),"") | H51: =IF(ISNUMBER(MATCH(3,'3 Options'!$I$6:$I$13,0)),IF(OR(MATCH(3,'3 Options'!$I$6:$I$13,0)=4,MATCH(3,'3 Options'!$I$6:$I$13,0)=5),INDEX(Textes!$B$2:$C$52,MATCH("tr_note",Textes!$A$2:$A$52,0),Listes!$H$1),""),"")
C52: =IF(ISNUMBER(MATCH(4,'3 Options'!$I$6:$I$13,0)),IF(INDEX('3 Options'!$D$6:$D$13,MATCH(4,'3 Options'!$I$6:$I$13,0))<>"",INDEX('3 Options'!$D$6:$D$13,MATCH(4,'3 Options'!$I$6:$I$13,0)),CHOOSE(MATCH(4,'3 Options'!$I$6:$I$13,0),INDEX(Textes!$B$2:$C$52,MATCH("op_day",Textes!$A$2:$A$52,0),Listes!$H$1),INDEX(Textes!$B$2:$C$52,MATCH("op_mob",Textes!$A$2:$A$52,0),Listes!$H$1),INDEX(Textes!$B$2:$C$52,MATCH("tight",Textes!$A$2:$A$52,0),Listes!$H$1),INDEX(Textes!$B$2:$C$52,MATCH("tr_mob",Textes!$A$2:$A$52,0),Listes!$H$1),INDEX(Textes!$B$2:$C$52,MATCH("tr_dem",Textes!$A$2:$A$52,0),Listes!$H$1),INDEX(Textes!$B$2:$C$52,MATCH("free",Textes!$A$2:$A$52,0),Listes!$H$1)&" 1",INDEX(Textes!$B$2:$C$52,MATCH("free",Textes!$A$2:$A$52,0),Listes!$H$1)&" 2",INDEX(Textes!$B$2:$C$52,MATCH("free",Textes!$A$2:$A$52,0),Listes!$H$1)&" 3")),"") | D52: =IF(ISNUMBER(MATCH(4,'3 Options'!$I$6:$I$13,0)),IF(INDEX('3 Options'!$G$6:$G$13,MATCH(4,'3 Options'!$I$6:$I$13,0))="Coût réel +15 %","",INDEX('3 Options'!$E$6:$E$13,MATCH(4,'3 Options'!$I$6:$I$13,0))),"") | E52: =IF(ISNUMBER(MATCH(4,'3 Options'!$I$6:$I$13,0)),IF(INDEX('3 Options'!$G$6:$G$13,MATCH(4,'3 Options'!$I$6:$I$13,0))="Coût réel +15 %","",INDEX('3 Options'!$G$6:$G$13,MATCH(4,'3 Options'!$I$6:$I$13,0))),"") | F52: =IF(ISNUMBER(MATCH(4,'3 Options'!$I$6:$I$13,0)),IF(INDEX('3 Options'!$G$6:$G$13,MATCH(4,'3 Options'!$I$6:$I$13,0))="Coût réel +15 %",INDEX(Textes!$B$2:$C$52,MATCH("at_cost",Textes!$A$2:$A$52,0),Listes!$H$1),IF(INDEX('3 Options'!$F$6:$F$13,MATCH(4,'3 Options'!$I$6:$I$13,0))="","",INDEX('3 Options'!$F$6:$F$13,MATCH(4,'3 Options'!$I$6:$I$13,0)))),"") | G52: =IF(ISNUMBER(MATCH(4,'3 Options'!$I$6:$I$13,0)),IF(INDEX('3 Options'!$G$6:$G$13,MATCH(4,'3 Options'!$I$6:$I$13,0))="Coût réel +15 %","—",INDEX('3 Options'!$H$6:$H$13,MATCH(4,'3 Options'!$I$6:$I$13,0))),"") | H52: =IF(ISNUMBER(MATCH(4,'3 Options'!$I$6:$I$13,0)),IF(OR(MATCH(4,'3 Options'!$I$6:$I$13,0)=4,MATCH(4,'3 Options'!$I$6:$I$13,0)=5),INDEX(Textes!$B$2:$C$52,MATCH("tr_note",Textes!$A$2:$A$52,0),Listes!$H$1),""),"")
C53: =IF(ISNUMBER(MATCH(5,'3 Options'!$I$6:$I$13,0)),IF(INDEX('3 Options'!$D$6:$D$13,MATCH(5,'3 Options'!$I$6:$I$13,0))<>"",INDEX('3 Options'!$D$6:$D$13,MATCH(5,'3 Options'!$I$6:$I$13,0)),CHOOSE(MATCH(5,'3 Options'!$I$6:$I$13,0),INDEX(Textes!$B$2:$C$52,MATCH("op_day",Textes!$A$2:$A$52,0),Listes!$H$1),INDEX(Textes!$B$2:$C$52,MATCH("op_mob",Textes!$A$2:$A$52,0),Listes!$H$1),INDEX(Textes!$B$2:$C$52,MATCH("tight",Textes!$A$2:$A$52,0),Listes!$H$1),INDEX(Textes!$B$2:$C$52,MATCH("tr_mob",Textes!$A$2:$A$52,0),Listes!$H$1),INDEX(Textes!$B$2:$C$52,MATCH("tr_dem",Textes!$A$2:$A$52,0),Listes!$H$1),INDEX(Textes!$B$2:$C$52,MATCH("free",Textes!$A$2:$A$52,0),Listes!$H$1)&" 1",INDEX(Textes!$B$2:$C$52,MATCH("free",Textes!$A$2:$A$52,0),Listes!$H$1)&" 2",INDEX(Textes!$B$2:$C$52,MATCH("free",Textes!$A$2:$A$52,0),Listes!$H$1)&" 3")),"") | D53: =IF(ISNUMBER(MATCH(5,'3 Options'!$I$6:$I$13,0)),IF(INDEX('3 Options'!$G$6:$G$13,MATCH(5,'3 Options'!$I$6:$I$13,0))="Coût réel +15 %","",INDEX('3 Options'!$E$6:$E$13,MATCH(5,'3 Options'!$I$6:$I$13,0))),"") | E53: =IF(ISNUMBER(MATCH(5,'3 Options'!$I$6:$I$13,0)),IF(INDEX('3 Options'!$G$6:$G$13,MATCH(5,'3 Options'!$I$6:$I$13,0))="Coût réel +15 %","",INDEX('3 Options'!$G$6:$G$13,MATCH(5,'3 Options'!$I$6:$I$13,0))),"") | F53: =IF(ISNUMBER(MATCH(5,'3 Options'!$I$6:$I$13,0)),IF(INDEX('3 Options'!$G$6:$G$13,MATCH(5,'3 Options'!$I$6:$I$13,0))="Coût réel +15 %",INDEX(Textes!$B$2:$C$52,MATCH("at_cost",Textes!$A$2:$A$52,0),Listes!$H$1),IF(INDEX('3 Options'!$F$6:$F$13,MATCH(5,'3 Options'!$I$6:$I$13,0))="","",INDEX('3 Options'!$F$6:$F$13,MATCH(5,'3 Options'!$I$6:$I$13,0)))),"") | G53: =IF(ISNUMBER(MATCH(5,'3 Options'!$I$6:$I$13,0)),IF(INDEX('3 Options'!$G$6:$G$13,MATCH(5,'3 Options'!$I$6:$I$13,0))="Coût réel +15 %","—",INDEX('3 Options'!$H$6:$H$13,MATCH(5,'3 Options'!$I$6:$I$13,0))),"") | H53: =IF(ISNUMBER(MATCH(5,'3 Options'!$I$6:$I$13,0)),IF(OR(MATCH(5,'3 Options'!$I$6:$I$13,0)=4,MATCH(5,'3 Options'!$I$6:$I$13,0)=5),INDEX(Textes!$B$2:$C$52,MATCH("tr_note",Textes!$A$2:$A$52,0),Listes!$H$1),""),"")
C54: =IF(ISNUMBER(MATCH(6,'3 Options'!$I$6:$I$13,0)),IF(INDEX('3 Options'!$D$6:$D$13,MATCH(6,'3 Options'!$I$6:$I$13,0))<>"",INDEX('3 Options'!$D$6:$D$13,MATCH(6,'3 Options'!$I$6:$I$13,0)),CHOOSE(MATCH(6,'3 Options'!$I$6:$I$13,0),INDEX(Textes!$B$2:$C$52,MATCH("op_day",Textes!$A$2:$A$52,0),Listes!$H$1),INDEX(Textes!$B$2:$C$52,MATCH("op_mob",Textes!$A$2:$A$52,0),Listes!$H$1),INDEX(Textes!$B$2:$C$52,MATCH("tight",Textes!$A$2:$A$52,0),Listes!$H$1),INDEX(Textes!$B$2:$C$52,MATCH("tr_mob",Textes!$A$2:$A$52,0),Listes!$H$1),INDEX(Textes!$B$2:$C$52,MATCH("tr_dem",Textes!$A$2:$A$52,0),Listes!$H$1),INDEX(Textes!$B$2:$C$52,MATCH("free",Textes!$A$2:$A$52,0),Listes!$H$1)&" 1",INDEX(Textes!$B$2:$C$52,MATCH("free",Textes!$A$2:$A$52,0),Listes!$H$1)&" 2",INDEX(Textes!$B$2:$C$52,MATCH("free",Textes!$A$2:$A$52,0),Listes!$H$1)&" 3")),"") | D54: =IF(ISNUMBER(MATCH(6,'3 Options'!$I$6:$I$13,0)),IF(INDEX('3 Options'!$G$6:$G$13,MATCH(6,'3 Options'!$I$6:$I$13,0))="Coût réel +15 %","",INDEX('3 Options'!$E$6:$E$13,MATCH(6,'3 Options'!$I$6:$I$13,0))),"") | E54: =IF(ISNUMBER(MATCH(6,'3 Options'!$I$6:$I$13,0)),IF(INDEX('3 Options'!$G$6:$G$13,MATCH(6,'3 Options'!$I$6:$I$13,0))="Coût réel +15 %","",INDEX('3 Options'!$G$6:$G$13,MATCH(6,'3 Options'!$I$6:$I$13,0))),"") | F54: =IF(ISNUMBER(MATCH(6,'3 Options'!$I$6:$I$13,0)),IF(INDEX('3 Options'!$G$6:$G$13,MATCH(6,'3 Options'!$I$6:$I$13,0))="Coût réel +15 %",INDEX(Textes!$B$2:$C$52,MATCH("at_cost",Textes!$A$2:$A$52,0),Listes!$H$1),IF(INDEX('3 Options'!$F$6:$F$13,MATCH(6,'3 Options'!$I$6:$I$13,0))="","",INDEX('3 Options'!$F$6:$F$13,MATCH(6,'3 Options'!$I$6:$I$13,0)))),"") | G54: =IF(ISNUMBER(MATCH(6,'3 Options'!$I$6:$I$13,0)),IF(INDEX('3 Options'!$G$6:$G$13,MATCH(6,'3 Options'!$I$6:$I$13,0))="Coût réel +15 %","—",INDEX('3 Options'!$H$6:$H$13,MATCH(6,'3 Options'!$I$6:$I$13,0))),"") | H54: =IF(ISNUMBER(MATCH(6,'3 Options'!$I$6:$I$13,0)),IF(OR(MATCH(6,'3 Options'!$I$6:$I$13,0)=4,MATCH(6,'3 Options'!$I$6:$I$13,0)=5),INDEX(Textes!$B$2:$C$52,MATCH("tr_note",Textes!$A$2:$A$52,0),Listes!$H$1),""),"")
C55: =IF(ISNUMBER(MATCH(7,'3 Options'!$I$6:$I$13,0)),IF(INDEX('3 Options'!$D$6:$D$13,MATCH(7,'3 Options'!$I$6:$I$13,0))<>"",INDEX('3 Options'!$D$6:$D$13,MATCH(7,'3 Options'!$I$6:$I$13,0)),CHOOSE(MATCH(7,'3 Options'!$I$6:$I$13,0),INDEX(Textes!$B$2:$C$52,MATCH("op_day",Textes!$A$2:$A$52,0),Listes!$H$1),INDEX(Textes!$B$2:$C$52,MATCH("op_mob",Textes!$A$2:$A$52,0),Listes!$H$1),INDEX(Textes!$B$2:$C$52,MATCH("tight",Textes!$A$2:$A$52,0),Listes!$H$1),INDEX(Textes!$B$2:$C$52,MATCH("tr_mob",Textes!$A$2:$A$52,0),Listes!$H$1),INDEX(Textes!$B$2:$C$52,MATCH("tr_dem",Textes!$A$2:$A$52,0),Listes!$H$1),INDEX(Textes!$B$2:$C$52,MATCH("free",Textes!$A$2:$A$52,0),Listes!$H$1)&" 1",INDEX(Textes!$B$2:$C$52,MATCH("free",Textes!$A$2:$A$52,0),Listes!$H$1)&" 2",INDEX(Textes!$B$2:$C$52,MATCH("free",Textes!$A$2:$A$52,0),Listes!$H$1)&" 3")),"") | D55: =IF(ISNUMBER(MATCH(7,'3 Options'!$I$6:$I$13,0)),IF(INDEX('3 Options'!$G$6:$G$13,MATCH(7,'3 Options'!$I$6:$I$13,0))="Coût réel +15 %","",INDEX('3 Options'!$E$6:$E$13,MATCH(7,'3 Options'!$I$6:$I$13,0))),"") | E55: =IF(ISNUMBER(MATCH(7,'3 Options'!$I$6:$I$13,0)),IF(INDEX('3 Options'!$G$6:$G$13,MATCH(7,'3 Options'!$I$6:$I$13,0))="Coût réel +15 %","",INDEX('3 Options'!$G$6:$G$13,MATCH(7,'3 Options'!$I$6:$I$13,0))),"") | F55: =IF(ISNUMBER(MATCH(7,'3 Options'!$I$6:$I$13,0)),IF(INDEX('3 Options'!$G$6:$G$13,MATCH(7,'3 Options'!$I$6:$I$13,0))="Coût réel +15 %",INDEX(Textes!$B$2:$C$52,MATCH("at_cost",Textes!$A$2:$A$52,0),Listes!$H$1),IF(INDEX('3 Options'!$F$6:$F$13,MATCH(7,'3 Options'!$I$6:$I$13,0))="","",INDEX('3 Options'!$F$6:$F$13,MATCH(7,'3 Options'!$I$6:$I$13,0)))),"") | G55: =IF(ISNUMBER(MATCH(7,'3 Options'!$I$6:$I$13,0)),IF(INDEX('3 Options'!$G$6:$G$13,MATCH(7,'3 Options'!$I$6:$I$13,0))="Coût réel +15 %","—",INDEX('3 Options'!$H$6:$H$13,MATCH(7,'3 Options'!$I$6:$I$13,0))),"") | H55: =IF(ISNUMBER(MATCH(7,'3 Options'!$I$6:$I$13,0)),IF(OR(MATCH(7,'3 Options'!$I$6:$I$13,0)=4,MATCH(7,'3 Options'!$I$6:$I$13,0)=5),INDEX(Textes!$B$2:$C$52,MATCH("tr_note",Textes!$A$2:$A$52,0),Listes!$H$1),""),"")
C56: =IF(ISNUMBER(MATCH(8,'3 Options'!$I$6:$I$13,0)),IF(INDEX('3 Options'!$D$6:$D$13,MATCH(8,'3 Options'!$I$6:$I$13,0))<>"",INDEX('3 Options'!$D$6:$D$13,MATCH(8,'3 Options'!$I$6:$I$13,0)),CHOOSE(MATCH(8,'3 Options'!$I$6:$I$13,0),INDEX(Textes!$B$2:$C$52,MATCH("op_day",Textes!$A$2:$A$52,0),Listes!$H$1),INDEX(Textes!$B$2:$C$52,MATCH("op_mob",Textes!$A$2:$A$52,0),Listes!$H$1),INDEX(Textes!$B$2:$C$52,MATCH("tight",Textes!$A$2:$A$52,0),Listes!$H$1),INDEX(Textes!$B$2:$C$52,MATCH("tr_mob",Textes!$A$2:$A$52,0),Listes!$H$1),INDEX(Textes!$B$2:$C$52,MATCH("tr_dem",Textes!$A$2:$A$52,0),Listes!$H$1),INDEX(Textes!$B$2:$C$52,MATCH("free",Textes!$A$2:$A$52,0),Listes!$H$1)&" 1",INDEX(Textes!$B$2:$C$52,MATCH("free",Textes!$A$2:$A$52,0),Listes!$H$1)&" 2",INDEX(Textes!$B$2:$C$52,MATCH("free",Textes!$A$2:$A$52,0),Listes!$H$1)&" 3")),"") | D56: =IF(ISNUMBER(MATCH(8,'3 Options'!$I$6:$I$13,0)),IF(INDEX('3 Options'!$G$6:$G$13,MATCH(8,'3 Options'!$I$6:$I$13,0))="Coût réel +15 %","",INDEX('3 Options'!$E$6:$E$13,MATCH(8,'3 Options'!$I$6:$I$13,0))),"") | E56: =IF(ISNUMBER(MATCH(8,'3 Options'!$I$6:$I$13,0)),IF(INDEX('3 Options'!$G$6:$G$13,MATCH(8,'3 Options'!$I$6:$I$13,0))="Coût réel +15 %","",INDEX('3 Options'!$G$6:$G$13,MATCH(8,'3 Options'!$I$6:$I$13,0))),"") | F56: =IF(ISNUMBER(MATCH(8,'3 Options'!$I$6:$I$13,0)),IF(INDEX('3 Options'!$G$6:$G$13,MATCH(8,'3 Options'!$I$6:$I$13,0))="Coût réel +15 %",INDEX(Textes!$B$2:$C$52,MATCH("at_cost",Textes!$A$2:$A$52,0),Listes!$H$1),IF(INDEX('3 Options'!$F$6:$F$13,MATCH(8,'3 Options'!$I$6:$I$13,0))="","",INDEX('3 Options'!$F$6:$F$13,MATCH(8,'3 Options'!$I$6:$I$13,0)))),"") | G56: =IF(ISNUMBER(MATCH(8,'3 Options'!$I$6:$I$13,0)),IF(INDEX('3 Options'!$G$6:$G$13,MATCH(8,'3 Options'!$I$6:$I$13,0))="Coût réel +15 %","—",INDEX('3 Options'!$H$6:$H$13,MATCH(8,'3 Options'!$I$6:$I$13,0))),"") | H56: =IF(ISNUMBER(MATCH(8,'3 Options'!$I$6:$I$13,0)),IF(OR(MATCH(8,'3 Options'!$I$6:$I$13,0)=4,MATCH(8,'3 Options'!$I$6:$I$13,0)=5),INDEX(Textes!$B$2:$C$52,MATCH("tr_note",Textes!$A$2:$A$52,0),Listes!$H$1),""),"")
B58: =INDEX(Textes!$B$2:$C$52,MATCH("sec_cond",Textes!$A$2:$A$52,0),Listes!$H$1)
...

Sheet Listes
A1: Contact Enedril | B1: E-mail | D1: Incoterm | E1: Validité | F1: Règlement | G1: Oui / Non | H1: 1 | J1: Support de colisage | K1: N° de colis | L1: Unité | M1: Mode transport | N1: Mode forfait | P1: Statut | Q1: Test / Taille
A2: Fabien JACQUOT | B2: fjacquot@enedril.fr | D2: EXW Lons | E2: 15 jours / 15 days | F2: 30 jours date de facture / 30 days invoice date | G2: Oui | H2: ← langue du devis : 1 = français, 2 = anglais | J2: Palette | K2: P1 | L2: forfait | M2: Coût réel +15 % | N2: Forfait calculé (S + O + UC) | P2: Oui | Q2: Taille OK
A3: Alexis ESTINES | B3: aestines@enedril.fr | D3: FCA Lons | E3: 30 jours / 30 days | F3: 30 jours fin de mois / 30 days end of month | G3: Non | J3: Fishing basket | K3: P2 | L3: €/jour | M3: Forfait | N3: Forfait global | P3: En cours | Q3: Test OK
A4: Paul HYNDERICK | B4: phynderick@enedril.fr | D4: DAP | E4: 60 jours / 60 days | F4: 45 jours fin de mois / 45 days end of month | J4: Caisse | K4: P3 | L4: €/jour/pers | N4: Forfait par jour | Q4: Taille + test OK
A5: Céline CARDONA | B5: ccardona@enedril.fr | D5: DDP | E5: 90 jours / 90 days | F5: À la commande / Upon order | J5: Loose (vrac) | K5: P4 | L5: €/pers | Q5: À contrôler
A6: Koen MONDELAERS | B6: kmondelaers@enedril.fr | D6: FOB | K6: P5 | L6: €/unité
A7: Luigi LIBERATORE | B7: lliberatore@enedril.fr | K7: P6
K8: P7
K9: P8
A10: Pour ajouter un contact, une validité, etc. : écrire à la suite dans la colonne (les listes déroulantes lisent les 12 premières lignes). | K10: P9
K11: P10
K12: Loose

Sheet Textes
A1: Clé | B1: Français | C1: English
A2: title | B2: OFFRE DE LOCATION | C2: EQUIPMENT RENTAL QUOTATION
A3: client | B3: Client | C3: Company
A4: attn | B4: À l'attention de | C4: Attention
A5: well | B5: Puits / Chantier | C5: Well / Location
A6: rig | B6: Rig | C6: Rig
A7: offer | B7: N° d'offre | C7: Offer N°
A8: date | B8: Date | C8: Date
A9: valid | B9: Validité de l'offre | C9: Validity
A10: inco | B10: Incoterm | C10: Incoterm
A11: lead | B11: Délai de mise à dispo | C11: Lead time
A12: pay | B12: Conditions de règlement | C12: Payment terms
... A52: lump | B52: forfait | C52: lump sum
