Workbook

Sheet 1 Matériel
B1: MATÉRIEL À COLLER | F1: EXEMPLE
B2: Dans le classeur Devis, onglet « 2 Matériel » : copier B6:D29 (Bannière, Description, Qté) et coller ici en B6. Aucun prix ici.
A5: # | B5: Bannière ? | C5: Description (ou titre de bannière) | D5: Qté | E5: Lignes | F5: Cumul
A6: =IF(AND(E6>0,B6<>"Oui"),COUNTIFS(E$6:E6,">0",B$6:B6,"<>Oui"),"") | B6: Oui | C6: BHA #1 | E6: =IF($C6="",0,IF($B6="Oui",1,IF(N($D6)>0,INT($D6),1))) | F6: =SUM(E$6:E6)
A7: =IF(AND(E7>0,B7<>"Oui"),COUNTIFS(E$6:E7,">0",B$6:B7,"<>Oui"),"") | C7: Stab 5-7/8 OD, 2-1/4" ID - 3-1/2" IF Pin x Box | D7: 1 | E7: =IF($C7="",0,IF($B7="Oui",1,IF(N($D7)>0,INT($D7),1))) | F7: =SUM(E$6:E7)
A8: =IF(AND(E8>0,B8<>"Oui"),COUNTIFS(E$6:E8,">0",B$6:B8,"<>Oui"),"") | C8: XO 3-1/2" IF Pin x 2-7/8" EU Box | D8: 2 | E8: =IF($C8="",0,IF($B8="Oui",1,IF(N($D8)>0,INT($D8),1))) | F8: =SUM(E$6:E8)
A9: =IF(AND(E9>0,B9<>"Oui"),COUNTIFS(E$6:E9,">0",B$6:B9,"<>Oui"),"") | B9: Oui | C9: BHA #2 | E9: =IF($C9="",0,IF($B9="Oui",1,IF(N($D9)>0,INT($D9),1))) | F9: =SUM(E$6:E9)
A10: =IF(AND(E10>0,B10<>"Oui"),COUNTIFS(E$6:E10,">0",B$6:B10,"<>Oui"),"") | C10: XO 3-1/2" IF Box x 2-7/8" EU Pin | D10: 1 | E10: =IF($C10="",0,IF($B10="Oui",1,IF(N($D10)>0,INT($D10),1))) | F10: =SUM(E$6:E10)
A11: =IF(AND(E11>0,B11<>"Oui"),COUNTIFS(E$6:E11,">0",B$6:B11,"<>Oui"),"") | E11: =IF($C11="",0,IF($B11="Oui",1,IF(N($D11)>0,INT($D11),1))) | F11: =SUM(E$6:E11)
A12: =IF(AND(E12>0,B12<>"Oui"),COUNTIFS(E$6:E12,">0",B$6:B12,"<>Oui"),"") | E12: =IF($C12="",0,IF($B12="Oui",1,IF(N($D12)>0,INT($D12),1))) | F12: =SUM(E$6:E12)
A13: =IF(AND(E13>0,B13<>"Oui"),COUNTIFS(E$6:E13,">0",B$6:B13,"<>Oui"),"") | E13: =IF($C13="",0,IF($B13="Oui",1,IF(N($D13)>0,INT($D13),1))) | F13: =SUM(E$6:E13)
A14: =IF(AND(E14>0,B14<>"Oui"),COUNTIFS(E$6:E14,">0",B$6:B14,"<>Oui"),"") | E14: =IF($C14="",0,IF($B14="Oui",1,IF(N($D14)>0,INT($D14),1))) | F14: =SUM(E$6:E14)
A15: =IF(AND(E15>0,B15<>"Oui"),COUNTIFS(E$6:E15,">0",B$6:B15,"<>Oui"),"") | E15: =IF($C15="",0,IF($B15="Oui",1,IF(N($D15)>0,INT($D15),1))) | F15: =SUM(E$6:E15)
A16: =IF(AND(E16>0,B16<>"Oui"),COUNTIFS(E$6:E16,">0",B$6:B16,"<>Oui"),"") | E16: =IF($C16="",0,IF($B16="Oui",1,IF(N($D16)>0,INT($D16),1))) | F16: =SUM(E$6:E16)
A17: =IF(AND(E17>0,B17<>"Oui"),COUNTIFS(E$6:E17,">0",B$6:B17,"<>Oui"),"") | E17: =IF($C17="",0,IF($B17="Oui",1,IF(N($D17)>0,INT($D17),1))) | F17: =SUM(E$6:E17)
A18: =IF(AND(E18>0,B18<>"Oui"),COUNTIFS(E$6:E18,">0",B$6:B18,"<>Oui"),"") | E18: =IF($C18="",0,IF($B18="Oui",1,IF(N($D18)>0,INT($D18),1))) | F18: =SUM(E$6:E18)
A19: =IF(AND(E19>0,B19<>"Oui"),COUNTIFS(E$6:E19,">0",B$6:B19,"<>Oui"),"") | E19: =IF($C19="",0,IF($B19="Oui",1,IF(N($D19)>0,INT($D19),1))) | F19: =SUM(E$6:E19)
A20: =IF(AND(E20>0,B20<>"Oui"),COUNTIFS(E$6:E20,">0",B$6:B20,"<>Oui"),"") | E20: =IF($C20="",0,IF($B20="Oui",1,IF(N($D20)>0,INT($D20),1))) | F20: =SUM(E$6:E20)
A21: =IF(AND(E21>0,B21<>"Oui"),COUNTIFS(E$6:E21,">0",B$6:B21,"<>Oui"),"") | E21: =IF($C21="",0,IF($B21="Oui",1,IF(N($D21)>0,INT($D21),1))) | F21: =SUM(E$6:E21)
A22: =IF(AND(E22>0,B22<>"Oui"),COUNTIFS(E$6:E22,">0",B$6:B22,"<>Oui"),"") | E22: =IF($C22="",0,IF($B22="Oui",1,IF(N($D22)>0,INT($D22),1))) | F22: =SUM(E$6:E22)
... A29: =IF(AND(E29>0,B29<>"Oui"),COUNTIFS(E$6:E29,">0",B$6:B29,"<>Oui"),"") | E29: =IF($C29="",0,IF($B29="Oui",1,IF(N($D29)>0,INT($D29),1))) | F29: =SUM(E$6:E29)
C31: =SUM(E6:E29)&" ligne(s) sur la tool list"
C32: ➜ Étape suivante : onglet « 2 Tool List ». Une quantité de 2 donne 2 lignes ; une bannière donne une ligne de titre.

Sheet 2 Tool List
E1: LISTE DE MATÉRIEL
E2: ="N° "&D8&IF(D6="",""," · "&D6)
A5: CLIENT | C5: PUITS / CHANTIER | D5: DOSSIER N° · RIG | H5: DESTINATION
A6: Geopetrol | C6: Puits Lacq-12 | D6: 26-82-FR · CLU108 | H6: Geopetrol · Lacq
A7: DATE DE DÉPART | C7: FAITE LE | D7: N° DE LISTE | H7: PRÉPARÉE PAR
A8: 46335 | C8: 46323 | D8: TL-26-058 | H8: Paul HYNDERICK
A9: DESCRIPTION GÉNÉRALE | D9: COLISAGE | H9: VALIDÉE PAR
A10: Stab + XO | D10: A communiquer dès que possible | H10: Fabien JACQUOT
A11: Toute modification par rapport à la liste ci-dessous doit être évitée, et impérativement signalée si pas le choix.
A12: =IF(SUBTOTAL(103,A15:A54)<MIN(SUM('1 Matériel'!$E$6:$E$29),40),"⚠ Appuyer sur Ctrl + Alt + L pour afficher toutes les lignes de la liste.","")
A13: ÉQUIPEMENT | D13: RELEVÉS (pouces) | I13: REMARQUES
A14: Item | B14: Référence / N° de série (à écrire) | C14: Description | D14: OD | E14: ID | F14: Ouverture blades | G14: Ouverture max couteaux | H14: Taille / test confirmé | I14: Commentaire | T14: ligne | U14: réf. | V14: bannière
A15: =IF(OR(T15=0,V15=1),"",T15-COUNTIF(V$15:V15,1)) | C15: =IF(T15=0,"",IF(V15=1,UPPER(INDEX('1 Matériel'!$C$6:$C$29,U15)),INDEX('1 Matériel'!$C$6:$C$29,U15)&IF(INDEX('1 Matériel'!$E$6:$E$29,U15)>1," ("&(T15-INDEX('1 Matériel'!$F$6:$F$29,U15)+INDEX('1 Matériel'!$E$6:$E$29,U15))&"/"&INDEX('1 Matériel'!$E$6:$E$29,U15)&")",""))) | T15: =IF(1<=SUM('1 Matériel'!$E$6:$E$29),1,0) | U15: =IF(T15=0,"",COUNTIF('1 Matériel'!$F$6:$F$29,"<"&T15)+1) | V15: =IF(U15="","",IF(INDEX('1 Matériel'!$B$6:$B$29,U15)="Oui",1,0))
A16: =IF(OR(T16=0,V16=1),"",T16-COUNTIF(V$15:V16,1)) | B16: PL-0412 | C16: =IF(T16=0,"",IF(V16=1,UPPER(INDEX('1 Matériel'!$C$6:$C$29,U16)),INDEX('1 Matériel'!$C$6:$C$29,U16)&IF(INDEX('1 Matériel'!$E$6:$E$29,U16)>1," ("&(T16-INDEX('1 Matériel'!$F$6:$F$29,U16)+INDEX('1 Matériel'!$E$6:$E$29,U16))&"/"&INDEX('1 Matériel'!$E$6:$E$29,U16)&")",""))) | D16: 5.875 | E16: 2.25 | H16: Taille OK | I16: Blades à tester avant départ | T16: =IF(2<=SUM('1 Matériel'!$E$6:$E$29),2,0) | U16: =IF(T16=0,"",COUNTIF('1 Matériel'!$F$6:$F$29,"<"&T16)+1) | V16: =IF(U16="","",IF(INDEX('1 Matériel'!$B$6:$B$29,U16)="Oui",1,0))
A17: =IF(OR(T17=0,V17=1),"",T17-COUNTIF(V$15:V17,1)) | B17: PL-0377 | C17: =IF(T17=0,"",IF(V17=1,UPPER(INDEX('1 Matériel'!$C$6:$C$29,U17)),INDEX('1 Matériel'!$C$6:$C$29,U17)&IF(INDEX('1 Matériel'!$E$6:$E$29,U17)>1," ("&(T17-INDEX('1 Matériel'!$F$6:$F$29,U17)+INDEX('1 Matériel'!$E$6:$E$29,U17))&"/"&INDEX('1 Matériel'!$E$6:$E$29,U17)&")",""))) | D17: 3.5 | E17: 2 | H17: Taille OK | T17: =IF(3<=SUM('1 Matériel'!$E$6:$E$29),3,0) | U17: =IF(T17=0,"",COUNTIF('1 Matériel'!$F$6:$F$29,"<"&T17)+1) | V17: =IF(U17="","",IF(INDEX('1 Matériel'!$B$6:$B$29,U17)="Oui",1,0))
A18: =IF(OR(T18=0,V18=1),"",T18-COUNTIF(V$15:V18,1)) | B18: PL-0377 | C18: =IF(T18=0,"",IF(V18=1,UPPER(INDEX('1 Matériel'!$C$6:$C$29,U18)),INDEX('1 Matériel'!$C$6:$C$29,U18)&IF(INDEX('1 Matériel'!$E$6:$E$29,U18)>1," ("&(T18-INDEX('1 Matériel'!$F$6:$F$29,U18)+INDEX('1 Matériel'!$E$6:$E$29,U18))&"/"&INDEX('1 Matériel'!$E$6:$E$29,U18)&")",""))) | D18: 3.5 | E18: 2 | H18: Taille OK | T18: =IF(4<=SUM('1 Matériel'!$E$6:$E$29),4,0) | U18: =IF(T18=0,"",COUNTIF('1 Matériel'!$F$6:$F$29,"<"&T18)+1) | V18: =IF(U18="","",IF(INDEX('1 Matériel'!$B$6:$B$29,U18)="Oui",1,0))
A19: =IF(OR(T19=0,V19=1),"",T19-COUNTIF(V$15:V19,1)) | C19: =IF(T19=0,"",IF(V19=1,UPPER(INDEX('1 Matériel'!$C$6:$C$29,U19)),INDEX('1 Matériel'!$C$6:$C$29,U19)&IF(INDEX('1 Matériel'!$E$6:$E$29,U19)>1," ("&(T19-INDEX('1 Matériel'!$F$6:$F$29,U19)+INDEX('1 Matériel'!$E$6:$E$29,U19))&"/"&INDEX('1 Matériel'!$E$6:$E$29,U19)&")",""))) | T19: =IF(5<=SUM('1 Matériel'!$E$6:$E$29),5,0) | U19: =IF(T19=0,"",COUNTIF('1 Matériel'!$F$6:$F$29,"<"&T19)+1) | V19: =IF(U19="","",IF(INDEX('1 Matériel'!$B$6:$B$29,U19)="Oui",1,0))
A20: =IF(OR(T20=0,V20=1),"",T20-COUNTIF(V$15:V20,1)) | C20: =IF(T20=0,"",IF(V20=1,UPPER(INDEX('1 Matériel'!$C$6:$C$29,U20)),INDEX('1 Matériel'!$C$6:$C$29,U20)&IF(INDEX('1 Matériel'!$E$6:$E$29,U20)>1," ("&(T20-INDEX('1 Matériel'!$F$6:$F$29,U20)+INDEX('1 Matériel'!$E$6:$E$29,U20))&"/"&INDEX('1 Matériel'!$E$6:$E$29,U20)&")",""))) | T20: =IF(6<=SUM('1 Matériel'!$E$6:$E$29),6,0) | U20: =IF(T20=0,"",COUNTIF('1 Matériel'!$F$6:$F$29,"<"&T20)+1) | V20: =IF(U20="","",IF(INDEX('1 Matériel'!$B$6:$B$29,U20)="Oui",1,0))
A21: =IF(OR(T21=0,V21=1),"",T21-COUNTIF(V$15:V21,1)) | C21: =IF(T21=0,"",IF(V21=1,UPPER(INDEX('1 Matériel'!$C$6:$C$29,U21)),INDEX('1 Matériel'!$C$6:$C$29,U21)&IF(INDEX('1 Matériel'!$E$6:$E$29,U21)>1," ("&(T21-INDEX('1 Matériel'!$F$6:$F$29,U21)+INDEX('1 Matériel'!$E$6:$E$29,U21))&"/"&INDEX('1 Matériel'!$E$6:$E$29,U21)&")",""))) | T21: =IF(7<=SUM('1 Matériel'!$E$6:$E$29),7,0) | U21: =IF(T21=0,"",COUNTIF('1 Matériel'!$F$6:$F$29,"<"&T21)+1) | V21: =IF(U21="","",IF(INDEX('1 Matériel'!$B$6:$B$29,U21)="Oui",1,0))
A22: =IF(OR(T22=0,V22=1),"",T22-COUNTIF(V$15:V22,1)) | C22: =IF(T22=0,"",IF(V22=1,UPPER(INDEX('1 Matériel'!$C$6:$C$29,U22)),INDEX('1 Matériel'!$C$6:$C$29,U22)&IF(INDEX('1 Matériel'!$E$6:$E$29,U22)>1," ("&(T22-INDEX('1 Matériel'!$F$6:$F$29,U22)+INDEX('1 Matériel'!$E$6:$E$29,U22))&"/"&INDEX('1 Matériel'!$E$6:$E$29,U22)&")",""))) | T22: =IF(8<=SUM('1 Matériel'!$E$6:$E$29),8,0) | U22: =IF(T22=0,"",COUNTIF('1 Matériel'!$F$6:$F$29,"<"&T22)+1) | V22: =IF(U22="","",IF(INDEX('1 Matériel'!$B$6:$B$29,U22)="Oui",1,0))
A23: =IF(OR(T23=0,V23=1),"",T23-COUNTIF(V$15:V23,1)) | C23: =IF(T23=0,"",IF(V23=1,UPPER(INDEX('1 Matériel'!$C$6:$C$29,U23)),INDEX('1 Matériel'!$C$6:$C$29,U23)&IF(INDEX('1 Matériel'!$E$6:$E$29,U23)>1," ("&(T23-INDEX('1 Matériel'!$F$6:$F$29,U23)+INDEX('1 Matériel'!$E$6:$E$29,U23))&"/"&INDEX('1 Matériel'!$E$6:$E$29,U23)&")",""))) | T23: =IF(9<=SUM('1 Matériel'!$E$6:$E$29),9,0) | U23: =IF(T23=0,"",COUNTIF('1 Matériel'!$F$6:$F$29,"<"&T23)+1) | V23: =IF(U23="","",IF(INDEX('1 Matériel'!$B$6:$B$29,U23)="Oui",1,0))
A24: =IF(OR(T24=0,V24=1),"",T24-COUNTIF(V$15:V24,1)) | C24: =IF(T24=0,"",IF(V24=1,UPPER(INDEX('1 Matériel'!$C$6:$C$29,U24)),INDEX('1 Matériel'!$C$6:$C$29,U24)&IF(INDEX('1 Matériel'!$E$6:$E$29,U24)>1," ("&(T24-INDEX('1 Matériel'!$F$6:$F$29,U24)+INDEX('1 Matériel'!$E$6:$E$29,U24))&"/"&INDEX('1 Matériel'!$E$6:$E$29,U24)&")",""))) | T24: =IF(10<=SUM('1 Matériel'!$E$6:$E$29),10,0) | U24: =IF(T24=0,"",COUNTIF('1 Matériel'!$F$6:$F$29,"<"&T24)+1) | V24: =IF(U24="","",IF(INDEX('1 Matériel'!$B$6:$B$29,U24)="Oui",1,0))
A25: =IF(OR(T25=0,V25=1),"",T25-COUNTIF(V$15:V25,1)) | C25: =IF(T25=0,"",IF(V25=1,UPPER(INDEX('1 Matériel'!$C$6:$C$29,U25)),INDEX('1 Matériel'!$C$6:$C$29,U25)&IF(INDEX('1 Matériel'!$E$6:$E$29,U25)>1," ("&(T25-INDEX('1 Matériel'!$F$6:$F$29,U25)+INDEX('1 Matériel'!$E$6:$E$29,U25))&"/"&INDEX('1 Matériel'!$E$6:$E$29,U25)&")",""))) | T25: =IF(11<=SUM('1 Matériel'!$E$6:$E$29),11,0) | U25: =IF(T25=0,"",COUNTIF('1 Matériel'!$F$6:$F$29,"<"&T25)+1) | V25: =IF(U25="","",IF(INDEX('1 Matériel'!$B$6:$B$29,U25)="Oui",1,0))
A26: =IF(OR(T26=0,V26=1),"",T26-COUNTIF(V$15:V26,1)) | C26: =IF(T26=0,"",IF(V26=1,UPPER(INDEX('1 Matériel'!$C$6:$C$29,U26)),INDEX('1 Matériel'!$C$6:$C$29,U26)&IF(INDEX('1 Matériel'!$E$6:$E$29,U26)>1," ("&(T26-INDEX('1 Matériel'!$F$6:$F$29,U26)+INDEX('1 Matériel'!$E$6:$E$29,U26))&"/"&INDEX('1 Matériel'!$E$6:$E$29,U26)&")",""))) | T26: =IF(12<=SUM('1 Matériel'!$E$6:$E$29),12,0) | U26: =IF(T26=0,"",COUNTIF('1 Matériel'!$F$6:$F$29,"<"&T26)+1) | V26: =IF(U26="","",IF(INDEX('1 Matériel'!$B$6:$B$29,U26)="Oui",1,0))
A27: =IF(OR(T27=0,V27=1),"",T27-COUNTIF(V$15:V27,1)) | C27: =IF(T27=0,"",IF(V27=1,UPPER(INDEX('1 Matériel'!$C$6:$C$29,U27)),INDEX('1 Matériel'!$C$6:$C$29,U27)&IF(INDEX('1 Matériel'!$E$6:$E$29,U27)>1," ("&(T27-INDEX('1 Matériel'!$F$6:$F$29,U27)+INDEX('1 Matériel'!$E$6:$E$29,U27))&"/"&INDEX('1 Matériel'!$E$6:$E$29,U27)&")",""))) | T27: =IF(13<=SUM('1 Matériel'!$E$6:$E$29),13,0) | U27: =IF(T27=0,"",COUNTIF('1 Matériel'!$F$6:$F$29,"<"&T27)+1) | V27: =IF(U27="","",IF(INDEX('1 Matériel'!$B$6:$B$29,U27)="Oui",1,0))
A28: =IF(OR(T28=0,V28=1),"",T28-COUNTIF(V$15:V28,1)) | C28: =IF(T28=0,"",IF(V28=1,UPPER(INDEX('1 Matériel'!$C$6:$C$29,U28)),INDEX('1 Matériel'!$C$6:$C$29,U28)&IF(INDEX('1 Matériel'!$E$6:$E$29,U28)>1," ("&(T28-INDEX('1 Matériel'!$F$6:$F$29,U28)+INDEX('1 Matériel'!$E$6:$E$29,U28))&"/"&INDEX('1 Matériel'!$E$6:$E$29,U28)&")",""))) | T28: =IF(14<=SUM('1 Matériel'!$E$6:$E$29),14,0) | U28: =IF(T28=0,"",COUNTIF('1 Matériel'!$F$6:$F$29,"<"&T28)+1) | V28: =IF(U28="","",IF(INDEX('1 Matériel'!$B$6:$B$29,U28)="Oui",1,0))
A29: =IF(OR(T29=0,V29=1),"",T29-COUNTIF(V$15:V29,1)) | C29: =IF(T29=0,"",IF(V29=1,UPPER(INDEX('1 Matériel'!$C$6:$C$29,U29)),INDEX('1 Matériel'!$C$6:$C$29,U29)&IF(INDEX('1 Matériel'!$E$6:$E$29,U29)>1," ("&(T29-INDEX('1 Matériel'!$F$6:$F$29,U29)+INDEX('1 Matériel'!$E$6:$E$29,U29))&"/"&INDEX('1 Matériel'!$E$6:$E$29,U29)&")",""))) | T29: =IF(15<=SUM('1 Matériel'!$E$6:$E$29),15,0) | U29: =IF(T29=0,"",COUNTIF('1 Matériel'!$F$6:$F$29,"<"&T29)+1) | V29: =IF(U29="","",IF(INDEX('1 Matériel'!$B$6:$B$29,U29)="Oui",1,0))
A30: =IF(OR(T30=0,V30=1),"",T30-COUNTIF(V$15:V30,1)) | C30: =IF(T30=0,"",IF(V30=1,UPPER(INDEX('1 Matériel'!$C$6:$C$29,U30)),INDEX('1 Matériel'!$C$6:$C$29,U30)&IF(INDEX('1 Matériel'!$E$6:$E$29,U30)>1," ("&(T30-INDEX('1 Matériel'!$F$6:$F$29,U30)+INDEX('1 Matériel'!$E$6:$E$29,U30))&"/"&INDEX('1 Matériel'!$E$6:$E$29,U30)&")",""))) | T30: =IF(16<=SUM('1 Matériel'!$E$6:$E$29),16,0) | U30: =IF(T30=0,"",COUNTIF('1 Matériel'!$F$6:$F$29,"<"&T30)+1) | V30: =IF(U30="","",IF(INDEX('1 Matériel'!$B$6:$B$29,U30)="Oui",1,0))
A31: =IF(OR(T31=0,V31=1),"",T31-COUNTIF(V$15:V31,1)) | C31: =IF(T31=0,"",IF(V31=1,UPPER(INDEX('1 Matériel'!$C$6:$C$29,U31)),INDEX('1 Matériel'!$C$6:$C$29,U31)&IF(INDEX('1 Matériel'!$E$6:$E$29,U31)>1," ("&(T31-INDEX('1 Matériel'!$F$6:$F$29,U31)+INDEX('1 Matériel'!$E$6:$E$29,U31))&"/"&INDEX('1 Matériel'!$E$6:$E$29,U31)&")",""))) | T31: =IF(17<=SUM('1 Matériel'!$E$6:$E$29),17,0) | U31: =IF(T31=0,"",COUNTIF('1 Matériel'!$F$6:$F$29,"<"&T31)+1) | V31: =IF(U31="","",IF(INDEX('1 Matériel'!$B$6:$B$29,U31)="Oui",1,0))
A32: =IF(OR(T32=0,V32=1),"",T32-COUNTIF(V$15:V32,1)) | C32: =IF(T32=0,"",IF(V32=1,UPPER(INDEX('1 Matériel'!$C$6:$C$29,U32)),INDEX('1 Matériel'!$C$6:$C$29,U32)&IF(INDEX('1 Matériel'!$E$6:$E$29,U32)>1," ("&(T32-INDEX('1 Matériel'!$F$6:$F$29,U32)+INDEX('1 Matériel'!$E$6:$E$29,U32))&"/"&INDEX('1 Matériel'!$E$6:$E$29,U32)&")",""))) | T32: =IF(18<=SUM('1 Matériel'!$E$6:$E$29),18,0) | U32: =IF(T32=0,"",COUNTIF('1 Matériel'!$F$6:$F$29,"<"&T32)+1) | V32: =IF(U32="","",IF(INDEX('1 Matériel'!$B$6:$B$29,U32)="Oui",1,0))
A33: =IF(OR(T33=0,V33=1),"",T33-COUNTIF(V$15:V33,1)) | C33: =IF(T33=0,"",IF(V33=1,UPPER(INDEX('1 Matériel'!$C$6:$C$29,U33)),INDEX('1 Matériel'!$C$6:$C$29,U33)&IF(INDEX('1 Matériel'!$E$6:$E$29,U33)>1," ("&(T33-INDEX('1 Matériel'!$F$6:$F$29,U33)+INDEX('1 Matériel'!$E$6:$E$29,U33))&"/"&INDEX('1 Matériel'!$E$6:$E$29,U33)&")",""))) | T33: =IF(19<=SUM('1 Matériel'!$E$6:$E$29),19,0) | U33: =IF(T33=0,"",COUNTIF('1 Matériel'!$F$6:$F$29,"<"&T33)+1) | V33: =IF(U33="","",IF(INDEX('1 Matériel'!$B$6:$B$29,U33)="Oui",1,0))
A34: =IF(OR(T34=0,V34=1),"",T34-COUNTIF(V$15:V34,1)) | C34: =IF(T34=0,"",IF(V34=1,UPPER(INDEX('1 Matériel'!$C$6:$C$29,U34)),INDEX('1 Matériel'!$C$6:$C$29,U34)&IF(INDEX('1 Matériel'!$E$6:$E$29,U34)>1," ("&(T34-INDEX('1 Matériel'!$F$6:$F$29,U34)+INDEX('1 Matériel'!$E$6:$E$29,U34))&"/"&INDEX('1 Matériel'!$E$6:$E$29,U34)&")",""))) | T34: =IF(20<=SUM('1 Matériel'!$E$6:$E$29),20,0) | U34: =IF(T34=0,"",COUNTIF('1 Matériel'!$F$6:$F$29,"<"&T34)+1) | V34: =IF(U34="","",IF(INDEX('1 Matériel'!$B$6:$B$29,U34)="Oui",1,0))
A35: =IF(OR(T35=0,V35=1),"",T35-COUNTIF(V$15:V35,1)) | C35: =IF(T35=0,"",IF(V35=1,UPPER(INDEX('1 Matériel'!$C$6:$C$29,U35)),INDEX('1 Matériel'!$C$6:$C$29,U35)&IF(INDEX('1 Matériel'!$E$6:$E$29,U35)>1," ("&(T35-INDEX('1 Matériel'!$F$6:$F$29,U35)+INDEX('1 Matériel'!$E$6:$E$29,U35))&"/"&INDEX('1 Matériel'!$E$6:$E$29,U35)&")",""))) | T35: =IF(21<=SUM('1 Matériel'!$E$6:$E$29),21,0) | U35: =IF(T35=0,"",COUNTIF('1 Matériel'!$F$6:$F$29,"<"&T35)+1) | V35: =IF(U35="","",IF(INDEX('1 Matériel'!$B$6:$B$29,U35)="Oui",1,0))
A36: =IF(OR(T36=0,V36=1),"",T36-COUNTIF(V$15:V36,1)) | C36: =IF(T36=0,"",IF(V36=1,UPPER(INDEX('1 Matériel'!$C$6:$C$29,U36)),INDEX('1 Matériel'!$C$6:$C$29,U36)&IF(INDEX('1 Matériel'!$E$6:$E$29,U36)>1," ("&(T36-INDEX('1 Matériel'!$F$6:$F$29,U36)+INDEX('1 Matériel'!$E$6:$E$29,U36))&"/"&INDEX('1 Matériel'!$E$6:$E$29,U36)&")",""))) | T36: =IF(22<=SUM('1 Matériel'!$E$6:$E$29),22,0) | U36: =IF(T36=0,"",COUNTIF('1 Matériel'!$F$6:$F$29,"<"&T36)+1) | V36: =IF(U36="","",IF(INDEX('1 Matériel'!$B$6:$B$29,U36)="Oui",1,0))
A37: =IF(OR(T37=0,V37=1),"",T37-COUNTIF(V$15:V37,1)) | C37: =IF(T37=0,"",IF(V37=1,UPPER(INDEX('1 Matériel'!$C$6:$C$29,U37)),INDEX('1 Matériel'!$C$6:$C$29,U37)&IF(INDEX('1 Matériel'!$E$6:$E$29,U37)>1," ("&(T37-INDEX('1 Matériel'!$F$6:$F$29,U37)+INDEX('1 Matériel'!$E$6:$E$29,U37))&"/"&INDEX('1 Matériel'!$E$6:$E$29,U37)&")",""))) | T37: =IF(23<=SUM('1 Matériel'!$E$6:$E$29),23,0) | U37: =IF(T37=0,"",COUNTIF('1 Matériel'!$F$6:$F$29,"<"&T37)+1) | V37: =IF(U37="","",IF(INDEX('1 Matériel'!$B$6:$B$29,U37)="Oui",1,0))
A38: =IF(OR(T38=0,V38=1),"",T38-COUNTIF(V$15:V38,1)) | C38: =IF(T38=0,"",IF(V38=1,UPPER(INDEX('1 Matériel'!$C$6:$C$29,U38)),INDEX('1 Matériel'!$C$6:$C$29,U38)&IF(INDEX('1 Matériel'!$E$6:$E$29,U38)>1," ("&(T38-INDEX('1 Matériel'!$F$6:$F$29,U38)+INDEX('1 Matériel'!$E$6:$E$29,U38))&"/"&INDEX('1 Matériel'!$E$6:$E$29,U38)&")",""))) | T38: =IF(24<=SUM('1 Matériel'!$E$6:$E$29),24,0) | U38: =IF(T38=0,"",COUNTIF('1 Matériel'!$F$6:$F$29,"<"&T38)+1) | V38: =IF(U38="","",IF(INDEX('1 Matériel'!$B$6:$B$29,U38)="Oui",1,0))
A39: =IF(OR(T39=0,V39=1),"",T39-COUNTIF(V$15:V39,1)) | C39: =IF(T39=0,"",IF(V39=1,UPPER(INDEX('1 Matériel'!$C$6:$C$29,U39)),INDEX('1 Matériel'!$C$6:$C$29,U39)&IF(INDEX('1 Matériel'!$E$6:$E$29,U39)>1," ("&(T39-INDEX('1 Matériel'!$F$6:$F$29,U39)+INDEX('1 Matériel'!$E$6:$E$29,U39))&"/"&INDEX('1 Matériel'!$E$6:$E$29,U39)&")",""))) | T39: =IF(25<=SUM('1 Matériel'!$E$6:$E$29),25,0) | U39: =IF(T39=0,"",COUNTIF('1 Matériel'!$F$6:$F$29,"<"&T39)+1) | V39: =IF(U39="","",IF(INDEX('1 Matériel'!$B$6:$B$29,U39)="Oui",1,0))
A40: =IF(OR(T40=0,V40=1),"",T40-COUNTIF(V$15:V40,1)) | C40: =IF(T40=0,"",IF(V40=1,UPPER(INDEX('1 Matériel'!$C$6:$C$29,U40)),INDEX('1 Matériel'!$C$6:$C$29,U40)&IF(INDEX('1 Matériel'!$E$6:$E$29,U40)>1," ("&(T40-INDEX('1 Matériel'!$F$6:$F$29,U40)+INDEX('1 Matériel'!$E$6:$E$29,U40))&"/"&INDEX('1 Matériel'!$E$6:$E$29,U40)&")",""))) | T40: =IF(26<=SUM('1 Matériel'!$E$6:$E$29),26,0) | U40: =IF(T40=0,"",COUNTIF('1 Matériel'!$F$6:$F$29,"<"&T40)+1) | V40: =IF(U40="","",IF(INDEX('1 Matériel'!$B$6:$B$29,U40)="Oui",1,0))
A41: =IF(OR(T41=0,V41=1),"",T41-COUNTIF(V$15:V41,1)) | C41: =IF(T41=0,"",IF(V41=1,UPPER(INDEX('1 Matériel'!$C$6:$C$29,U41)),INDEX('1 Matériel'!$C$6:$C$29,U41)&IF(INDEX('1 Matériel'!$E$6:$E$29,U41)>1," ("&(T41-INDEX('1 Matériel'!$F$6:$F$29,U41)+INDEX('1 Matériel'!$E$6:$E$29,U41))&"/"&INDEX('1 Matériel'!$E$6:$E$29,U41)&")",""))) | T41: =IF(27<=SUM('1 Matériel'!$E$6:$E$29),27,0) | U41: =IF(T41=0,"",COUNTIF('1 Matériel'!$F$6:$F$29,"<"&T41)+1) | V41: =IF(U41="","",IF(INDEX('1 Matériel'!$B$6:$B$29,U41)="Oui",1,0))
A42: =IF(OR(T42=0,V42=1),"",T42-COUNTIF(V$15:V42,1)) | C42: =IF(T42=0,"",IF(V42=1,UPPER(INDEX('1 Matériel'!$C$6:$C$29,U42)),INDEX('1 Matériel'!$C$6:$C$29,U42)&IF(INDEX('1 Matériel'!$E$6:$E$29,U42)>1," ("&(T42-INDEX('1 Matériel'!$F$6:$F$29,U42)+INDEX('1 Matériel'!$E$6:$E$29,U42))&"/"&INDEX('1 Matériel'!$E$6:$E$29,U42)&")",""))) | T42: =IF(28<=SUM('1 Matériel'!$E$6:$E$29),28,0) | U42: =IF(T42=0,"",COUNTIF('1 Matériel'!$F$6:$F$29,"<"&T42)+1) | V42: =IF(U42="","",IF(INDEX('1 Matériel'!$B$6:$B$29,U42)="Oui",1,0))
...

Sheet Listes
A1: Contact Enedril | B1: E-mail | D1: Incoterm | E1: Validité | F1: Règlement | G1: Oui / Non | H1: 1 | J1: Support de colisage | K1: N° de colis | L1: Unité | M1: Mode transport | N1: Mode forfait | P1: Statut | Q1: Test / Taille
A2: Fabien JACQUOT | B2: fjacquot@enedril.fr | D2: EXW Lons | E2: 15 jours / 15 days | F2: 30 jours date de facture / 30 days invoice date | G2: Oui | H2: ← langue du devis : 1 = français, 2 = anglais | J2: Palette | K2: P1 | L2: forfait | M2: Coût réel +15 % | N2: Forfait calculé (S + O + UC) | P2: Oui | Q2: Taille OK
A3: Alexis ESTINES | B3: aestines@enedril.fr | D3: FCA Lons | E3: 30 jours / 30 days | F3: 30 jours fin de mois / 30 days end of month | G3: Non | J3: Fishing basket | K3: P2 | L3: €/jour | M3: Forfait | N3: Forfait global | P3: En cours | Q3: Test OK
A4: Paul HYNDERICK | B4: phynderick@enedril.fr | D4: DAP | E4: 60 jours / 60 days | F4: 45 jours fin de mois / 45 days end of month | J4: Caisse | K4: P3 | L4: €/jour/pers | N4: Forfait par jour | Q4: Taille + test OK
A5: Céline CARDONA | B5: ccardona@enedril.fr | D5: DDP | E5: 90 jours / 90 days | F5: À la commande / Upon order | J5: Vrac | K5: P4 | L5: €/pers | Q5: À contrôler
A6: Koen MONDELAERS | B6: kmondelaers@enedril.fr | D6: FOB | K6: P5 | L6: €/unité
A7: Luigi LIBERATORE | B7: lliberatore@enedril.fr | K7: P6
K8: P7
K9: P8
A10: Pour ajouter un contact, une validité, etc. : écrire à la suite dans la colonne (les listes déroulantes lisent les 12 premières lignes). | K10: P9
K11: P10
K12: Vrac
